from first import *

def rambler(v):
	mc.setBlock(v + Vec3(-22,-4,-16),20, 0)
	mc.setBlock(v + Vec3(-22,-4,-15),20, 0)
	mc.setBlock(v + Vec3(-22,-4,-14),20, 0)
	mc.setBlock(v + Vec3(-22,-4,-12),49, 0)
	mc.setBlock(v + Vec3(-22,-4,-11),49, 0)
	mc.setBlock(v + Vec3(-22,-4,-10),20, 0)
	mc.setBlock(v + Vec3(-22,-4,-9),20, 0)
	mc.setBlock(v + Vec3(-22,-4,-8),20, 0)
	mc.setBlock(v + Vec3(-22,-4,-7),49, 0)
	mc.setBlock(v + Vec3(-22,-4,-6),49, 0)
	mc.setBlock(v + Vec3(-22,-4,-5),49, 0)
	mc.setBlock(v + Vec3(-22,-4,-4),20, 0)
	mc.setBlock(v + Vec3(-22,-4,-3),20, 0)
	mc.setBlock(v + Vec3(-22,-4,-2),20, 0)
	mc.setBlock(v + Vec3(-22,-4,-1),49, 0)
	mc.setBlock(v + Vec3(-22,-4,0),49, 0)
	mc.setBlock(v + Vec3(-22,-4,1),49, 0)
	mc.setBlock(v + Vec3(-22,-4,2),20, 0)
	mc.setBlock(v + Vec3(-22,-4,3),20, 0)
	mc.setBlock(v + Vec3(-22,-4,4),20, 0)
	mc.setBlock(v + Vec3(-22,-4,5),49, 0)
	mc.setBlock(v + Vec3(-22,-4,6),49, 0)
	mc.setBlock(v + Vec3(-22,-4,7),49, 0)
	mc.setBlock(v + Vec3(-22,-4,8),20, 0)
	mc.setBlock(v + Vec3(-22,-4,9),20, 0)
	mc.setBlock(v + Vec3(-22,-4,10),20, 0)
	mc.setBlock(v + Vec3(-22,-4,11),49, 0)
	mc.setBlock(v + Vec3(-22,-4,12),44, 8)
	mc.setBlock(v + Vec3(-22,-4,13),49, 0)
	mc.setBlock(v + Vec3(-22,-4,14),20, 0)
	mc.setBlock(v + Vec3(-22,-4,15),20, 0)
	mc.setBlock(v + Vec3(-21,-4,-16),49, 0)
	mc.setBlock(v + Vec3(-21,-4,-15),49, 0)
	mc.setBlock(v + Vec3(-21,-4,-14),49, 0)
	mc.setBlock(v + Vec3(-21,-4,-13),49, 0)
	mc.setBlock(v + Vec3(-21,-4,-12),49, 0)
	mc.setBlock(v + Vec3(-21,-4,-11),49, 0)
	mc.setBlock(v + Vec3(-21,-4,-10),49, 0)
	mc.setBlock(v + Vec3(-21,-4,-9),49, 0)
	mc.setBlock(v + Vec3(-21,-4,-8),49, 0)
	mc.setBlock(v + Vec3(-21,-4,-7),49, 0)
	mc.setBlock(v + Vec3(-21,-4,-6),49, 0)
	mc.setBlock(v + Vec3(-21,-4,-5),49, 0)
	mc.setBlock(v + Vec3(-21,-4,-4),49, 0)
	mc.setBlock(v + Vec3(-21,-4,-3),49, 0)
	mc.setBlock(v + Vec3(-21,-4,-2),49, 0)
	mc.setBlock(v + Vec3(-21,-4,-1),49, 0)
	mc.setBlock(v + Vec3(-21,-4,0),44, 8)
	mc.setBlock(v + Vec3(-21,-4,1),44, 8)
	mc.setBlock(v + Vec3(-21,-4,2),44, 8)
	mc.setBlock(v + Vec3(-21,-4,3),44, 8)
	mc.setBlock(v + Vec3(-21,-4,4),44, 8)
	mc.setBlock(v + Vec3(-21,-4,5),44, 8)
	mc.setBlock(v + Vec3(-21,-4,6),44, 8)
	mc.setBlock(v + Vec3(-21,-4,7),44, 8)
	mc.setBlock(v + Vec3(-21,-4,8),44, 8)
	mc.setBlock(v + Vec3(-21,-4,9),44, 8)
	mc.setBlock(v + Vec3(-21,-4,10),44, 8)
	mc.setBlock(v + Vec3(-21,-4,11),44, 8)
	mc.setBlock(v + Vec3(-21,-4,12),44, 8)
	mc.setBlock(v + Vec3(-21,-4,13),49, 0)
	mc.setBlock(v + Vec3(-21,-4,14),49, 0)
	mc.setBlock(v + Vec3(-21,-4,15),49, 0)
	mc.setBlock(v + Vec3(-20,-4,-16),20, 0)
	mc.setBlock(v + Vec3(-20,-4,-15),20, 0)
	mc.setBlock(v + Vec3(-20,-4,-14),20, 0)
	mc.setBlock(v + Vec3(-20,-4,-7),49, 0)
	mc.setBlock(v + Vec3(-20,-4,-6),49, 0)
	mc.setBlock(v + Vec3(-20,-4,-5),49, 0)
	mc.setBlock(v + Vec3(-20,-4,-4),20, 0)
	mc.setBlock(v + Vec3(-20,-4,-3),20, 0)
	mc.setBlock(v + Vec3(-20,-4,-2),20, 0)
	mc.setBlock(v + Vec3(-20,-4,-1),49, 0)
	mc.setBlock(v + Vec3(-20,-4,0),44, 8)
	mc.setBlock(v + Vec3(-20,-4,1),49, 0)
	mc.setBlock(v + Vec3(-20,-4,2),20, 0)
	mc.setBlock(v + Vec3(-20,-4,3),20, 0)
	mc.setBlock(v + Vec3(-20,-4,4),20, 0)
	mc.setBlock(v + Vec3(-20,-4,5),49, 0)
	mc.setBlock(v + Vec3(-20,-4,6),49, 0)
	mc.setBlock(v + Vec3(-20,-4,8),20, 0)
	mc.setBlock(v + Vec3(-20,-4,9),20, 0)
	mc.setBlock(v + Vec3(-20,-4,10),20, 0)
	mc.setBlock(v + Vec3(-20,-4,11),49, 0)
	mc.setBlock(v + Vec3(-20,-4,12),49, 0)
	mc.setBlock(v + Vec3(-20,-4,13),49, 0)
	mc.setBlock(v + Vec3(-20,-4,14),20, 0)
	mc.setBlock(v + Vec3(-20,-4,15),20, 0)
	mc.setBlock(v + Vec3(-19,-4,-16),20, 0)
	mc.setBlock(v + Vec3(-19,-4,-15),20, 0)
	mc.setBlock(v + Vec3(-19,-4,-14),20, 0)
	mc.setBlock(v + Vec3(-19,-4,-12),60, 0)
	mc.setBlock(v + Vec3(-19,-4,-11),60, 0)
	mc.setBlock(v + Vec3(-19,-4,-10),60, 0)
	mc.setBlock(v + Vec3(-19,-4,-9),60, 0)
	mc.setBlock(v + Vec3(-19,-4,-7),20, 0)
	mc.setBlock(v + Vec3(-19,-4,-6),49, 0)
	mc.setBlock(v + Vec3(-19,-4,-5),20, 0)
	mc.setBlock(v + Vec3(-19,-4,-4),20, 0)
	mc.setBlock(v + Vec3(-19,-4,-3),20, 0)
	mc.setBlock(v + Vec3(-19,-4,-2),20, 0)
	mc.setBlock(v + Vec3(-19,-4,-1),20, 0)
	mc.setBlock(v + Vec3(-19,-4,0),44, 8)
	mc.setBlock(v + Vec3(-19,-4,1),20, 0)
	mc.setBlock(v + Vec3(-19,-4,2),20, 0)
	mc.setBlock(v + Vec3(-19,-4,3),20, 0)
	mc.setBlock(v + Vec3(-19,-4,4),20, 0)
	mc.setBlock(v + Vec3(-19,-4,5),20, 0)
	mc.setBlock(v + Vec3(-19,-4,6),49, 0)
	mc.setBlock(v + Vec3(-19,-4,8),20, 0)
	mc.setBlock(v + Vec3(-19,-4,9),20, 0)
	mc.setBlock(v + Vec3(-19,-4,10),20, 0)
	mc.setBlock(v + Vec3(-19,-4,11),20, 0)
	mc.setBlock(v + Vec3(-19,-4,12),49, 0)
	mc.setBlock(v + Vec3(-19,-4,13),20, 0)
	mc.setBlock(v + Vec3(-19,-4,14),20, 0)
	mc.setBlock(v + Vec3(-19,-4,15),20, 0)
	mc.setBlock(v + Vec3(-18,-4,-16),20, 0)
	mc.setBlock(v + Vec3(-18,-4,-15),20, 0)
	mc.setBlock(v + Vec3(-18,-4,-14),20, 0)
	mc.setBlock(v + Vec3(-18,-4,-12),48, 0)
	mc.setBlock(v + Vec3(-18,-4,-11),48, 0)
	mc.setBlock(v + Vec3(-18,-4,-7),20, 0)
	mc.setBlock(v + Vec3(-18,-4,-6),49, 0)
	mc.setBlock(v + Vec3(-18,-4,-5),20, 0)
	mc.setBlock(v + Vec3(-18,-4,-4),20, 0)
	mc.setBlock(v + Vec3(-18,-4,-3),20, 0)
	mc.setBlock(v + Vec3(-18,-4,-2),20, 0)
	mc.setBlock(v + Vec3(-18,-4,-1),20, 0)
	mc.setBlock(v + Vec3(-18,-4,0),44, 8)
	mc.setBlock(v + Vec3(-18,-4,1),20, 0)
	mc.setBlock(v + Vec3(-18,-4,2),20, 0)
	mc.setBlock(v + Vec3(-18,-4,3),20, 0)
	mc.setBlock(v + Vec3(-18,-4,4),20, 0)
	mc.setBlock(v + Vec3(-18,-4,5),20, 0)
	mc.setBlock(v + Vec3(-18,-4,6),49, 0)
	mc.setBlock(v + Vec3(-18,-4,8),20, 0)
	mc.setBlock(v + Vec3(-18,-4,9),20, 0)
	mc.setBlock(v + Vec3(-18,-4,10),20, 0)
	mc.setBlock(v + Vec3(-18,-4,11),20, 0)
	mc.setBlock(v + Vec3(-18,-4,12),49, 0)
	mc.setBlock(v + Vec3(-18,-4,13),20, 0)
	mc.setBlock(v + Vec3(-18,-4,14),20, 0)
	mc.setBlock(v + Vec3(-18,-4,15),20, 0)
	mc.setBlock(v + Vec3(-17,-4,-16),20, 0)
	mc.setBlock(v + Vec3(-17,-4,-15),20, 0)
	mc.setBlock(v + Vec3(-17,-4,-14),20, 0)
	mc.setBlock(v + Vec3(-17,-4,-12),48, 0)
	mc.setBlock(v + Vec3(-17,-4,-11),48, 0)
	mc.setBlock(v + Vec3(-17,-4,-10),48, 0)
	mc.setBlock(v + Vec3(-17,-4,-9),48, 0)
	mc.setBlock(v + Vec3(-17,-4,-7),20, 0)
	mc.setBlock(v + Vec3(-17,-4,-6),49, 0)
	mc.setBlock(v + Vec3(-17,-4,-5),20, 0)
	mc.setBlock(v + Vec3(-17,-4,-4),20, 0)
	mc.setBlock(v + Vec3(-17,-4,-3),20, 0)
	mc.setBlock(v + Vec3(-17,-4,-2),20, 0)
	mc.setBlock(v + Vec3(-17,-4,-1),20, 0)
	mc.setBlock(v + Vec3(-17,-4,0),44, 8)
	mc.setBlock(v + Vec3(-17,-4,1),20, 0)
	mc.setBlock(v + Vec3(-17,-4,2),20, 0)
	mc.setBlock(v + Vec3(-17,-4,3),20, 0)
	mc.setBlock(v + Vec3(-17,-4,5),20, 0)
	mc.setBlock(v + Vec3(-17,-4,6),49, 0)
	mc.setBlock(v + Vec3(-17,-4,8),20, 0)
	mc.setBlock(v + Vec3(-17,-4,9),20, 0)
	mc.setBlock(v + Vec3(-17,-4,10),20, 0)
	mc.setBlock(v + Vec3(-17,-4,11),20, 0)
	mc.setBlock(v + Vec3(-17,-4,12),49, 0)
	mc.setBlock(v + Vec3(-17,-4,13),20, 0)
	mc.setBlock(v + Vec3(-17,-4,14),20, 0)
	mc.setBlock(v + Vec3(-17,-4,15),20, 0)
	mc.setBlock(v + Vec3(-16,-4,-16),20, 0)
	mc.setBlock(v + Vec3(-16,-4,-15),20, 0)
	mc.setBlock(v + Vec3(-16,-4,-14),20, 0)
	mc.setBlock(v + Vec3(-16,-4,-13),48, 0)
	mc.setBlock(v + Vec3(-16,-4,-12),48, 0)
	mc.setBlock(v + Vec3(-16,-4,-11),48, 0)
	mc.setBlock(v + Vec3(-16,-4,-10),60, 0)
	mc.setBlock(v + Vec3(-16,-4,-9),60, 0)
	mc.setBlock(v + Vec3(-16,-4,-7),49, 0)
	mc.setBlock(v + Vec3(-16,-4,-6),49, 0)
	mc.setBlock(v + Vec3(-16,-4,-5),49, 0)
	mc.setBlock(v + Vec3(-16,-4,-4),20, 0)
	mc.setBlock(v + Vec3(-16,-4,-3),155, 0)
	mc.setBlock(v + Vec3(-16,-4,-2),155, 0)
	mc.setBlock(v + Vec3(-16,-4,-1),44, 8)
	mc.setBlock(v + Vec3(-16,-4,0),44, 8)
	mc.setBlock(v + Vec3(-16,-4,1),44, 8)
	mc.setBlock(v + Vec3(-16,-4,2),20, 0)
	mc.setBlock(v + Vec3(-16,-4,3),20, 0)
	mc.setBlock(v + Vec3(-16,-4,4),20, 0)
	mc.setBlock(v + Vec3(-16,-4,8),20, 0)
	mc.setBlock(v + Vec3(-16,-4,9),20, 0)
	mc.setBlock(v + Vec3(-16,-4,10),20, 0)
	mc.setBlock(v + Vec3(-16,-4,11),49, 0)
	mc.setBlock(v + Vec3(-16,-4,12),49, 0)
	mc.setBlock(v + Vec3(-16,-4,13),49, 0)
	mc.setBlock(v + Vec3(-16,-4,14),20, 0)
	mc.setBlock(v + Vec3(-16,-4,15),20, 0)
	mc.setBlock(v + Vec3(-15,-4,-16),49, 0)
	mc.setBlock(v + Vec3(-15,-4,-15),49, 0)
	mc.setBlock(v + Vec3(-15,-4,-14),49, 0)
	mc.setBlock(v + Vec3(-15,-4,-12),60, 0)
	mc.setBlock(v + Vec3(-15,-4,-11),60, 0)
	mc.setBlock(v + Vec3(-15,-4,-10),60, 0)
	mc.setBlock(v + Vec3(-15,-4,-9),60, 0)
	mc.setBlock(v + Vec3(-15,-4,-7),49, 0)
	mc.setBlock(v + Vec3(-15,-4,-6),49, 0)
	mc.setBlock(v + Vec3(-15,-4,-5),49, 0)
	mc.setBlock(v + Vec3(-15,-4,-4),49, 0)
	mc.setBlock(v + Vec3(-15,-4,-3),155, 0)
	mc.setBlock(v + Vec3(-15,-4,-2),49, 0)
	mc.setBlock(v + Vec3(-15,-4,-1),44, 8)
	mc.setBlock(v + Vec3(-15,-4,0),44, 8)
	mc.setBlock(v + Vec3(-15,-4,1),44, 8)
	mc.setBlock(v + Vec3(-15,-4,2),49, 0)
	mc.setBlock(v + Vec3(-15,-4,3),49, 0)
	mc.setBlock(v + Vec3(-15,-4,4),49, 0)
	mc.setBlock(v + Vec3(-15,-4,5),49, 0)
	mc.setBlock(v + Vec3(-15,-4,6),49, 0)
	mc.setBlock(v + Vec3(-15,-4,7),49, 0)
	mc.setBlock(v + Vec3(-15,-4,8),49, 0)
	mc.setBlock(v + Vec3(-15,-4,9),49, 0)
	mc.setBlock(v + Vec3(-15,-4,10),49, 0)
	mc.setBlock(v + Vec3(-15,-4,11),49, 0)
	mc.setBlock(v + Vec3(-15,-4,12),49, 0)
	mc.setBlock(v + Vec3(-15,-4,13),49, 0)
	mc.setBlock(v + Vec3(-15,-4,14),49, 0)
	mc.setBlock(v + Vec3(-15,-4,15),49, 0)
	mc.setBlock(v + Vec3(-14,-4,-16),20, 0)
	mc.setBlock(v + Vec3(-14,-4,-15),20, 0)
	mc.setBlock(v + Vec3(-14,-4,-14),20, 0)
	mc.setBlock(v + Vec3(-14,-4,-12),60, 0)
	mc.setBlock(v + Vec3(-14,-4,-11),60, 0)
	mc.setBlock(v + Vec3(-14,-4,-10),60, 0)
	mc.setBlock(v + Vec3(-14,-4,-9),60, 0)
	mc.setBlock(v + Vec3(-14,-4,-7),49, 0)
	mc.setBlock(v + Vec3(-14,-4,-6),49, 0)
	mc.setBlock(v + Vec3(-14,-4,-5),49, 0)
	mc.setBlock(v + Vec3(-14,-4,-4),20, 0)
	mc.setBlock(v + Vec3(-14,-4,-3),155, 0)
	mc.setBlock(v + Vec3(-14,-4,-2),20, 0)
	mc.setBlock(v + Vec3(-14,-4,-1),49, 0)
	mc.setBlock(v + Vec3(-14,-4,0),49, 0)
	mc.setBlock(v + Vec3(-14,-4,1),49, 0)
	mc.setBlock(v + Vec3(-14,-4,2),20, 0)
	mc.setBlock(v + Vec3(-14,-4,3),20, 0)
	mc.setBlock(v + Vec3(-14,-4,4),20, 0)
	mc.setBlock(v + Vec3(-14,-4,5),49, 0)
	mc.setBlock(v + Vec3(-14,-4,6),49, 0)
	mc.setBlock(v + Vec3(-14,-4,7),49, 0)
	mc.setBlock(v + Vec3(-14,-4,8),20, 0)
	mc.setBlock(v + Vec3(-14,-4,9),20, 0)
	mc.setBlock(v + Vec3(-14,-4,10),20, 0)
	mc.setBlock(v + Vec3(-14,-4,11),49, 0)
	mc.setBlock(v + Vec3(-14,-4,12),49, 0)
	mc.setBlock(v + Vec3(-14,-4,13),49, 0)
	mc.setBlock(v + Vec3(-14,-4,14),20, 0)
	mc.setBlock(v + Vec3(-14,-4,15),20, 0)
	mc.setBlock(v + Vec3(-13,-4,-16),20, 0)
	mc.setBlock(v + Vec3(-13,-4,-15),20, 0)
	mc.setBlock(v + Vec3(-13,-4,-14),20, 0)
	mc.setBlock(v + Vec3(-13,-4,-7),20, 0)
	mc.setBlock(v + Vec3(-13,-4,-6),49, 0)
	mc.setBlock(v + Vec3(-13,-4,-5),20, 0)
	mc.setBlock(v + Vec3(-13,-4,-4),20, 0)
	mc.setBlock(v + Vec3(-13,-4,-3),155, 0)
	mc.setBlock(v + Vec3(-13,-4,-2),20, 0)
	mc.setBlock(v + Vec3(-13,-4,-1),20, 0)
	mc.setBlock(v + Vec3(-13,-4,0),49, 0)
	mc.setBlock(v + Vec3(-13,-4,1),20, 0)
	mc.setBlock(v + Vec3(-13,-4,2),20, 0)
	mc.setBlock(v + Vec3(-13,-4,3),20, 0)
	mc.setBlock(v + Vec3(-13,-4,4),20, 0)
	mc.setBlock(v + Vec3(-13,-4,5),20, 0)
	mc.setBlock(v + Vec3(-13,-4,6),49, 0)
	mc.setBlock(v + Vec3(-13,-4,7),20, 0)
	mc.setBlock(v + Vec3(-13,-4,8),20, 0)
	mc.setBlock(v + Vec3(-13,-4,9),20, 0)
	mc.setBlock(v + Vec3(-13,-4,10),20, 0)
	mc.setBlock(v + Vec3(-13,-4,11),20, 0)
	mc.setBlock(v + Vec3(-13,-4,12),49, 0)
	mc.setBlock(v + Vec3(-13,-4,13),20, 0)
	mc.setBlock(v + Vec3(-13,-4,14),20, 0)
	mc.setBlock(v + Vec3(-13,-4,15),20, 0)
	mc.setBlock(v + Vec3(-12,-4,-15),20, 0)
	mc.setBlock(v + Vec3(-12,-4,-14),20, 0)
	mc.setBlock(v + Vec3(-12,-4,-13),20, 0)
	mc.setBlock(v + Vec3(-12,-4,-12),49, 0)
	mc.setBlock(v + Vec3(-12,-4,-11),20, 0)
	mc.setBlock(v + Vec3(-12,-4,-10),20, 0)
	mc.setBlock(v + Vec3(-12,-4,-9),155, 0)
	mc.setBlock(v + Vec3(-12,-4,-8),155, 0)
	mc.setBlock(v + Vec3(-12,-4,-7),155, 0)
	mc.setBlock(v + Vec3(-12,-4,-6),155, 0)
	mc.setBlock(v + Vec3(-12,-4,-5),155, 0)
	mc.setBlock(v + Vec3(-12,-4,-4),155, 0)
	mc.setBlock(v + Vec3(-12,-4,-3),155, 0)
	mc.setBlock(v + Vec3(-12,-4,-2),20, 0)
	mc.setBlock(v + Vec3(-12,-4,-1),20, 0)
	mc.setBlock(v + Vec3(-12,-4,0),49, 0)
	mc.setBlock(v + Vec3(-12,-4,1),20, 0)
	mc.setBlock(v + Vec3(-12,-4,2),20, 0)
	mc.setBlock(v + Vec3(-12,-4,3),20, 0)
	mc.setBlock(v + Vec3(-12,-4,4),20, 0)
	mc.setBlock(v + Vec3(-12,-4,5),20, 0)
	mc.setBlock(v + Vec3(-12,-4,6),49, 0)
	mc.setBlock(v + Vec3(-12,-4,7),20, 0)
	mc.setBlock(v + Vec3(-12,-4,8),20, 0)
	mc.setBlock(v + Vec3(-12,-4,9),20, 0)
	mc.setBlock(v + Vec3(-12,-4,10),20, 0)
	mc.setBlock(v + Vec3(-12,-4,11),20, 0)
	mc.setBlock(v + Vec3(-12,-4,12),49, 0)
	mc.setBlock(v + Vec3(-12,-4,13),20, 0)
	mc.setBlock(v + Vec3(-12,-4,14),20, 0)
	mc.setBlock(v + Vec3(-12,-4,15),20, 0)
	mc.setBlock(v + Vec3(-11,-4,-16),20, 0)
	mc.setBlock(v + Vec3(-11,-4,-15),20, 0)
	mc.setBlock(v + Vec3(-11,-4,-14),20, 0)
	mc.setBlock(v + Vec3(-11,-4,-13),20, 0)
	mc.setBlock(v + Vec3(-11,-4,-12),49, 0)
	mc.setBlock(v + Vec3(-11,-4,-11),20, 0)
	mc.setBlock(v + Vec3(-11,-4,-10),20, 0)
	mc.setBlock(v + Vec3(-11,-4,-9),155, 0)
	mc.setBlock(v + Vec3(-11,-4,-8),20, 0)
	mc.setBlock(v + Vec3(-11,-4,-7),20, 0)
	mc.setBlock(v + Vec3(-11,-4,-6),49, 0)
	mc.setBlock(v + Vec3(-11,-4,-5),20, 0)
	mc.setBlock(v + Vec3(-11,-4,-4),20, 0)
	mc.setBlock(v + Vec3(-11,-4,-3),20, 0)
	mc.setBlock(v + Vec3(-11,-4,-2),20, 0)
	mc.setBlock(v + Vec3(-11,-4,-1),20, 0)
	mc.setBlock(v + Vec3(-11,-4,0),49, 0)
	mc.setBlock(v + Vec3(-11,-4,1),20, 0)
	mc.setBlock(v + Vec3(-11,-4,2),20, 0)
	mc.setBlock(v + Vec3(-11,-4,3),20, 0)
	mc.setBlock(v + Vec3(-11,-4,4),20, 0)
	mc.setBlock(v + Vec3(-11,-4,5),20, 0)
	mc.setBlock(v + Vec3(-11,-4,6),49, 0)
	mc.setBlock(v + Vec3(-11,-4,7),20, 0)
	mc.setBlock(v + Vec3(-11,-4,8),20, 0)
	mc.setBlock(v + Vec3(-11,-4,9),20, 0)
	mc.setBlock(v + Vec3(-11,-4,10),20, 0)
	mc.setBlock(v + Vec3(-11,-4,11),20, 0)
	mc.setBlock(v + Vec3(-11,-4,12),49, 0)
	mc.setBlock(v + Vec3(-11,-4,13),20, 0)
	mc.setBlock(v + Vec3(-11,-4,14),20, 0)
	mc.setBlock(v + Vec3(-11,-4,15),20, 0)
	mc.setBlock(v + Vec3(-10,-4,-16),20, 0)
	mc.setBlock(v + Vec3(-10,-4,-15),20, 0)
	mc.setBlock(v + Vec3(-10,-4,-14),20, 0)
	mc.setBlock(v + Vec3(-10,-4,-13),49, 0)
	mc.setBlock(v + Vec3(-10,-4,-12),49, 0)
	mc.setBlock(v + Vec3(-10,-4,-11),49, 0)
	mc.setBlock(v + Vec3(-10,-4,-10),20, 0)
	mc.setBlock(v + Vec3(-10,-4,-9),155, 0)
	mc.setBlock(v + Vec3(-10,-4,-8),20, 0)
	mc.setBlock(v + Vec3(-10,-4,-7),49, 0)
	mc.setBlock(v + Vec3(-10,-4,-6),49, 0)
	mc.setBlock(v + Vec3(-10,-4,-5),49, 0)
	mc.setBlock(v + Vec3(-10,-4,-4),20, 0)
	mc.setBlock(v + Vec3(-10,-4,-3),20, 0)
	mc.setBlock(v + Vec3(-10,-4,-2),20, 0)
	mc.setBlock(v + Vec3(-10,-4,-1),49, 0)
	mc.setBlock(v + Vec3(-10,-4,0),49, 0)
	mc.setBlock(v + Vec3(-10,-4,1),49, 0)
	mc.setBlock(v + Vec3(-10,-4,2),20, 0)
	mc.setBlock(v + Vec3(-10,-4,3),20, 0)
	mc.setBlock(v + Vec3(-10,-4,4),20, 0)
	mc.setBlock(v + Vec3(-10,-4,5),49, 0)
	mc.setBlock(v + Vec3(-10,-4,6),49, 0)
	mc.setBlock(v + Vec3(-10,-4,7),49, 0)
	mc.setBlock(v + Vec3(-10,-4,8),20, 0)
	mc.setBlock(v + Vec3(-10,-4,9),20, 0)
	mc.setBlock(v + Vec3(-10,-4,10),20, 0)
	mc.setBlock(v + Vec3(-10,-4,11),49, 0)
	mc.setBlock(v + Vec3(-10,-4,12),49, 0)
	mc.setBlock(v + Vec3(-10,-4,13),49, 0)
	mc.setBlock(v + Vec3(-10,-4,14),20, 0)
	mc.setBlock(v + Vec3(-10,-4,15),20, 0)
	mc.setBlock(v + Vec3(-9,-4,-16),49, 0)
	mc.setBlock(v + Vec3(-9,-4,-15),49, 0)
	mc.setBlock(v + Vec3(-9,-4,-14),49, 0)
	mc.setBlock(v + Vec3(-9,-4,-13),49, 0)
	mc.setBlock(v + Vec3(-9,-4,-12),49, 0)
	mc.setBlock(v + Vec3(-9,-4,-11),20, 0)
	mc.setBlock(v + Vec3(-9,-4,-10),155, 0)
	mc.setBlock(v + Vec3(-9,-4,-9),155, 0)
	mc.setBlock(v + Vec3(-9,-4,-8),49, 0)
	mc.setBlock(v + Vec3(-9,-4,-7),49, 0)
	mc.setBlock(v + Vec3(-9,-4,-6),49, 0)
	mc.setBlock(v + Vec3(-9,-4,-5),49, 0)
	mc.setBlock(v + Vec3(-9,-4,-4),49, 0)
	mc.setBlock(v + Vec3(-9,-4,-3),49, 0)
	mc.setBlock(v + Vec3(-9,-4,-2),49, 0)
	mc.setBlock(v + Vec3(-9,-4,-1),49, 0)
	mc.setBlock(v + Vec3(-9,-4,0),49, 0)
	mc.setBlock(v + Vec3(-9,-4,1),49, 0)
	mc.setBlock(v + Vec3(-9,-4,2),49, 0)
	mc.setBlock(v + Vec3(-9,-4,3),49, 0)
	mc.setBlock(v + Vec3(-9,-4,4),49, 0)
	mc.setBlock(v + Vec3(-9,-4,5),49, 0)
	mc.setBlock(v + Vec3(-9,-4,6),49, 0)
	mc.setBlock(v + Vec3(-9,-4,7),49, 0)
	mc.setBlock(v + Vec3(-9,-4,8),49, 0)
	mc.setBlock(v + Vec3(-9,-4,9),49, 0)
	mc.setBlock(v + Vec3(-9,-4,10),49, 0)
	mc.setBlock(v + Vec3(-9,-4,11),49, 0)
	mc.setBlock(v + Vec3(-9,-4,12),49, 0)
	mc.setBlock(v + Vec3(-9,-4,13),49, 0)
	mc.setBlock(v + Vec3(-9,-4,14),49, 0)
	mc.setBlock(v + Vec3(-9,-4,15),49, 0)
	mc.setBlock(v + Vec3(-8,-4,-16),20, 0)
	mc.setBlock(v + Vec3(-8,-4,-15),20, 0)
	mc.setBlock(v + Vec3(-8,-4,-14),20, 0)
	mc.setBlock(v + Vec3(-8,-4,-13),49, 0)
	mc.setBlock(v + Vec3(-8,-4,-12),49, 0)
	mc.setBlock(v + Vec3(-8,-4,-11),20, 0)
	mc.setBlock(v + Vec3(-8,-4,-10),155, 0)
	mc.setBlock(v + Vec3(-8,-4,-9),20, 0)
	mc.setBlock(v + Vec3(-8,-4,-8),20, 0)
	mc.setBlock(v + Vec3(-8,-4,-7),49, 0)
	mc.setBlock(v + Vec3(-8,-4,-6),49, 0)
	mc.setBlock(v + Vec3(-8,-4,-5),49, 0)
	mc.setBlock(v + Vec3(-8,-4,-4),20, 0)
	mc.setBlock(v + Vec3(-8,-4,-3),20, 0)
	mc.setBlock(v + Vec3(-8,-4,-2),20, 0)
	mc.setBlock(v + Vec3(-8,-4,-1),49, 0)
	mc.setBlock(v + Vec3(-8,-4,0),49, 0)
	mc.setBlock(v + Vec3(-8,-4,1),49, 0)
	mc.setBlock(v + Vec3(-8,-4,2),20, 0)
	mc.setBlock(v + Vec3(-8,-4,3),20, 0)
	mc.setBlock(v + Vec3(-8,-4,4),20, 0)
	mc.setBlock(v + Vec3(-8,-4,5),49, 0)
	mc.setBlock(v + Vec3(-8,-4,6),49, 0)
	mc.setBlock(v + Vec3(-8,-4,7),49, 0)
	mc.setBlock(v + Vec3(-8,-4,8),20, 0)
	mc.setBlock(v + Vec3(-8,-4,9),20, 0)
	mc.setBlock(v + Vec3(-8,-4,10),20, 0)
	mc.setBlock(v + Vec3(-8,-4,11),49, 0)
	mc.setBlock(v + Vec3(-8,-4,12),49, 0)
	mc.setBlock(v + Vec3(-8,-4,13),49, 0)
	mc.setBlock(v + Vec3(-8,-4,14),20, 0)
	mc.setBlock(v + Vec3(-8,-4,15),20, 0)
	mc.setBlock(v + Vec3(-7,-4,-16),20, 0)
	mc.setBlock(v + Vec3(-7,-4,-15),20, 0)
	mc.setBlock(v + Vec3(-7,-4,-14),20, 0)
	mc.setBlock(v + Vec3(-7,-4,-13),20, 0)
	mc.setBlock(v + Vec3(-7,-4,-12),49, 0)
	mc.setBlock(v + Vec3(-7,-4,-11),20, 0)
	mc.setBlock(v + Vec3(-7,-4,-10),155, 0)
	mc.setBlock(v + Vec3(-7,-4,-9),20, 0)
	mc.setBlock(v + Vec3(-7,-4,-8),20, 0)
	mc.setBlock(v + Vec3(-7,-4,-7),20, 0)
	mc.setBlock(v + Vec3(-7,-4,-6),49, 0)
	mc.setBlock(v + Vec3(-7,-4,-5),20, 0)
	mc.setBlock(v + Vec3(-7,-4,-4),20, 0)
	mc.setBlock(v + Vec3(-7,-4,-3),20, 0)
	mc.setBlock(v + Vec3(-7,-4,-2),20, 0)
	mc.setBlock(v + Vec3(-7,-4,-1),20, 0)
	mc.setBlock(v + Vec3(-7,-4,0),49, 0)
	mc.setBlock(v + Vec3(-7,-4,1),20, 0)
	mc.setBlock(v + Vec3(-7,-4,2),20, 0)
	mc.setBlock(v + Vec3(-7,-4,3),20, 0)
	mc.setBlock(v + Vec3(-7,-4,4),20, 0)
	mc.setBlock(v + Vec3(-7,-4,5),20, 0)
	mc.setBlock(v + Vec3(-7,-4,6),49, 0)
	mc.setBlock(v + Vec3(-7,-4,7),20, 0)
	mc.setBlock(v + Vec3(-7,-4,8),20, 0)
	mc.setBlock(v + Vec3(-7,-4,9),20, 0)
	mc.setBlock(v + Vec3(-7,-4,10),20, 0)
	mc.setBlock(v + Vec3(-7,-4,11),20, 0)
	mc.setBlock(v + Vec3(-7,-4,12),49, 0)
	mc.setBlock(v + Vec3(-7,-4,13),20, 0)
	mc.setBlock(v + Vec3(-7,-4,14),20, 0)
	mc.setBlock(v + Vec3(-7,-4,15),20, 0)
	mc.setBlock(v + Vec3(-6,-4,-16),20, 0)
	mc.setBlock(v + Vec3(-6,-4,-15),20, 0)
	mc.setBlock(v + Vec3(-6,-4,-14),20, 0)
	mc.setBlock(v + Vec3(-6,-4,-13),20, 0)
	mc.setBlock(v + Vec3(-6,-4,-12),49, 0)
	mc.setBlock(v + Vec3(-6,-4,-11),20, 0)
	mc.setBlock(v + Vec3(-6,-4,-10),155, 0)
	mc.setBlock(v + Vec3(-6,-4,-9),20, 0)
	mc.setBlock(v + Vec3(-6,-4,-8),20, 0)
	mc.setBlock(v + Vec3(-6,-4,-7),20, 0)
	mc.setBlock(v + Vec3(-6,-4,-6),49, 0)
	mc.setBlock(v + Vec3(-6,-4,-5),20, 0)
	mc.setBlock(v + Vec3(-6,-4,-4),20, 0)
	mc.setBlock(v + Vec3(-6,-4,-3),20, 0)
	mc.setBlock(v + Vec3(-6,-4,-2),20, 0)
	mc.setBlock(v + Vec3(-6,-4,-1),20, 0)
	mc.setBlock(v + Vec3(-6,-4,0),49, 0)
	mc.setBlock(v + Vec3(-6,-4,1),20, 0)
	mc.setBlock(v + Vec3(-6,-4,2),20, 0)
	mc.setBlock(v + Vec3(-6,-4,3),20, 0)
	mc.setBlock(v + Vec3(-6,-4,4),20, 0)
	mc.setBlock(v + Vec3(-6,-4,5),20, 0)
	mc.setBlock(v + Vec3(-6,-4,6),49, 0)
	mc.setBlock(v + Vec3(-6,-4,7),20, 0)
	mc.setBlock(v + Vec3(-6,-4,8),20, 0)
	mc.setBlock(v + Vec3(-6,-4,9),20, 0)
	mc.setBlock(v + Vec3(-6,-4,10),20, 0)
	mc.setBlock(v + Vec3(-6,-4,11),20, 0)
	mc.setBlock(v + Vec3(-6,-4,12),49, 0)
	mc.setBlock(v + Vec3(-6,-4,13),20, 0)
	mc.setBlock(v + Vec3(-6,-4,14),20, 0)
	mc.setBlock(v + Vec3(-6,-4,15),20, 0)
	mc.setBlock(v + Vec3(-5,-4,-16),20, 0)
	mc.setBlock(v + Vec3(-5,-4,-15),20, 0)
	mc.setBlock(v + Vec3(-5,-4,-14),20, 0)
	mc.setBlock(v + Vec3(-5,-4,-13),20, 0)
	mc.setBlock(v + Vec3(-5,-4,-12),49, 0)
	mc.setBlock(v + Vec3(-5,-4,-11),20, 0)
	mc.setBlock(v + Vec3(-5,-4,-10),155, 0)
	mc.setBlock(v + Vec3(-5,-4,-9),20, 0)
	mc.setBlock(v + Vec3(-5,-4,-8),20, 0)
	mc.setBlock(v + Vec3(-5,-4,-7),20, 0)
	mc.setBlock(v + Vec3(-5,-4,-6),49, 0)
	mc.setBlock(v + Vec3(-5,-4,-5),20, 0)
	mc.setBlock(v + Vec3(-5,-4,-4),20, 0)
	mc.setBlock(v + Vec3(-5,-4,-3),20, 0)
	mc.setBlock(v + Vec3(-5,-4,-2),20, 0)
	mc.setBlock(v + Vec3(-5,-4,-1),20, 0)
	mc.setBlock(v + Vec3(-5,-4,0),49, 0)
	mc.setBlock(v + Vec3(-5,-4,1),20, 0)
	mc.setBlock(v + Vec3(-5,-4,2),20, 0)
	mc.setBlock(v + Vec3(-5,-4,3),20, 0)
	mc.setBlock(v + Vec3(-5,-4,4),20, 0)
	mc.setBlock(v + Vec3(-5,-4,5),20, 0)
	mc.setBlock(v + Vec3(-5,-4,6),49, 0)
	mc.setBlock(v + Vec3(-5,-4,7),20, 0)
	mc.setBlock(v + Vec3(-5,-4,8),20, 0)
	mc.setBlock(v + Vec3(-5,-4,9),20, 0)
	mc.setBlock(v + Vec3(-5,-4,10),20, 0)
	mc.setBlock(v + Vec3(-5,-4,11),20, 0)
	mc.setBlock(v + Vec3(-5,-4,12),49, 0)
	mc.setBlock(v + Vec3(-5,-4,13),20, 0)
	mc.setBlock(v + Vec3(-5,-4,14),20, 0)
	mc.setBlock(v + Vec3(-5,-4,15),20, 0)
	mc.setBlock(v + Vec3(-4,-4,-16),20, 0)
	mc.setBlock(v + Vec3(-4,-4,-15),20, 0)
	mc.setBlock(v + Vec3(-4,-4,-14),20, 0)
	mc.setBlock(v + Vec3(-4,-4,-13),49, 0)
	mc.setBlock(v + Vec3(-4,-4,-12),49, 0)
	mc.setBlock(v + Vec3(-4,-4,-11),49, 0)
	mc.setBlock(v + Vec3(-4,-4,-10),155, 0)
	mc.setBlock(v + Vec3(-4,-4,-9),155, 0)
	mc.setBlock(v + Vec3(-4,-4,-8),20, 0)
	mc.setBlock(v + Vec3(-4,-4,-7),49, 0)
	mc.setBlock(v + Vec3(-4,-4,-6),49, 0)
	mc.setBlock(v + Vec3(-4,-4,-5),49, 0)
	mc.setBlock(v + Vec3(-4,-4,-4),20, 0)
	mc.setBlock(v + Vec3(-4,-4,-3),20, 0)
	mc.setBlock(v + Vec3(-4,-4,-2),20, 0)
	mc.setBlock(v + Vec3(-4,-4,-1),49, 0)
	mc.setBlock(v + Vec3(-4,-4,0),49, 0)
	mc.setBlock(v + Vec3(-4,-4,1),49, 0)
	mc.setBlock(v + Vec3(-4,-4,2),20, 0)
	mc.setBlock(v + Vec3(-4,-4,3),20, 0)
	mc.setBlock(v + Vec3(-4,-4,4),20, 0)
	mc.setBlock(v + Vec3(-4,-4,5),49, 0)
	mc.setBlock(v + Vec3(-4,-4,6),49, 0)
	mc.setBlock(v + Vec3(-4,-4,7),49, 0)
	mc.setBlock(v + Vec3(-4,-4,8),20, 0)
	mc.setBlock(v + Vec3(-4,-4,9),20, 0)
	mc.setBlock(v + Vec3(-4,-4,10),20, 0)
	mc.setBlock(v + Vec3(-4,-4,11),49, 0)
	mc.setBlock(v + Vec3(-4,-4,12),49, 0)
	mc.setBlock(v + Vec3(-4,-4,13),49, 0)
	mc.setBlock(v + Vec3(-4,-4,14),20, 0)
	mc.setBlock(v + Vec3(-4,-4,15),20, 0)
	mc.setBlock(v + Vec3(-3,-4,-16),49, 0)
	mc.setBlock(v + Vec3(-3,-4,-15),49, 0)
	mc.setBlock(v + Vec3(-3,-4,-14),49, 0)
	mc.setBlock(v + Vec3(-3,-4,-13),49, 0)
	mc.setBlock(v + Vec3(-3,-4,-12),49, 0)
	mc.setBlock(v + Vec3(-3,-4,-11),49, 0)
	mc.setBlock(v + Vec3(-3,-4,-10),49, 0)
	mc.setBlock(v + Vec3(-3,-4,-9),155, 0)
	mc.setBlock(v + Vec3(-3,-4,-8),49, 0)
	mc.setBlock(v + Vec3(-3,-4,-7),49, 0)
	mc.setBlock(v + Vec3(-3,-4,-6),49, 0)
	mc.setBlock(v + Vec3(-3,-4,-5),49, 0)
	mc.setBlock(v + Vec3(-3,-4,-4),49, 0)
	mc.setBlock(v + Vec3(-3,-4,-3),49, 0)
	mc.setBlock(v + Vec3(-3,-4,-2),49, 0)
	mc.setBlock(v + Vec3(-3,-4,-1),49, 0)
	mc.setBlock(v + Vec3(-3,-4,0),49, 0)
	mc.setBlock(v + Vec3(-3,-4,1),49, 0)
	mc.setBlock(v + Vec3(-3,-4,2),49, 0)
	mc.setBlock(v + Vec3(-3,-4,3),49, 0)
	mc.setBlock(v + Vec3(-3,-4,4),49, 0)
	mc.setBlock(v + Vec3(-3,-4,5),49, 0)
	mc.setBlock(v + Vec3(-3,-4,6),49, 0)
	mc.setBlock(v + Vec3(-3,-4,7),49, 0)
	mc.setBlock(v + Vec3(-3,-4,8),49, 0)
	mc.setBlock(v + Vec3(-3,-4,9),49, 0)
	mc.setBlock(v + Vec3(-3,-4,10),49, 0)
	mc.setBlock(v + Vec3(-3,-4,11),49, 0)
	mc.setBlock(v + Vec3(-3,-4,12),49, 0)
	mc.setBlock(v + Vec3(-3,-4,13),49, 0)
	mc.setBlock(v + Vec3(-3,-4,14),49, 0)
	mc.setBlock(v + Vec3(-3,-4,15),49, 0)
	mc.setBlock(v + Vec3(-2,-4,-16),20, 0)
	mc.setBlock(v + Vec3(-2,-4,-15),20, 0)
	mc.setBlock(v + Vec3(-2,-4,-14),20, 0)
	mc.setBlock(v + Vec3(-2,-4,-13),49, 0)
	mc.setBlock(v + Vec3(-2,-4,-12),49, 0)
	mc.setBlock(v + Vec3(-2,-4,-11),49, 0)
	mc.setBlock(v + Vec3(-2,-4,-10),20, 0)
	mc.setBlock(v + Vec3(-2,-4,-9),155, 0)
	mc.setBlock(v + Vec3(-2,-4,-8),20, 0)
	mc.setBlock(v + Vec3(-2,-4,-7),49, 0)
	mc.setBlock(v + Vec3(-2,-4,-6),49, 0)
	mc.setBlock(v + Vec3(-2,-4,-5),49, 0)
	mc.setBlock(v + Vec3(-2,-4,-4),20, 0)
	mc.setBlock(v + Vec3(-2,-4,-3),20, 0)
	mc.setBlock(v + Vec3(-2,-4,-2),20, 0)
	mc.setBlock(v + Vec3(-2,-4,-1),49, 0)
	mc.setBlock(v + Vec3(-2,-4,0),49, 0)
	mc.setBlock(v + Vec3(-2,-4,1),49, 0)
	mc.setBlock(v + Vec3(-2,-4,2),20, 0)
	mc.setBlock(v + Vec3(-2,-4,3),20, 0)
	mc.setBlock(v + Vec3(-2,-4,4),20, 0)
	mc.setBlock(v + Vec3(-2,-4,5),49, 0)
	mc.setBlock(v + Vec3(-2,-4,6),49, 0)
	mc.setBlock(v + Vec3(-2,-4,7),49, 0)
	mc.setBlock(v + Vec3(-2,-4,8),20, 0)
	mc.setBlock(v + Vec3(-2,-4,9),20, 0)
	mc.setBlock(v + Vec3(-2,-4,10),20, 0)
	mc.setBlock(v + Vec3(-2,-4,11),49, 0)
	mc.setBlock(v + Vec3(-2,-4,12),49, 0)
	mc.setBlock(v + Vec3(-2,-4,13),49, 0)
	mc.setBlock(v + Vec3(-2,-4,14),20, 0)
	mc.setBlock(v + Vec3(-2,-4,15),20, 0)
	mc.setBlock(v + Vec3(-1,-4,-16),20, 0)
	mc.setBlock(v + Vec3(-1,-4,-15),20, 0)
	mc.setBlock(v + Vec3(-1,-4,-14),20, 0)
	mc.setBlock(v + Vec3(-1,-4,-13),20, 0)
	mc.setBlock(v + Vec3(-1,-4,-12),49, 0)
	mc.setBlock(v + Vec3(-1,-4,-11),20, 0)
	mc.setBlock(v + Vec3(-1,-4,-10),20, 0)
	mc.setBlock(v + Vec3(-1,-4,-9),155, 0)
	mc.setBlock(v + Vec3(-1,-4,-8),155, 0)
	mc.setBlock(v + Vec3(-1,-4,-7),155, 0)
	mc.setBlock(v + Vec3(-1,-4,-6),155, 0)
	mc.setBlock(v + Vec3(-1,-4,-5),155, 0)
	mc.setBlock(v + Vec3(-1,-4,-4),155, 0)
	mc.setBlock(v + Vec3(-1,-4,-3),155, 0)
	mc.setBlock(v + Vec3(-1,-4,-2),155, 0)
	mc.setBlock(v + Vec3(-1,-4,-1),155, 0)
	mc.setBlock(v + Vec3(-1,-4,0),155, 0)
	mc.setBlock(v + Vec3(-1,-4,1),155, 0)
	mc.setBlock(v + Vec3(-1,-4,2),4, 0)
	mc.setBlock(v + Vec3(-1,-4,3),4, 0)
	mc.setBlock(v + Vec3(-1,-4,4),4, 0)
	mc.setBlock(v + Vec3(-1,-4,5),4, 0)
	mc.setBlock(v + Vec3(-1,-4,6),49, 0)
	mc.setBlock(v + Vec3(-1,-4,7),20, 0)
	mc.setBlock(v + Vec3(-1,-4,8),20, 0)
	mc.setBlock(v + Vec3(-1,-4,9),20, 0)
	mc.setBlock(v + Vec3(-1,-4,10),20, 0)
	mc.setBlock(v + Vec3(-1,-4,11),20, 0)
	mc.setBlock(v + Vec3(-1,-4,12),49, 0)
	mc.setBlock(v + Vec3(-1,-4,13),20, 0)
	mc.setBlock(v + Vec3(-1,-4,14),20, 0)
	mc.setBlock(v + Vec3(-1,-4,15),20, 0)
	mc.setBlock(v + Vec3(0,-4,-16),20, 0)
	mc.setBlock(v + Vec3(0,-4,-15),20, 0)
	mc.setBlock(v + Vec3(0,-4,-14),20, 0)
	mc.setBlock(v + Vec3(0,-4,-13),20, 0)
	mc.setBlock(v + Vec3(0,-4,-12),49, 0)
	mc.setBlock(v + Vec3(0,-4,-11),20, 0)
	mc.setBlock(v + Vec3(0,-4,-10),20, 0)
	mc.setBlock(v + Vec3(0,-4,-9),20, 0)
	mc.setBlock(v + Vec3(0,-4,-8),20, 0)
	mc.setBlock(v + Vec3(0,-4,-7),20, 0)
	mc.setBlock(v + Vec3(0,-4,-6),49, 0)
	mc.setBlock(v + Vec3(0,-4,-5),20, 0)
	mc.setBlock(v + Vec3(0,-4,-4),20, 0)
	mc.setBlock(v + Vec3(0,-4,-3),20, 0)
	mc.setBlock(v + Vec3(0,-4,-2),20, 0)
	mc.setBlock(v + Vec3(0,-4,-1),155, 0)
	mc.setBlock(v + Vec3(0,-4,0),155, 0)
	mc.setBlock(v + Vec3(0,-4,1),155, 0)
	mc.setBlock(v + Vec3(0,-4,2),4, 0)
	mc.setBlock(v + Vec3(0,-4,3),4, 0)
	mc.setBlock(v + Vec3(0,-4,4),4, 0)
	mc.setBlock(v + Vec3(0,-4,5),4, 0)
	mc.setBlock(v + Vec3(0,-4,6),49, 0)
	mc.setBlock(v + Vec3(0,-4,7),20, 0)
	mc.setBlock(v + Vec3(0,-4,8),20, 0)
	mc.setBlock(v + Vec3(0,-4,9),20, 0)
	mc.setBlock(v + Vec3(0,-4,10),20, 0)
	mc.setBlock(v + Vec3(0,-4,11),20, 0)
	mc.setBlock(v + Vec3(0,-4,12),49, 0)
	mc.setBlock(v + Vec3(0,-4,13),20, 0)
	mc.setBlock(v + Vec3(0,-4,14),20, 0)
	mc.setBlock(v + Vec3(0,-4,15),20, 0)
	mc.setBlock(v + Vec3(1,-4,-16),20, 0)
	mc.setBlock(v + Vec3(1,-4,-15),20, 0)
	mc.setBlock(v + Vec3(1,-4,-14),20, 0)
	mc.setBlock(v + Vec3(1,-4,-13),20, 0)
	mc.setBlock(v + Vec3(1,-4,-12),49, 0)
	mc.setBlock(v + Vec3(1,-4,-11),20, 0)
	mc.setBlock(v + Vec3(1,-4,-10),20, 0)
	mc.setBlock(v + Vec3(1,-4,-9),20, 0)
	mc.setBlock(v + Vec3(1,-4,-8),20, 0)
	mc.setBlock(v + Vec3(1,-4,-7),20, 0)
	mc.setBlock(v + Vec3(1,-4,-6),49, 0)
	mc.setBlock(v + Vec3(1,-4,-5),20, 0)
	mc.setBlock(v + Vec3(1,-4,-4),20, 0)
	mc.setBlock(v + Vec3(1,-4,-3),20, 0)
	mc.setBlock(v + Vec3(1,-4,-2),20, 0)
	mc.setBlock(v + Vec3(1,-4,-1),155, 0)
	mc.setBlock(v + Vec3(1,-4,0),4, 0)
	mc.setBlock(v + Vec3(1,-4,1),4, 0)
	mc.setBlock(v + Vec3(1,-4,2),4, 0)
	mc.setBlock(v + Vec3(1,-4,3),4, 0)
	mc.setBlock(v + Vec3(1,-4,4),4, 0)
	mc.setBlock(v + Vec3(1,-4,5),4, 0)
	mc.setBlock(v + Vec3(1,-4,6),4, 0)
	mc.setBlock(v + Vec3(1,-4,7),4, 0)
	mc.setBlock(v + Vec3(1,-4,8),4, 0)
	mc.setBlock(v + Vec3(1,-4,9),4, 0)
	mc.setBlock(v + Vec3(1,-4,10),20, 0)
	mc.setBlock(v + Vec3(1,-4,11),20, 0)
	mc.setBlock(v + Vec3(1,-4,12),49, 0)
	mc.setBlock(v + Vec3(1,-4,13),20, 0)
	mc.setBlock(v + Vec3(1,-4,14),20, 0)
	mc.setBlock(v + Vec3(1,-4,15),20, 0)
	mc.setBlock(v + Vec3(2,-4,-16),20, 0)
	mc.setBlock(v + Vec3(2,-4,-15),20, 0)
	mc.setBlock(v + Vec3(2,-4,-14),20, 0)
	mc.setBlock(v + Vec3(2,-4,-13),49, 0)
	mc.setBlock(v + Vec3(2,-4,-12),49, 0)
	mc.setBlock(v + Vec3(2,-4,-11),49, 0)
	mc.setBlock(v + Vec3(2,-4,-10),20, 0)
	mc.setBlock(v + Vec3(2,-4,-9),20, 0)
	mc.setBlock(v + Vec3(2,-4,-8),20, 0)
	mc.setBlock(v + Vec3(2,-4,-7),49, 0)
	mc.setBlock(v + Vec3(2,-4,-6),49, 0)
	mc.setBlock(v + Vec3(2,-4,-5),49, 0)
	mc.setBlock(v + Vec3(2,-4,-4),20, 0)
	mc.setBlock(v + Vec3(2,-4,-3),20, 0)
	mc.setBlock(v + Vec3(2,-4,-2),20, 0)
	mc.setBlock(v + Vec3(2,-4,-1),155, 0)
	mc.setBlock(v + Vec3(2,-4,0),4, 0)
	mc.setBlock(v + Vec3(2,-4,1),35, 14)
	mc.setBlock(v + Vec3(2,-4,2),35, 14)
	mc.setBlock(v + Vec3(2,-4,3),35, 14)
	mc.setBlock(v + Vec3(2,-4,4),35, 14)
	mc.setBlock(v + Vec3(2,-4,5),35, 14)
	mc.setBlock(v + Vec3(2,-4,6),35, 14)
	mc.setBlock(v + Vec3(2,-4,7),35, 14)
	mc.setBlock(v + Vec3(2,-4,8),35, 14)
	mc.setBlock(v + Vec3(2,-4,9),4, 0)
	mc.setBlock(v + Vec3(2,-4,10),20, 0)
	mc.setBlock(v + Vec3(2,-4,11),49, 0)
	mc.setBlock(v + Vec3(2,-4,12),49, 0)
	mc.setBlock(v + Vec3(2,-4,13),49, 0)
	mc.setBlock(v + Vec3(2,-4,14),20, 0)
	mc.setBlock(v + Vec3(2,-4,15),20, 0)
	mc.setBlock(v + Vec3(3,-4,-16),49, 0)
	mc.setBlock(v + Vec3(3,-4,-15),49, 0)
	mc.setBlock(v + Vec3(3,-4,-14),49, 0)
	mc.setBlock(v + Vec3(3,-4,-13),49, 0)
	mc.setBlock(v + Vec3(3,-4,-12),49, 0)
	mc.setBlock(v + Vec3(3,-4,-11),49, 0)
	mc.setBlock(v + Vec3(3,-4,-10),49, 0)
	mc.setBlock(v + Vec3(3,-4,-9),49, 0)
	mc.setBlock(v + Vec3(3,-4,-8),49, 0)
	mc.setBlock(v + Vec3(3,-4,-7),49, 0)
	mc.setBlock(v + Vec3(3,-4,-6),49, 0)
	mc.setBlock(v + Vec3(3,-4,-5),49, 0)
	mc.setBlock(v + Vec3(3,-4,-4),49, 0)
	mc.setBlock(v + Vec3(3,-4,-3),49, 0)
	mc.setBlock(v + Vec3(3,-4,-2),49, 0)
	mc.setBlock(v + Vec3(3,-4,-1),155, 0)
	mc.setBlock(v + Vec3(3,-4,0),4, 0)
	mc.setBlock(v + Vec3(3,-4,1),35, 14)
	mc.setBlock(v + Vec3(3,-4,2),35, 1)
	mc.setBlock(v + Vec3(3,-4,3),35, 1)
	mc.setBlock(v + Vec3(3,-4,4),35, 1)
	mc.setBlock(v + Vec3(3,-4,5),35, 1)
	mc.setBlock(v + Vec3(3,-4,6),35, 1)
	mc.setBlock(v + Vec3(3,-4,7),35, 1)
	mc.setBlock(v + Vec3(3,-4,8),35, 14)
	mc.setBlock(v + Vec3(3,-4,9),4, 0)
	mc.setBlock(v + Vec3(3,-4,10),49, 0)
	mc.setBlock(v + Vec3(3,-4,11),49, 0)
	mc.setBlock(v + Vec3(3,-4,12),49, 0)
	mc.setBlock(v + Vec3(3,-4,13),49, 0)
	mc.setBlock(v + Vec3(3,-4,14),49, 0)
	mc.setBlock(v + Vec3(3,-4,15),49, 0)
	mc.setBlock(v + Vec3(4,-4,-16),20, 0)
	mc.setBlock(v + Vec3(4,-4,-15),20, 0)
	mc.setBlock(v + Vec3(4,-4,-14),20, 0)
	mc.setBlock(v + Vec3(4,-4,-13),49, 0)
	mc.setBlock(v + Vec3(4,-4,-12),49, 0)
	mc.setBlock(v + Vec3(4,-4,-11),49, 0)
	mc.setBlock(v + Vec3(4,-4,-10),20, 0)
	mc.setBlock(v + Vec3(4,-4,-9),20, 0)
	mc.setBlock(v + Vec3(4,-4,-8),20, 0)
	mc.setBlock(v + Vec3(4,-4,-7),49, 0)
	mc.setBlock(v + Vec3(4,-4,-6),49, 0)
	mc.setBlock(v + Vec3(4,-4,-5),49, 0)
	mc.setBlock(v + Vec3(4,-4,-4),20, 0)
	mc.setBlock(v + Vec3(4,-4,-3),20, 0)
	mc.setBlock(v + Vec3(4,-4,-2),20, 0)
	mc.setBlock(v + Vec3(4,-4,-1),155, 0)
	mc.setBlock(v + Vec3(4,-4,0),4, 0)
	mc.setBlock(v + Vec3(4,-4,1),35, 14)
	mc.setBlock(v + Vec3(4,-4,2),35, 1)
	mc.setBlock(v + Vec3(4,-4,3),35, 4)
	mc.setBlock(v + Vec3(4,-4,4),35, 4)
	mc.setBlock(v + Vec3(4,-4,5),35, 4)
	mc.setBlock(v + Vec3(4,-4,6),35, 4)
	mc.setBlock(v + Vec3(4,-4,7),35, 1)
	mc.setBlock(v + Vec3(4,-4,8),35, 14)
	mc.setBlock(v + Vec3(4,-4,9),4, 0)
	mc.setBlock(v + Vec3(4,-4,10),20, 0)
	mc.setBlock(v + Vec3(4,-4,11),49, 0)
	mc.setBlock(v + Vec3(4,-4,12),49, 0)
	mc.setBlock(v + Vec3(4,-4,13),49, 0)
	mc.setBlock(v + Vec3(4,-4,14),20, 0)
	mc.setBlock(v + Vec3(4,-4,15),20, 0)
	mc.setBlock(v + Vec3(5,-4,-16),20, 0)
	mc.setBlock(v + Vec3(5,-4,-15),20, 0)
	mc.setBlock(v + Vec3(5,-4,-14),20, 0)
	mc.setBlock(v + Vec3(5,-4,-13),20, 0)
	mc.setBlock(v + Vec3(5,-4,-12),49, 0)
	mc.setBlock(v + Vec3(5,-4,-11),20, 0)
	mc.setBlock(v + Vec3(5,-4,-10),20, 0)
	mc.setBlock(v + Vec3(5,-4,-9),20, 0)
	mc.setBlock(v + Vec3(5,-4,-8),20, 0)
	mc.setBlock(v + Vec3(5,-4,-7),20, 0)
	mc.setBlock(v + Vec3(5,-4,-6),49, 0)
	mc.setBlock(v + Vec3(5,-4,-5),20, 0)
	mc.setBlock(v + Vec3(5,-4,-4),20, 0)
	mc.setBlock(v + Vec3(5,-4,-3),20, 0)
	mc.setBlock(v + Vec3(5,-4,-2),20, 0)
	mc.setBlock(v + Vec3(5,-4,-1),155, 0)
	mc.setBlock(v + Vec3(5,-4,0),4, 0)
	mc.setBlock(v + Vec3(5,-4,1),35, 14)
	mc.setBlock(v + Vec3(5,-4,2),35, 1)
	mc.setBlock(v + Vec3(5,-4,3),35, 4)
	mc.setBlock(v + Vec3(5,-4,4),35, 3)
	mc.setBlock(v + Vec3(5,-4,5),35, 3)
	mc.setBlock(v + Vec3(5,-4,6),35, 4)
	mc.setBlock(v + Vec3(5,-4,7),35, 1)
	mc.setBlock(v + Vec3(5,-4,8),35, 14)
	mc.setBlock(v + Vec3(5,-4,9),4, 0)
	mc.setBlock(v + Vec3(5,-4,10),20, 0)
	mc.setBlock(v + Vec3(5,-4,11),20, 0)
	mc.setBlock(v + Vec3(5,-4,12),49, 0)
	mc.setBlock(v + Vec3(5,-4,13),20, 0)
	mc.setBlock(v + Vec3(5,-4,14),20, 0)
	mc.setBlock(v + Vec3(5,-4,15),246, 0)
	mc.setBlock(v + Vec3(6,-4,-16),20, 0)
	mc.setBlock(v + Vec3(6,-4,-15),20, 0)
	mc.setBlock(v + Vec3(6,-4,-14),20, 0)
	mc.setBlock(v + Vec3(6,-4,-13),20, 0)
	mc.setBlock(v + Vec3(6,-4,-12),49, 0)
	mc.setBlock(v + Vec3(6,-4,-11),20, 0)
	mc.setBlock(v + Vec3(6,-4,-10),20, 0)
	mc.setBlock(v + Vec3(6,-4,-9),20, 0)
	mc.setBlock(v + Vec3(6,-4,-8),20, 0)
	mc.setBlock(v + Vec3(6,-4,-7),20, 0)
	mc.setBlock(v + Vec3(6,-4,-6),49, 0)
	mc.setBlock(v + Vec3(6,-4,-5),20, 0)
	mc.setBlock(v + Vec3(6,-4,-4),20, 0)
	mc.setBlock(v + Vec3(6,-4,-3),20, 0)
	mc.setBlock(v + Vec3(6,-4,-2),20, 0)
	mc.setBlock(v + Vec3(6,-4,-1),155, 0)
	mc.setBlock(v + Vec3(6,-4,0),4, 0)
	mc.setBlock(v + Vec3(6,-4,1),35, 14)
	mc.setBlock(v + Vec3(6,-4,2),35, 1)
	mc.setBlock(v + Vec3(6,-4,3),35, 4)
	mc.setBlock(v + Vec3(6,-4,4),35, 4)
	mc.setBlock(v + Vec3(6,-4,5),35, 4)
	mc.setBlock(v + Vec3(6,-4,6),35, 4)
	mc.setBlock(v + Vec3(6,-4,7),35, 1)
	mc.setBlock(v + Vec3(6,-4,8),35, 14)
	mc.setBlock(v + Vec3(6,-4,9),4, 0)
	mc.setBlock(v + Vec3(6,-4,10),20, 0)
	mc.setBlock(v + Vec3(6,-4,11),20, 0)
	mc.setBlock(v + Vec3(6,-4,12),49, 0)
	mc.setBlock(v + Vec3(6,-4,13),20, 0)
	mc.setBlock(v + Vec3(6,-4,14),246, 0)
	mc.setBlock(v + Vec3(7,-4,-16),20, 0)
	mc.setBlock(v + Vec3(7,-4,-15),20, 0)
	mc.setBlock(v + Vec3(7,-4,-14),20, 0)
	mc.setBlock(v + Vec3(7,-4,-13),20, 0)
	mc.setBlock(v + Vec3(7,-4,-12),49, 0)
	mc.setBlock(v + Vec3(7,-4,-11),20, 0)
	mc.setBlock(v + Vec3(7,-4,-10),20, 0)
	mc.setBlock(v + Vec3(7,-4,-9),20, 0)
	mc.setBlock(v + Vec3(7,-4,-8),20, 0)
	mc.setBlock(v + Vec3(7,-4,-7),20, 0)
	mc.setBlock(v + Vec3(7,-4,-6),49, 0)
	mc.setBlock(v + Vec3(7,-4,-5),20, 0)
	mc.setBlock(v + Vec3(7,-4,-4),20, 0)
	mc.setBlock(v + Vec3(7,-4,-3),20, 0)
	mc.setBlock(v + Vec3(7,-4,-2),20, 0)
	mc.setBlock(v + Vec3(7,-4,-1),155, 0)
	mc.setBlock(v + Vec3(7,-4,0),4, 0)
	mc.setBlock(v + Vec3(7,-4,1),35, 14)
	mc.setBlock(v + Vec3(7,-4,2),35, 1)
	mc.setBlock(v + Vec3(7,-4,3),35, 1)
	mc.setBlock(v + Vec3(7,-4,4),35, 1)
	mc.setBlock(v + Vec3(7,-4,5),35, 1)
	mc.setBlock(v + Vec3(7,-4,6),35, 1)
	mc.setBlock(v + Vec3(7,-4,7),35, 1)
	mc.setBlock(v + Vec3(7,-4,8),35, 14)
	mc.setBlock(v + Vec3(7,-4,9),4, 0)
	mc.setBlock(v + Vec3(7,-4,10),20, 0)
	mc.setBlock(v + Vec3(7,-4,11),20, 0)
	mc.setBlock(v + Vec3(7,-4,12),49, 0)
	mc.setBlock(v + Vec3(7,-4,13),246, 0)
	mc.setBlock(v + Vec3(8,-4,-16),20, 0)
	mc.setBlock(v + Vec3(8,-4,-15),20, 0)
	mc.setBlock(v + Vec3(8,-4,-14),20, 0)
	mc.setBlock(v + Vec3(8,-4,-13),49, 0)
	mc.setBlock(v + Vec3(8,-4,-12),49, 0)
	mc.setBlock(v + Vec3(8,-4,-11),49, 0)
	mc.setBlock(v + Vec3(8,-4,-10),20, 0)
	mc.setBlock(v + Vec3(8,-4,-9),20, 0)
	mc.setBlock(v + Vec3(8,-4,-8),20, 0)
	mc.setBlock(v + Vec3(8,-4,-7),49, 0)
	mc.setBlock(v + Vec3(8,-4,-6),49, 0)
	mc.setBlock(v + Vec3(8,-4,-5),49, 0)
	mc.setBlock(v + Vec3(8,-4,-4),20, 0)
	mc.setBlock(v + Vec3(8,-4,-3),20, 0)
	mc.setBlock(v + Vec3(8,-4,-2),20, 0)
	mc.setBlock(v + Vec3(8,-4,-1),155, 0)
	mc.setBlock(v + Vec3(8,-4,0),4, 0)
	mc.setBlock(v + Vec3(8,-4,1),35, 14)
	mc.setBlock(v + Vec3(8,-4,2),35, 14)
	mc.setBlock(v + Vec3(8,-4,3),35, 14)
	mc.setBlock(v + Vec3(8,-4,4),35, 14)
	mc.setBlock(v + Vec3(8,-4,5),35, 14)
	mc.setBlock(v + Vec3(8,-4,6),35, 14)
	mc.setBlock(v + Vec3(8,-4,7),35, 14)
	mc.setBlock(v + Vec3(8,-4,8),35, 14)
	mc.setBlock(v + Vec3(8,-4,9),4, 0)
	mc.setBlock(v + Vec3(8,-4,10),155, 0)
	mc.setBlock(v + Vec3(8,-4,11),155, 0)
	mc.setBlock(v + Vec3(8,-4,12),49, 0)
	mc.setBlock(v + Vec3(8,-4,13),246, 0)
	mc.setBlock(v + Vec3(9,-4,-16),49, 0)
	mc.setBlock(v + Vec3(9,-4,-15),49, 0)
	mc.setBlock(v + Vec3(9,-4,-14),49, 0)
	mc.setBlock(v + Vec3(9,-4,-13),49, 0)
	mc.setBlock(v + Vec3(9,-4,-12),49, 0)
	mc.setBlock(v + Vec3(9,-4,-11),49, 0)
	mc.setBlock(v + Vec3(9,-4,-10),49, 0)
	mc.setBlock(v + Vec3(9,-4,-9),49, 0)
	mc.setBlock(v + Vec3(9,-4,-8),49, 0)
	mc.setBlock(v + Vec3(9,-4,-7),49, 0)
	mc.setBlock(v + Vec3(9,-4,-6),49, 0)
	mc.setBlock(v + Vec3(9,-4,-5),49, 0)
	mc.setBlock(v + Vec3(9,-4,-4),49, 0)
	mc.setBlock(v + Vec3(9,-4,-2),155, 0)
	mc.setBlock(v + Vec3(9,-4,-1),155, 0)
	mc.setBlock(v + Vec3(9,-4,0),4, 0)
	mc.setBlock(v + Vec3(9,-4,1),4, 0)
	mc.setBlock(v + Vec3(9,-4,2),4, 0)
	mc.setBlock(v + Vec3(9,-4,3),4, 0)
	mc.setBlock(v + Vec3(9,-4,4),4, 0)
	mc.setBlock(v + Vec3(9,-4,5),4, 0)
	mc.setBlock(v + Vec3(9,-4,6),4, 0)
	mc.setBlock(v + Vec3(9,-4,7),4, 0)
	mc.setBlock(v + Vec3(9,-4,8),4, 0)
	mc.setBlock(v + Vec3(9,-4,9),4, 0)
	mc.setBlock(v + Vec3(9,-4,10),155, 0)
	mc.setBlock(v + Vec3(9,-4,11),155, 0)
	mc.setBlock(v + Vec3(9,-4,12),49, 0)
	mc.setBlock(v + Vec3(9,-4,13),246, 0)
	mc.setBlock(v + Vec3(10,-4,-16),20, 0)
	mc.setBlock(v + Vec3(10,-4,-15),20, 0)
	mc.setBlock(v + Vec3(10,-4,-14),20, 0)
	mc.setBlock(v + Vec3(10,-4,-13),49, 0)
	mc.setBlock(v + Vec3(10,-4,-12),49, 0)
	mc.setBlock(v + Vec3(10,-4,-11),49, 0)
	mc.setBlock(v + Vec3(10,-4,-10),20, 0)
	mc.setBlock(v + Vec3(10,-4,-9),20, 0)
	mc.setBlock(v + Vec3(10,-4,-8),20, 0)
	mc.setBlock(v + Vec3(10,-4,-7),49, 0)
	mc.setBlock(v + Vec3(10,-4,-6),49, 0)
	mc.setBlock(v + Vec3(10,-4,-5),49, 0)
	mc.setBlock(v + Vec3(10,-4,-4),20, 0)
	mc.setBlock(v + Vec3(10,-4,-2),155, 0)
	mc.setBlock(v + Vec3(10,-4,-1),155, 0)
	mc.setBlock(v + Vec3(10,-4,10),155, 0)
	mc.setBlock(v + Vec3(10,-4,11),155, 0)
	mc.setBlock(v + Vec3(10,-4,12),49, 0)
	mc.setBlock(v + Vec3(10,-4,13),246, 0)
	mc.setBlock(v + Vec3(11,-4,-16),20, 0)
	mc.setBlock(v + Vec3(11,-4,-15),20, 0)
	mc.setBlock(v + Vec3(11,-4,-14),20, 0)
	mc.setBlock(v + Vec3(11,-4,-13),20, 0)
	mc.setBlock(v + Vec3(11,-4,-12),49, 0)
	mc.setBlock(v + Vec3(11,-4,-11),20, 0)
	mc.setBlock(v + Vec3(11,-4,-10),20, 0)
	mc.setBlock(v + Vec3(11,-4,-9),20, 0)
	mc.setBlock(v + Vec3(11,-4,-8),20, 0)
	mc.setBlock(v + Vec3(11,-4,-7),20, 0)
	mc.setBlock(v + Vec3(11,-4,-6),49, 0)
	mc.setBlock(v + Vec3(11,-4,-5),20, 0)
	mc.setBlock(v + Vec3(11,-4,-4),20, 0)
	mc.setBlock(v + Vec3(11,-4,-2),155, 0)
	mc.setBlock(v + Vec3(11,-4,-1),155, 0)
	mc.setBlock(v + Vec3(11,-4,0),155, 0)
	mc.setBlock(v + Vec3(11,-4,1),155, 0)
	mc.setBlock(v + Vec3(11,-4,2),155, 0)
	mc.setBlock(v + Vec3(11,-4,3),155, 0)
	mc.setBlock(v + Vec3(11,-4,4),155, 0)
	mc.setBlock(v + Vec3(11,-4,5),155, 0)
	mc.setBlock(v + Vec3(11,-4,6),155, 0)
	mc.setBlock(v + Vec3(11,-4,7),155, 0)
	mc.setBlock(v + Vec3(11,-4,8),155, 0)
	mc.setBlock(v + Vec3(11,-4,9),155, 0)
	mc.setBlock(v + Vec3(11,-4,10),155, 0)
	mc.setBlock(v + Vec3(11,-4,12),49, 0)
	mc.setBlock(v + Vec3(11,-4,13),246, 0)
	mc.setBlock(v + Vec3(12,-4,-16),20, 0)
	mc.setBlock(v + Vec3(12,-4,-15),20, 0)
	mc.setBlock(v + Vec3(12,-4,-14),20, 0)
	mc.setBlock(v + Vec3(12,-4,-13),20, 0)
	mc.setBlock(v + Vec3(12,-4,-12),49, 0)
	mc.setBlock(v + Vec3(12,-4,-11),20, 0)
	mc.setBlock(v + Vec3(12,-4,-10),20, 0)
	mc.setBlock(v + Vec3(12,-4,-9),20, 0)
	mc.setBlock(v + Vec3(12,-4,-8),20, 0)
	mc.setBlock(v + Vec3(12,-4,-7),20, 0)
	mc.setBlock(v + Vec3(12,-4,-6),49, 0)
	mc.setBlock(v + Vec3(12,-4,-5),20, 0)
	mc.setBlock(v + Vec3(12,-4,-4),20, 0)
	mc.setBlock(v + Vec3(12,-4,5),60, 0)
	mc.setBlock(v + Vec3(12,-4,12),49, 0)
	mc.setBlock(v + Vec3(12,-4,13),20, 0)
	mc.setBlock(v + Vec3(12,-4,14),246, 0)
	mc.setBlock(v + Vec3(13,-4,-16),20, 0)
	mc.setBlock(v + Vec3(13,-4,-15),20, 0)
	mc.setBlock(v + Vec3(13,-4,-14),20, 0)
	mc.setBlock(v + Vec3(13,-4,-13),20, 0)
	mc.setBlock(v + Vec3(13,-4,-12),49, 0)
	mc.setBlock(v + Vec3(13,-4,-11),20, 0)
	mc.setBlock(v + Vec3(13,-4,-10),20, 0)
	mc.setBlock(v + Vec3(13,-4,-9),20, 0)
	mc.setBlock(v + Vec3(13,-4,-8),20, 0)
	mc.setBlock(v + Vec3(13,-4,-7),20, 0)
	mc.setBlock(v + Vec3(13,-4,-6),49, 0)
	mc.setBlock(v + Vec3(13,-4,-5),20, 0)
	mc.setBlock(v + Vec3(13,-4,-4),20, 0)
	mc.setBlock(v + Vec3(13,-4,2),60, 0)
	mc.setBlock(v + Vec3(13,-4,9),60, 0)
	mc.setBlock(v + Vec3(13,-4,12),49, 0)
	mc.setBlock(v + Vec3(13,-4,13),20, 0)
	mc.setBlock(v + Vec3(13,-4,14),20, 0)
	mc.setBlock(v + Vec3(13,-4,15),246, 0)
	mc.setBlock(v + Vec3(14,-4,-16),20, 0)
	mc.setBlock(v + Vec3(14,-4,-15),20, 0)
	mc.setBlock(v + Vec3(14,-4,-14),20, 0)
	mc.setBlock(v + Vec3(14,-4,-13),49, 0)
	mc.setBlock(v + Vec3(14,-4,-12),49, 0)
	mc.setBlock(v + Vec3(14,-4,-11),49, 0)
	mc.setBlock(v + Vec3(14,-4,-10),20, 0)
	mc.setBlock(v + Vec3(14,-4,-9),20, 0)
	mc.setBlock(v + Vec3(14,-4,-8),20, 0)
	mc.setBlock(v + Vec3(14,-4,-7),49, 0)
	mc.setBlock(v + Vec3(14,-4,-6),49, 0)
	mc.setBlock(v + Vec3(14,-4,-5),49, 0)
	mc.setBlock(v + Vec3(14,-4,-4),20, 0)
	mc.setBlock(v + Vec3(14,-4,12),49, 0)
	mc.setBlock(v + Vec3(14,-4,13),49, 0)
	mc.setBlock(v + Vec3(14,-4,14),20, 0)
	mc.setBlock(v + Vec3(14,-4,15),20, 0)
	mc.setBlock(v + Vec3(15,-4,-16),49, 0)
	mc.setBlock(v + Vec3(15,-4,-15),49, 0)
	mc.setBlock(v + Vec3(15,-4,-14),49, 0)
	mc.setBlock(v + Vec3(15,-4,-13),49, 0)
	mc.setBlock(v + Vec3(15,-4,-12),49, 0)
	mc.setBlock(v + Vec3(15,-4,-11),49, 0)
	mc.setBlock(v + Vec3(15,-4,-10),49, 0)
	mc.setBlock(v + Vec3(15,-4,-9),49, 0)
	mc.setBlock(v + Vec3(15,-4,-8),49, 0)
	mc.setBlock(v + Vec3(15,-4,-7),49, 0)
	mc.setBlock(v + Vec3(15,-4,-6),49, 0)
	mc.setBlock(v + Vec3(15,-4,-5),49, 0)
	mc.setBlock(v + Vec3(15,-4,-4),49, 0)
	mc.setBlock(v + Vec3(15,-4,2),60, 0)
	mc.setBlock(v + Vec3(15,-4,12),49, 0)
	mc.setBlock(v + Vec3(15,-4,13),49, 0)
	mc.setBlock(v + Vec3(15,-4,14),49, 0)
	mc.setBlock(v + Vec3(15,-4,15),49, 0)
	mc.setBlock(v + Vec3(16,-4,-16),20, 0)
	mc.setBlock(v + Vec3(16,-4,-15),20, 0)
	mc.setBlock(v + Vec3(16,-4,-14),20, 0)
	mc.setBlock(v + Vec3(16,-4,-13),49, 0)
	mc.setBlock(v + Vec3(16,-4,-12),49, 0)
	mc.setBlock(v + Vec3(16,-4,-11),49, 0)
	mc.setBlock(v + Vec3(16,-4,-10),20, 0)
	mc.setBlock(v + Vec3(16,-4,-9),20, 0)
	mc.setBlock(v + Vec3(16,-4,-8),20, 0)
	mc.setBlock(v + Vec3(16,-4,-7),49, 0)
	mc.setBlock(v + Vec3(16,-4,-6),49, 0)
	mc.setBlock(v + Vec3(16,-4,-5),49, 0)
	mc.setBlock(v + Vec3(16,-4,-4),20, 0)
	mc.setBlock(v + Vec3(16,-4,3),60, 0)
	mc.setBlock(v + Vec3(16,-4,5),60, 0)
	mc.setBlock(v + Vec3(16,-4,12),49, 0)
	mc.setBlock(v + Vec3(16,-4,13),49, 0)
	mc.setBlock(v + Vec3(16,-4,14),20, 0)
	mc.setBlock(v + Vec3(16,-4,15),20, 0)
	mc.setBlock(v + Vec3(17,-4,-16),20, 0)
	mc.setBlock(v + Vec3(17,-4,-15),20, 0)
	mc.setBlock(v + Vec3(17,-4,-14),20, 0)
	mc.setBlock(v + Vec3(17,-4,-13),20, 0)
	mc.setBlock(v + Vec3(17,-4,-12),49, 0)
	mc.setBlock(v + Vec3(17,-4,-11),20, 0)
	mc.setBlock(v + Vec3(17,-4,-10),20, 0)
	mc.setBlock(v + Vec3(17,-4,-9),20, 0)
	mc.setBlock(v + Vec3(17,-4,-8),20, 0)
	mc.setBlock(v + Vec3(17,-4,-7),20, 0)
	mc.setBlock(v + Vec3(17,-4,-6),49, 0)
	mc.setBlock(v + Vec3(17,-4,-5),20, 0)
	mc.setBlock(v + Vec3(17,-4,-4),20, 0)
	mc.setBlock(v + Vec3(17,-4,12),49, 0)
	mc.setBlock(v + Vec3(17,-4,13),20, 0)
	mc.setBlock(v + Vec3(17,-4,14),20, 0)
	mc.setBlock(v + Vec3(17,-4,15),20, 0)
	mc.setBlock(v + Vec3(18,-4,-16),20, 0)
	mc.setBlock(v + Vec3(18,-4,-15),20, 0)
	mc.setBlock(v + Vec3(18,-4,-14),20, 0)
	mc.setBlock(v + Vec3(18,-4,-13),20, 0)
	mc.setBlock(v + Vec3(18,-4,-12),49, 0)
	mc.setBlock(v + Vec3(18,-4,-11),20, 0)
	mc.setBlock(v + Vec3(18,-4,-10),20, 0)
	mc.setBlock(v + Vec3(18,-4,-9),20, 0)
	mc.setBlock(v + Vec3(18,-4,-8),20, 0)
	mc.setBlock(v + Vec3(18,-4,-7),20, 0)
	mc.setBlock(v + Vec3(18,-4,-6),49, 0)
	mc.setBlock(v + Vec3(18,-4,-5),20, 0)
	mc.setBlock(v + Vec3(18,-4,-4),20, 0)
	mc.setBlock(v + Vec3(18,-4,4),60, 0)
	mc.setBlock(v + Vec3(18,-4,12),49, 0)
	mc.setBlock(v + Vec3(18,-4,13),20, 0)
	mc.setBlock(v + Vec3(18,-4,14),20, 0)
	mc.setBlock(v + Vec3(18,-4,15),20, 0)
	mc.setBlock(v + Vec3(19,-4,-16),20, 0)
	mc.setBlock(v + Vec3(19,-4,-15),20, 0)
	mc.setBlock(v + Vec3(19,-4,-14),20, 0)
	mc.setBlock(v + Vec3(19,-4,-13),20, 0)
	mc.setBlock(v + Vec3(19,-4,-12),49, 0)
	mc.setBlock(v + Vec3(19,-4,-11),20, 0)
	mc.setBlock(v + Vec3(19,-4,-10),20, 0)
	mc.setBlock(v + Vec3(19,-4,-9),20, 0)
	mc.setBlock(v + Vec3(19,-4,-8),20, 0)
	mc.setBlock(v + Vec3(19,-4,-7),20, 0)
	mc.setBlock(v + Vec3(19,-4,-6),49, 0)
	mc.setBlock(v + Vec3(19,-4,-5),20, 0)
	mc.setBlock(v + Vec3(19,-4,-4),20, 0)
	mc.setBlock(v + Vec3(19,-4,12),49, 0)
	mc.setBlock(v + Vec3(19,-4,13),20, 0)
	mc.setBlock(v + Vec3(19,-4,14),20, 0)
	mc.setBlock(v + Vec3(19,-4,15),20, 0)
	mc.setBlock(v + Vec3(20,-4,-16),20, 0)
	mc.setBlock(v + Vec3(20,-4,-15),20, 0)
	mc.setBlock(v + Vec3(20,-4,-14),20, 0)
	mc.setBlock(v + Vec3(20,-4,-13),49, 0)
	mc.setBlock(v + Vec3(20,-4,-12),49, 0)
	mc.setBlock(v + Vec3(20,-4,-11),49, 0)
	mc.setBlock(v + Vec3(20,-4,-10),20, 0)
	mc.setBlock(v + Vec3(20,-4,-9),20, 0)
	mc.setBlock(v + Vec3(20,-4,-8),20, 0)
	mc.setBlock(v + Vec3(20,-4,-7),49, 0)
	mc.setBlock(v + Vec3(20,-4,-6),49, 0)
	mc.setBlock(v + Vec3(20,-4,-5),49, 0)
	mc.setBlock(v + Vec3(20,-4,-4),20, 0)
	mc.setBlock(v + Vec3(20,-4,-3),20, 0)
	mc.setBlock(v + Vec3(20,-4,-2),20, 0)
	mc.setBlock(v + Vec3(20,-4,-1),49, 0)
	mc.setBlock(v + Vec3(20,-4,0),49, 0)
	mc.setBlock(v + Vec3(20,-4,1),49, 0)
	mc.setBlock(v + Vec3(20,-4,2),20, 0)
	mc.setBlock(v + Vec3(20,-4,3),20, 0)
	mc.setBlock(v + Vec3(20,-4,4),20, 0)
	mc.setBlock(v + Vec3(20,-4,5),49, 0)
	mc.setBlock(v + Vec3(20,-4,6),49, 0)
	mc.setBlock(v + Vec3(20,-4,7),49, 0)
	mc.setBlock(v + Vec3(20,-4,8),20, 0)
	mc.setBlock(v + Vec3(20,-4,9),20, 0)
	mc.setBlock(v + Vec3(20,-4,10),20, 0)
	mc.setBlock(v + Vec3(20,-4,11),49, 0)
	mc.setBlock(v + Vec3(20,-4,12),49, 0)
	mc.setBlock(v + Vec3(20,-4,13),49, 0)
	mc.setBlock(v + Vec3(20,-4,14),20, 0)
	mc.setBlock(v + Vec3(20,-4,15),20, 0)
	mc.setBlock(v + Vec3(21,-4,-16),49, 0)
	mc.setBlock(v + Vec3(21,-4,-15),49, 0)
	mc.setBlock(v + Vec3(21,-4,-14),49, 0)
	mc.setBlock(v + Vec3(21,-4,-13),49, 0)
	mc.setBlock(v + Vec3(21,-4,-12),49, 0)
	mc.setBlock(v + Vec3(21,-4,-11),49, 0)
	mc.setBlock(v + Vec3(21,-4,-10),49, 0)
	mc.setBlock(v + Vec3(21,-4,-9),49, 0)
	mc.setBlock(v + Vec3(21,-4,-8),49, 0)
	mc.setBlock(v + Vec3(21,-4,-7),49, 0)
	mc.setBlock(v + Vec3(21,-4,-6),49, 0)
	mc.setBlock(v + Vec3(21,-4,-5),49, 0)
	mc.setBlock(v + Vec3(21,-4,-4),49, 0)
	mc.setBlock(v + Vec3(21,-4,-3),49, 0)
	mc.setBlock(v + Vec3(21,-4,-2),49, 0)
	mc.setBlock(v + Vec3(21,-4,-1),49, 0)
	mc.setBlock(v + Vec3(21,-4,0),49, 0)
	mc.setBlock(v + Vec3(21,-4,1),49, 0)
	mc.setBlock(v + Vec3(21,-4,2),49, 0)
	mc.setBlock(v + Vec3(21,-4,3),49, 0)
	mc.setBlock(v + Vec3(21,-4,4),49, 0)
	mc.setBlock(v + Vec3(21,-4,5),49, 0)
	mc.setBlock(v + Vec3(21,-4,6),49, 0)
	mc.setBlock(v + Vec3(21,-4,7),49, 0)
	mc.setBlock(v + Vec3(21,-4,8),49, 0)
	mc.setBlock(v + Vec3(21,-4,9),49, 0)
	mc.setBlock(v + Vec3(21,-4,10),49, 0)
	mc.setBlock(v + Vec3(21,-4,11),49, 0)
	mc.setBlock(v + Vec3(21,-4,12),49, 0)
	mc.setBlock(v + Vec3(21,-4,13),49, 0)
	mc.setBlock(v + Vec3(21,-4,14),49, 0)
	mc.setBlock(v + Vec3(21,-4,15),49, 0)
	mc.setBlock(v + Vec3(-21,-3,9),85, 0)
	mc.setBlock(v + Vec3(-20,-3,-13),85, 0)
	mc.setBlock(v + Vec3(-20,-3,-12),85, 0)
	mc.setBlock(v + Vec3(-20,-3,-11),85, 0)
	mc.setBlock(v + Vec3(-20,-3,-10),85, 0)
	mc.setBlock(v + Vec3(-20,-3,-9),85, 0)
	mc.setBlock(v + Vec3(-20,-3,-8),85, 0)
	mc.setBlock(v + Vec3(-20,-3,3),85, 0)
	mc.setBlock(v + Vec3(-20,-3,6),85, 0)
	mc.setBlock(v + Vec3(-20,-3,7),85, 0)
	mc.setBlock(v + Vec3(-20,-3,12),85, 0)
	mc.setBlock(v + Vec3(-19,-3,-13),85, 0)
	mc.setBlock(v + Vec3(-19,-3,-12),59, 7)
	mc.setBlock(v + Vec3(-19,-3,-11),59, 7)
	mc.setBlock(v + Vec3(-19,-3,-10),59, 7)
	mc.setBlock(v + Vec3(-19,-3,-9),59, 7)
	mc.setBlock(v + Vec3(-19,-3,-8),85, 0)
	mc.setBlock(v + Vec3(-19,-3,8),85, 0)
	mc.setBlock(v + Vec3(-19,-3,10),85, 0)
	mc.setBlock(v + Vec3(-18,-3,-13),85, 0)
	mc.setBlock(v + Vec3(-18,-3,-8),85, 0)
	mc.setBlock(v + Vec3(-18,-3,14),85, 0)
	mc.setBlock(v + Vec3(-17,-3,-13),85, 0)
	mc.setBlock(v + Vec3(-17,-3,-8),85, 0)
	mc.setBlock(v + Vec3(-17,-3,12),85, 0)
	mc.setBlock(v + Vec3(-17,-3,13),85, 0)
	mc.setBlock(v + Vec3(-17,-3,14),85, 0)
	mc.setBlock(v + Vec3(-17,-3,15),85, 0)
	mc.setBlock(v + Vec3(-16,-3,-13),107, 2)
	mc.setBlock(v + Vec3(-16,-3,-10),59, 7)
	mc.setBlock(v + Vec3(-16,-3,-9),59, 7)
	mc.setBlock(v + Vec3(-16,-3,-8),85, 0)
	mc.setBlock(v + Vec3(-15,-3,-13),85, 0)
	mc.setBlock(v + Vec3(-15,-3,-12),59, 7)
	mc.setBlock(v + Vec3(-15,-3,-11),59, 7)
	mc.setBlock(v + Vec3(-15,-3,-10),59, 7)
	mc.setBlock(v + Vec3(-15,-3,-9),59, 7)
	mc.setBlock(v + Vec3(-15,-3,-8),85, 0)
	mc.setBlock(v + Vec3(-15,-3,-2),98, 0)
	mc.setBlock(v + Vec3(-15,-3,2),98, 0)
	mc.setBlock(v + Vec3(-14,-3,-13),85, 0)
	mc.setBlock(v + Vec3(-14,-3,-12),59, 7)
	mc.setBlock(v + Vec3(-14,-3,-11),59, 7)
	mc.setBlock(v + Vec3(-14,-3,-10),59, 7)
	mc.setBlock(v + Vec3(-14,-3,-9),59, 7)
	mc.setBlock(v + Vec3(-14,-3,-8),85, 0)
	mc.setBlock(v + Vec3(-14,-3,-2),98, 0)
	mc.setBlock(v + Vec3(-14,-3,-1),67, 3)
	mc.setBlock(v + Vec3(-14,-3,0),67, 0)
	mc.setBlock(v + Vec3(-14,-3,1),67, 2)
	mc.setBlock(v + Vec3(-14,-3,2),98, 0)
	mc.setBlock(v + Vec3(-13,-3,-13),85, 0)
	mc.setBlock(v + Vec3(-13,-3,-12),85, 0)
	mc.setBlock(v + Vec3(-13,-3,-11),85, 0)
	mc.setBlock(v + Vec3(-13,-3,-10),85, 0)
	mc.setBlock(v + Vec3(-13,-3,-9),85, 0)
	mc.setBlock(v + Vec3(-13,-3,-8),85, 0)
	mc.setBlock(v + Vec3(-13,-3,-2),98, 0)
	mc.setBlock(v + Vec3(-13,-3,-1),4, 0)
	mc.setBlock(v + Vec3(-13,-3,0),4, 0)
	mc.setBlock(v + Vec3(-13,-3,1),4, 0)
	mc.setBlock(v + Vec3(-13,-3,2),98, 0)
	mc.setBlock(v + Vec3(-13,-3,13),85, 0)
	mc.setBlock(v + Vec3(-12,-3,-2),98, 0)
	mc.setBlock(v + Vec3(-12,-3,-1),4, 0)
	mc.setBlock(v + Vec3(-12,-3,0),4, 0)
	mc.setBlock(v + Vec3(-12,-3,1),4, 0)
	mc.setBlock(v + Vec3(-12,-3,2),98, 0)
	mc.setBlock(v + Vec3(-12,-3,14),85, 0)
	mc.setBlock(v + Vec3(-12,-3,15),85, 0)
	mc.setBlock(v + Vec3(-11,-3,-8),4, 0)
	mc.setBlock(v + Vec3(-11,-3,-7),67, 4)
	mc.setBlock(v + Vec3(-11,-3,-6),4, 0)
	mc.setBlock(v + Vec3(-11,-3,-5),67, 4)
	mc.setBlock(v + Vec3(-11,-3,-4),67, 4)
	mc.setBlock(v + Vec3(-11,-3,-3),4, 0)
	mc.setBlock(v + Vec3(-11,-3,-2),156, 5)
	mc.setBlock(v + Vec3(-11,-3,-1),4, 0)
	mc.setBlock(v + Vec3(-11,-3,0),4, 0)
	mc.setBlock(v + Vec3(-11,-3,1),4, 0)
	mc.setBlock(v + Vec3(-11,-3,2),156, 5)
	mc.setBlock(v + Vec3(-11,-3,3),4, 0)
	mc.setBlock(v + Vec3(-11,-3,4),67, 4)
	mc.setBlock(v + Vec3(-11,-3,5),67, 4)
	mc.setBlock(v + Vec3(-11,-3,6),4, 0)
	mc.setBlock(v + Vec3(-11,-3,7),67, 4)
	mc.setBlock(v + Vec3(-11,-3,8),4, 0)
	mc.setBlock(v + Vec3(-11,-3,9),67, 4)
	mc.setBlock(v + Vec3(-11,-3,10),67, 4)
	mc.setBlock(v + Vec3(-11,-3,11),4, 0)
	mc.setBlock(v + Vec3(-11,-3,12),67, 4)
	mc.setBlock(v + Vec3(-11,-3,13),4, 0)
	mc.setBlock(v + Vec3(-11,-3,15),85, 0)
	mc.setBlock(v + Vec3(-10,-3,-8),67, 6)
	mc.setBlock(v + Vec3(-10,-3,-7),5, 0)
	mc.setBlock(v + Vec3(-10,-3,-6),5, 0)
	mc.setBlock(v + Vec3(-10,-3,-5),5, 0)
	mc.setBlock(v + Vec3(-10,-3,-4),5, 0)
	mc.setBlock(v + Vec3(-10,-3,-3),5, 0)
	mc.setBlock(v + Vec3(-10,-3,-2),5, 0)
	mc.setBlock(v + Vec3(-10,-3,-1),35, 14)
	mc.setBlock(v + Vec3(-10,-3,0),35, 14)
	mc.setBlock(v + Vec3(-10,-3,1),35, 14)
	mc.setBlock(v + Vec3(-10,-3,2),5, 0)
	mc.setBlock(v + Vec3(-10,-3,3),5, 0)
	mc.setBlock(v + Vec3(-10,-3,4),5, 0)
	mc.setBlock(v + Vec3(-10,-3,5),5, 0)
	mc.setBlock(v + Vec3(-10,-3,6),5, 0)
	mc.setBlock(v + Vec3(-10,-3,7),5, 0)
	mc.setBlock(v + Vec3(-10,-3,8),5, 0)
	mc.setBlock(v + Vec3(-10,-3,9),5, 0)
	mc.setBlock(v + Vec3(-10,-3,10),5, 0)
	mc.setBlock(v + Vec3(-10,-3,11),5, 0)
	mc.setBlock(v + Vec3(-10,-3,12),5, 0)
	mc.setBlock(v + Vec3(-10,-3,13),67, 7)
	mc.setBlock(v + Vec3(-10,-3,14),85, 0)
	mc.setBlock(v + Vec3(-9,-3,-8),67, 6)
	mc.setBlock(v + Vec3(-9,-3,-7),5, 0)
	mc.setBlock(v + Vec3(-9,-3,-6),5, 0)
	mc.setBlock(v + Vec3(-9,-3,-5),5, 0)
	mc.setBlock(v + Vec3(-9,-3,-4),5, 0)
	mc.setBlock(v + Vec3(-9,-3,-3),5, 0)
	mc.setBlock(v + Vec3(-9,-3,-2),5, 0)
	mc.setBlock(v + Vec3(-9,-3,-1),5, 0)
	mc.setBlock(v + Vec3(-9,-3,0),5, 0)
	mc.setBlock(v + Vec3(-9,-3,1),5, 0)
	mc.setBlock(v + Vec3(-9,-3,2),5, 0)
	mc.setBlock(v + Vec3(-9,-3,3),5, 0)
	mc.setBlock(v + Vec3(-9,-3,4),5, 0)
	mc.setBlock(v + Vec3(-9,-3,5),5, 0)
	mc.setBlock(v + Vec3(-9,-3,6),5, 0)
	mc.setBlock(v + Vec3(-9,-3,7),5, 0)
	mc.setBlock(v + Vec3(-9,-3,8),5, 0)
	mc.setBlock(v + Vec3(-9,-3,9),5, 0)
	mc.setBlock(v + Vec3(-9,-3,10),5, 0)
	mc.setBlock(v + Vec3(-9,-3,11),5, 0)
	mc.setBlock(v + Vec3(-9,-3,12),5, 0)
	mc.setBlock(v + Vec3(-9,-3,13),67, 7)
	mc.setBlock(v + Vec3(-8,-3,-9),67, 4)
	mc.setBlock(v + Vec3(-8,-3,-8),67, 6)
	mc.setBlock(v + Vec3(-8,-3,-7),4, 0)
	mc.setBlock(v + Vec3(-8,-3,-6),4, 0)
	mc.setBlock(v + Vec3(-8,-3,-5),5, 0)
	mc.setBlock(v + Vec3(-8,-3,-4),5, 0)
	mc.setBlock(v + Vec3(-8,-3,-3),5, 0)
	mc.setBlock(v + Vec3(-8,-3,-2),5, 0)
	mc.setBlock(v + Vec3(-8,-3,-1),5, 0)
	mc.setBlock(v + Vec3(-8,-3,0),5, 0)
	mc.setBlock(v + Vec3(-8,-3,1),5, 0)
	mc.setBlock(v + Vec3(-8,-3,2),5, 0)
	mc.setBlock(v + Vec3(-8,-3,3),5, 0)
	mc.setBlock(v + Vec3(-8,-3,4),5, 0)
	mc.setBlock(v + Vec3(-8,-3,5),5, 0)
	mc.setBlock(v + Vec3(-8,-3,6),5, 0)
	mc.setBlock(v + Vec3(-8,-3,7),5, 0)
	mc.setBlock(v + Vec3(-8,-3,8),5, 0)
	mc.setBlock(v + Vec3(-8,-3,9),5, 0)
	mc.setBlock(v + Vec3(-8,-3,10),5, 0)
	mc.setBlock(v + Vec3(-8,-3,11),5, 0)
	mc.setBlock(v + Vec3(-8,-3,12),5, 0)
	mc.setBlock(v + Vec3(-8,-3,13),4, 0)
	mc.setBlock(v + Vec3(-8,-3,14),85, 0)
	mc.setBlock(v + Vec3(-7,-3,-9),67, 6)
	mc.setBlock(v + Vec3(-7,-3,-8),67, 3)
	mc.setBlock(v + Vec3(-7,-3,-6),67, 2)
	mc.setBlock(v + Vec3(-7,-3,-5),5, 0)
	mc.setBlock(v + Vec3(-7,-3,-4),5, 0)
	mc.setBlock(v + Vec3(-7,-3,-3),5, 0)
	mc.setBlock(v + Vec3(-7,-3,-2),5, 0)
	mc.setBlock(v + Vec3(-7,-3,-1),5, 0)
	mc.setBlock(v + Vec3(-7,-3,0),5, 0)
	mc.setBlock(v + Vec3(-7,-3,1),5, 0)
	mc.setBlock(v + Vec3(-7,-3,2),5, 0)
	mc.setBlock(v + Vec3(-7,-3,3),5, 0)
	mc.setBlock(v + Vec3(-7,-3,4),5, 0)
	mc.setBlock(v + Vec3(-7,-3,5),5, 0)
	mc.setBlock(v + Vec3(-7,-3,6),5, 0)
	mc.setBlock(v + Vec3(-7,-3,7),5, 0)
	mc.setBlock(v + Vec3(-7,-3,8),5, 0)
	mc.setBlock(v + Vec3(-7,-3,9),5, 0)
	mc.setBlock(v + Vec3(-7,-3,10),5, 0)
	mc.setBlock(v + Vec3(-7,-3,11),5, 0)
	mc.setBlock(v + Vec3(-7,-3,12),5, 0)
	mc.setBlock(v + Vec3(-7,-3,13),67, 7)
	mc.setBlock(v + Vec3(-6,-3,-9),67, 6)
	mc.setBlock(v + Vec3(-6,-3,-8),67, 3)
	mc.setBlock(v + Vec3(-6,-3,-6),67, 2)
	mc.setBlock(v + Vec3(-6,-3,-5),5, 0)
	mc.setBlock(v + Vec3(-6,-3,-4),5, 0)
	mc.setBlock(v + Vec3(-6,-3,-3),5, 0)
	mc.setBlock(v + Vec3(-6,-3,-2),5, 0)
	mc.setBlock(v + Vec3(-6,-3,-1),5, 0)
	mc.setBlock(v + Vec3(-6,-3,0),5, 0)
	mc.setBlock(v + Vec3(-6,-3,1),5, 0)
	mc.setBlock(v + Vec3(-6,-3,2),5, 0)
	mc.setBlock(v + Vec3(-6,-3,3),5, 0)
	mc.setBlock(v + Vec3(-6,-3,4),5, 0)
	mc.setBlock(v + Vec3(-6,-3,5),5, 0)
	mc.setBlock(v + Vec3(-6,-3,6),5, 0)
	mc.setBlock(v + Vec3(-6,-3,7),5, 0)
	mc.setBlock(v + Vec3(-6,-3,8),5, 0)
	mc.setBlock(v + Vec3(-6,-3,9),5, 0)
	mc.setBlock(v + Vec3(-6,-3,10),5, 0)
	mc.setBlock(v + Vec3(-6,-3,11),5, 0)
	mc.setBlock(v + Vec3(-6,-3,12),5, 0)
	mc.setBlock(v + Vec3(-6,-3,13),67, 7)
	mc.setBlock(v + Vec3(-5,-3,-9),67, 5)
	mc.setBlock(v + Vec3(-5,-3,-8),67, 6)
	mc.setBlock(v + Vec3(-5,-3,-7),4, 0)
	mc.setBlock(v + Vec3(-5,-3,-6),4, 0)
	mc.setBlock(v + Vec3(-5,-3,-5),5, 0)
	mc.setBlock(v + Vec3(-5,-3,-4),5, 0)
	mc.setBlock(v + Vec3(-5,-3,-3),5, 0)
	mc.setBlock(v + Vec3(-5,-3,-2),5, 0)
	mc.setBlock(v + Vec3(-5,-3,-1),5, 0)
	mc.setBlock(v + Vec3(-5,-3,0),5, 0)
	mc.setBlock(v + Vec3(-5,-3,1),5, 0)
	mc.setBlock(v + Vec3(-5,-3,2),5, 0)
	mc.setBlock(v + Vec3(-5,-3,3),5, 0)
	mc.setBlock(v + Vec3(-5,-3,4),5, 0)
	mc.setBlock(v + Vec3(-5,-3,5),5, 0)
	mc.setBlock(v + Vec3(-5,-3,6),5, 0)
	mc.setBlock(v + Vec3(-5,-3,7),5, 0)
	mc.setBlock(v + Vec3(-5,-3,8),5, 0)
	mc.setBlock(v + Vec3(-5,-3,9),5, 0)
	mc.setBlock(v + Vec3(-5,-3,10),5, 0)
	mc.setBlock(v + Vec3(-5,-3,11),5, 0)
	mc.setBlock(v + Vec3(-5,-3,12),5, 0)
	mc.setBlock(v + Vec3(-5,-3,13),4, 0)
	mc.setBlock(v + Vec3(-4,-3,-8),67, 6)
	mc.setBlock(v + Vec3(-4,-3,-7),5, 0)
	mc.setBlock(v + Vec3(-4,-3,-6),5, 0)
	mc.setBlock(v + Vec3(-4,-3,-5),5, 0)
	mc.setBlock(v + Vec3(-4,-3,-4),5, 0)
	mc.setBlock(v + Vec3(-4,-3,-3),5, 0)
	mc.setBlock(v + Vec3(-4,-3,-2),5, 0)
	mc.setBlock(v + Vec3(-4,-3,-1),5, 0)
	mc.setBlock(v + Vec3(-4,-3,0),5, 0)
	mc.setBlock(v + Vec3(-4,-3,1),5, 0)
	mc.setBlock(v + Vec3(-4,-3,2),5, 0)
	mc.setBlock(v + Vec3(-4,-3,3),5, 0)
	mc.setBlock(v + Vec3(-4,-3,4),5, 0)
	mc.setBlock(v + Vec3(-4,-3,5),5, 0)
	mc.setBlock(v + Vec3(-4,-3,6),5, 0)
	mc.setBlock(v + Vec3(-4,-3,7),5, 0)
	mc.setBlock(v + Vec3(-4,-3,8),5, 0)
	mc.setBlock(v + Vec3(-4,-3,9),5, 0)
	mc.setBlock(v + Vec3(-4,-3,10),5, 0)
	mc.setBlock(v + Vec3(-4,-3,11),5, 0)
	mc.setBlock(v + Vec3(-4,-3,12),5, 0)
	mc.setBlock(v + Vec3(-4,-3,13),67, 7)
	mc.setBlock(v + Vec3(-3,-3,-8),67, 6)
	mc.setBlock(v + Vec3(-3,-3,-7),5, 0)
	mc.setBlock(v + Vec3(-3,-3,-6),5, 0)
	mc.setBlock(v + Vec3(-3,-3,-5),5, 0)
	mc.setBlock(v + Vec3(-3,-3,-4),5, 0)
	mc.setBlock(v + Vec3(-3,-3,-3),5, 0)
	mc.setBlock(v + Vec3(-3,-3,-2),5, 0)
	mc.setBlock(v + Vec3(-3,-3,-1),5, 0)
	mc.setBlock(v + Vec3(-3,-3,0),5, 0)
	mc.setBlock(v + Vec3(-3,-3,1),5, 0)
	mc.setBlock(v + Vec3(-3,-3,2),5, 0)
	mc.setBlock(v + Vec3(-3,-3,3),5, 0)
	mc.setBlock(v + Vec3(-3,-3,4),5, 0)
	mc.setBlock(v + Vec3(-3,-3,5),5, 0)
	mc.setBlock(v + Vec3(-3,-3,6),5, 0)
	mc.setBlock(v + Vec3(-3,-3,7),5, 0)
	mc.setBlock(v + Vec3(-3,-3,8),5, 0)
	mc.setBlock(v + Vec3(-3,-3,9),5, 0)
	mc.setBlock(v + Vec3(-3,-3,10),5, 0)
	mc.setBlock(v + Vec3(-3,-3,11),5, 0)
	mc.setBlock(v + Vec3(-3,-3,12),5, 0)
	mc.setBlock(v + Vec3(-3,-3,13),67, 7)
	mc.setBlock(v + Vec3(-2,-3,-8),4, 0)
	mc.setBlock(v + Vec3(-2,-3,-7),67, 5)
	mc.setBlock(v + Vec3(-2,-3,-6),4, 0)
	mc.setBlock(v + Vec3(-2,-3,-5),67, 5)
	mc.setBlock(v + Vec3(-2,-3,-4),67, 5)
	mc.setBlock(v + Vec3(-2,-3,-3),4, 0)
	mc.setBlock(v + Vec3(-2,-3,-2),67, 5)
	mc.setBlock(v + Vec3(-2,-3,-1),67, 5)
	mc.setBlock(v + Vec3(-2,-3,0),67, 5)
	mc.setBlock(v + Vec3(-2,-3,1),67, 5)
	mc.setBlock(v + Vec3(-2,-3,2),17, 1)
	mc.setBlock(v + Vec3(-2,-3,3),5, 0)
	mc.setBlock(v + Vec3(-2,-3,4),5, 0)
	mc.setBlock(v + Vec3(-2,-3,5),17, 1)
	mc.setBlock(v + Vec3(-2,-3,6),67, 5)
	mc.setBlock(v + Vec3(-2,-3,7),67, 5)
	mc.setBlock(v + Vec3(-2,-3,8),67, 5)
	mc.setBlock(v + Vec3(-2,-3,9),67, 5)
	mc.setBlock(v + Vec3(-2,-3,10),67, 5)
	mc.setBlock(v + Vec3(-2,-3,11),67, 5)
	mc.setBlock(v + Vec3(-2,-3,12),67, 5)
	mc.setBlock(v + Vec3(-2,-3,13),4, 0)
	mc.setBlock(v + Vec3(-1,-3,2),17, 0)
	mc.setBlock(v + Vec3(-1,-3,3),53, 1)
	mc.setBlock(v + Vec3(-1,-3,4),53, 1)
	mc.setBlock(v + Vec3(-1,-3,5),17, 0)
	mc.setBlock(v + Vec3(0,-3,2),17, 0)
	mc.setBlock(v + Vec3(0,-3,5),17, 0)
	mc.setBlock(v + Vec3(1,-3,0),17, 1)
	mc.setBlock(v + Vec3(1,-3,1),155, 0)
	mc.setBlock(v + Vec3(1,-3,2),17, 1)
	mc.setBlock(v + Vec3(1,-3,5),17, 1)
	mc.setBlock(v + Vec3(1,-3,6),155, 0)
	mc.setBlock(v + Vec3(1,-3,7),155, 0)
	mc.setBlock(v + Vec3(1,-3,8),155, 0)
	mc.setBlock(v + Vec3(1,-3,9),17, 1)
	mc.setBlock(v + Vec3(2,-3,0),155, 0)
	mc.setBlock(v + Vec3(2,-3,9),155, 0)
	mc.setBlock(v + Vec3(3,-3,0),155, 0)
	mc.setBlock(v + Vec3(3,-3,9),155, 0)
	mc.setBlock(v + Vec3(4,-3,0),155, 0)
	mc.setBlock(v + Vec3(4,-3,9),155, 0)
	mc.setBlock(v + Vec3(5,-3,0),155, 0)
	mc.setBlock(v + Vec3(5,-3,9),155, 0)
	mc.setBlock(v + Vec3(6,-3,0),155, 0)
	mc.setBlock(v + Vec3(6,-3,9),155, 0)
	mc.setBlock(v + Vec3(7,-3,0),155, 0)
	mc.setBlock(v + Vec3(7,-3,9),155, 0)
	mc.setBlock(v + Vec3(8,-3,0),155, 0)
	mc.setBlock(v + Vec3(8,-3,9),155, 0)
	mc.setBlock(v + Vec3(9,-3,-3),85, 0)
	mc.setBlock(v + Vec3(9,-3,-2),85, 0)
	mc.setBlock(v + Vec3(9,-3,-1),107, 7)
	mc.setBlock(v + Vec3(9,-3,0),17, 1)
	mc.setBlock(v + Vec3(9,-3,1),155, 0)
	mc.setBlock(v + Vec3(9,-3,2),64, 2)
	mc.setBlock(v + Vec3(9,-3,3),155, 0)
	mc.setBlock(v + Vec3(9,-3,4),155, 0)
	mc.setBlock(v + Vec3(9,-3,5),155, 0)
	mc.setBlock(v + Vec3(9,-3,6),155, 0)
	mc.setBlock(v + Vec3(9,-3,7),155, 0)
	mc.setBlock(v + Vec3(9,-3,8),155, 0)
	mc.setBlock(v + Vec3(9,-3,9),17, 1)
	mc.setBlock(v + Vec3(9,-3,10),107, 1)
	mc.setBlock(v + Vec3(9,-3,11),85, 0)
	mc.setBlock(v + Vec3(10,-3,-3),85, 0)
	mc.setBlock(v + Vec3(10,-3,11),85, 0)
	mc.setBlock(v + Vec3(11,-3,-3),85, 0)
	mc.setBlock(v + Vec3(11,-3,11),85, 0)
	mc.setBlock(v + Vec3(12,-3,-3),85, 0)
	mc.setBlock(v + Vec3(12,-3,5),59, 7)
	mc.setBlock(v + Vec3(12,-3,11),85, 0)
	mc.setBlock(v + Vec3(13,-3,-3),85, 0)
	mc.setBlock(v + Vec3(13,-3,2),59, 7)
	mc.setBlock(v + Vec3(13,-3,9),59, 7)
	mc.setBlock(v + Vec3(13,-3,11),85, 0)
	mc.setBlock(v + Vec3(14,-3,-3),85, 0)
	mc.setBlock(v + Vec3(14,-3,11),85, 0)
	mc.setBlock(v + Vec3(15,-3,-3),85, 0)
	mc.setBlock(v + Vec3(15,-3,2),59, 7)
	mc.setBlock(v + Vec3(15,-3,11),85, 0)
	mc.setBlock(v + Vec3(16,-3,-3),85, 0)
	mc.setBlock(v + Vec3(16,-3,3),59, 7)
	mc.setBlock(v + Vec3(16,-3,5),59, 7)
	mc.setBlock(v + Vec3(16,-3,11),85, 0)
	mc.setBlock(v + Vec3(17,-3,-3),85, 0)
	mc.setBlock(v + Vec3(17,-3,11),85, 0)
	mc.setBlock(v + Vec3(18,-3,-3),85, 0)
	mc.setBlock(v + Vec3(18,-3,4),59, 7)
	mc.setBlock(v + Vec3(18,-3,11),85, 0)
	mc.setBlock(v + Vec3(19,-3,-3),85, 0)
	mc.setBlock(v + Vec3(19,-3,-2),85, 0)
	mc.setBlock(v + Vec3(19,-3,-1),85, 0)
	mc.setBlock(v + Vec3(19,-3,0),85, 0)
	mc.setBlock(v + Vec3(19,-3,1),85, 0)
	mc.setBlock(v + Vec3(19,-3,2),85, 0)
	mc.setBlock(v + Vec3(19,-3,3),85, 0)
	mc.setBlock(v + Vec3(19,-3,4),85, 0)
	mc.setBlock(v + Vec3(19,-3,5),85, 0)
	mc.setBlock(v + Vec3(19,-3,6),85, 0)
	mc.setBlock(v + Vec3(19,-3,7),85, 0)
	mc.setBlock(v + Vec3(19,-3,8),85, 0)
	mc.setBlock(v + Vec3(19,-3,9),85, 0)
	mc.setBlock(v + Vec3(19,-3,10),85, 0)
	mc.setBlock(v + Vec3(19,-3,11),85, 0)
	mc.setBlock(v + Vec3(-20,-2,3),54, 4)
	mc.setBlock(v + Vec3(-17,-2,12),85, 0)
	mc.setBlock(v + Vec3(-14,-2,-2),109, 5)
	mc.setBlock(v + Vec3(-14,-2,2),109, 5)
	mc.setBlock(v + Vec3(-13,-2,-2),109, 4)
	mc.setBlock(v + Vec3(-13,-2,2),109, 4)
	mc.setBlock(v + Vec3(-12,-2,-2),98, 0)
	mc.setBlock(v + Vec3(-12,-2,2),98, 0)
	mc.setBlock(v + Vec3(-11,-2,-8),17, 1)
	mc.setBlock(v + Vec3(-11,-2,-7),155, 0)
	mc.setBlock(v + Vec3(-11,-2,-6),17, 1)
	mc.setBlock(v + Vec3(-11,-2,-5),53, 1)
	mc.setBlock(v + Vec3(-11,-2,-4),53, 1)
	mc.setBlock(v + Vec3(-11,-2,-3),17, 1)
	mc.setBlock(v + Vec3(-11,-2,-2),156, 5)
	mc.setBlock(v + Vec3(-11,-2,-1),17, 1)
	mc.setBlock(v + Vec3(-11,-2,0),64, 0)
	mc.setBlock(v + Vec3(-11,-2,1),17, 1)
	mc.setBlock(v + Vec3(-11,-2,2),156, 5)
	mc.setBlock(v + Vec3(-11,-2,3),17, 1)
	mc.setBlock(v + Vec3(-11,-2,4),53, 1)
	mc.setBlock(v + Vec3(-11,-2,5),53, 1)
	mc.setBlock(v + Vec3(-11,-2,6),17, 1)
	mc.setBlock(v + Vec3(-11,-2,7),155, 0)
	mc.setBlock(v + Vec3(-11,-2,8),17, 1)
	mc.setBlock(v + Vec3(-11,-2,9),5, 0)
	mc.setBlock(v + Vec3(-11,-2,10),5, 0)
	mc.setBlock(v + Vec3(-11,-2,11),17, 1)
	mc.setBlock(v + Vec3(-11,-2,12),155, 0)
	mc.setBlock(v + Vec3(-11,-2,13),17, 1)
	mc.setBlock(v + Vec3(-10,-2,-8),155, 0)
	mc.setBlock(v + Vec3(-10,-2,-7),47, 0)
	mc.setBlock(v + Vec3(-10,-2,2),26, 0)
	mc.setBlock(v + Vec3(-10,-2,3),26, 2)
	mc.setBlock(v + Vec3(-10,-2,4),26, 2)
	mc.setBlock(v + Vec3(-10,-2,5),26, 2)
	mc.setBlock(v + Vec3(-10,-2,6),26, 3)
	mc.setBlock(v + Vec3(-10,-2,7),5, 0)
	mc.setBlock(v + Vec3(-10,-2,8),245, 0)
	mc.setBlock(v + Vec3(-10,-2,11),26, 0)
	mc.setBlock(v + Vec3(-10,-2,12),26, 8)
	mc.setBlock(v + Vec3(-10,-2,13),155, 0)
	mc.setBlock(v + Vec3(-9,-2,-8),155, 0)
	mc.setBlock(v + Vec3(-9,-2,-7),47, 0)
	mc.setBlock(v + Vec3(-9,-2,6),26, 3)
	mc.setBlock(v + Vec3(-9,-2,7),5, 0)
	mc.setBlock(v + Vec3(-9,-2,11),26, 0)
	mc.setBlock(v + Vec3(-9,-2,12),26, 8)
	mc.setBlock(v + Vec3(-9,-2,13),155, 0)
	mc.setBlock(v + Vec3(-8,-2,-9),4, 0)
	mc.setBlock(v + Vec3(-8,-2,-8),4, 0)
	mc.setBlock(v + Vec3(-8,-2,-7),4, 0)
	mc.setBlock(v + Vec3(-8,-2,6),26, 1)
	mc.setBlock(v + Vec3(-8,-2,7),5, 0)
	mc.setBlock(v + Vec3(-8,-2,12),54, 2)
	mc.setBlock(v + Vec3(-8,-2,13),17, 1)
	mc.setBlock(v + Vec3(-7,-2,-9),4, 0)
	mc.setBlock(v + Vec3(-7,-2,-4),26, 3)
	mc.setBlock(v + Vec3(-7,-2,7),64, 1)
	mc.setBlock(v + Vec3(-7,-2,8),64, 1)
	mc.setBlock(v + Vec3(-7,-2,12),58, 0)
	mc.setBlock(v + Vec3(-7,-2,13),5, 0)
	mc.setBlock(v + Vec3(-6,-2,-9),4, 0)
	mc.setBlock(v + Vec3(-6,-2,-4),26, 1)
	mc.setBlock(v + Vec3(-6,-2,7),64, 1)
	mc.setBlock(v + Vec3(-6,-2,8),64, 1)
	mc.setBlock(v + Vec3(-6,-2,12),58, 0)
	mc.setBlock(v + Vec3(-6,-2,13),5, 0)
	mc.setBlock(v + Vec3(-5,-2,-9),4, 0)
	mc.setBlock(v + Vec3(-5,-2,-8),4, 0)
	mc.setBlock(v + Vec3(-5,-2,-7),4, 0)
	mc.setBlock(v + Vec3(-5,-2,7),5, 0)
	mc.setBlock(v + Vec3(-5,-2,12),54, 2)
	mc.setBlock(v + Vec3(-5,-2,13),17, 1)
	mc.setBlock(v + Vec3(-4,-2,-8),155, 0)
	mc.setBlock(v + Vec3(-4,-2,7),5, 0)
	mc.setBlock(v + Vec3(-4,-2,11),26, 0)
	mc.setBlock(v + Vec3(-4,-2,12),26, 8)
	mc.setBlock(v + Vec3(-4,-2,13),155, 0)
	mc.setBlock(v + Vec3(-3,-2,-8),155, 0)
	mc.setBlock(v + Vec3(-3,-2,7),5, 0)
	mc.setBlock(v + Vec3(-3,-2,8),58, 0)
	mc.setBlock(v + Vec3(-3,-2,11),26, 0)
	mc.setBlock(v + Vec3(-3,-2,12),26, 8)
	mc.setBlock(v + Vec3(-3,-2,13),155, 0)
	mc.setBlock(v + Vec3(-2,-2,-8),17, 1)
	mc.setBlock(v + Vec3(-2,-2,-7),155, 0)
	mc.setBlock(v + Vec3(-2,-2,-6),17, 1)
	mc.setBlock(v + Vec3(-2,-2,-5),53, 0)
	mc.setBlock(v + Vec3(-2,-2,-4),53, 0)
	mc.setBlock(v + Vec3(-2,-2,-3),17, 1)
	mc.setBlock(v + Vec3(-2,-2,-2),155, 0)
	mc.setBlock(v + Vec3(-2,-2,-1),155, 0)
	mc.setBlock(v + Vec3(-2,-2,0),155, 0)
	mc.setBlock(v + Vec3(-2,-2,1),155, 0)
	mc.setBlock(v + Vec3(-2,-2,2),17, 1)
	mc.setBlock(v + Vec3(-2,-2,5),17, 1)
	mc.setBlock(v + Vec3(-2,-2,6),155, 0)
	mc.setBlock(v + Vec3(-2,-2,7),155, 0)
	mc.setBlock(v + Vec3(-2,-2,8),155, 0)
	mc.setBlock(v + Vec3(-2,-2,9),155, 0)
	mc.setBlock(v + Vec3(-2,-2,10),155, 0)
	mc.setBlock(v + Vec3(-2,-2,11),155, 0)
	mc.setBlock(v + Vec3(-2,-2,12),155, 0)
	mc.setBlock(v + Vec3(-2,-2,13),17, 1)
	mc.setBlock(v + Vec3(-1,-2,2),17, 0)
	mc.setBlock(v + Vec3(-1,-2,5),17, 0)
	mc.setBlock(v + Vec3(0,-2,2),17, 0)
	mc.setBlock(v + Vec3(0,-2,5),17, 0)
	mc.setBlock(v + Vec3(1,-2,0),17, 1)
	mc.setBlock(v + Vec3(1,-2,1),155, 0)
	mc.setBlock(v + Vec3(1,-2,2),17, 1)
	mc.setBlock(v + Vec3(1,-2,5),17, 1)
	mc.setBlock(v + Vec3(1,-2,6),155, 0)
	mc.setBlock(v + Vec3(1,-2,7),155, 0)
	mc.setBlock(v + Vec3(1,-2,8),155, 0)
	mc.setBlock(v + Vec3(1,-2,9),17, 1)
	mc.setBlock(v + Vec3(2,-2,0),155, 0)
	mc.setBlock(v + Vec3(2,-2,9),155, 0)
	mc.setBlock(v + Vec3(3,-2,0),155, 0)
	mc.setBlock(v + Vec3(3,-2,9),155, 0)
	mc.setBlock(v + Vec3(4,-2,0),102, 0)
	mc.setBlock(v + Vec3(4,-2,9),155, 0)
	mc.setBlock(v + Vec3(5,-2,0),102, 0)
	mc.setBlock(v + Vec3(5,-2,9),155, 0)
	mc.setBlock(v + Vec3(6,-2,0),102, 0)
	mc.setBlock(v + Vec3(6,-2,9),155, 0)
	mc.setBlock(v + Vec3(7,-2,0),155, 0)
	mc.setBlock(v + Vec3(7,-2,9),155, 0)
	mc.setBlock(v + Vec3(8,-2,0),155, 0)
	mc.setBlock(v + Vec3(8,-2,9),155, 0)
	mc.setBlock(v + Vec3(9,-2,-3),85, 0)
	mc.setBlock(v + Vec3(9,-2,-2),85, 0)
	mc.setBlock(v + Vec3(9,-2,0),17, 1)
	mc.setBlock(v + Vec3(9,-2,1),155, 0)
	mc.setBlock(v + Vec3(9,-2,2),64, 9)
	mc.setBlock(v + Vec3(9,-2,3),155, 0)
	mc.setBlock(v + Vec3(9,-2,4),102, 0)
	mc.setBlock(v + Vec3(9,-2,5),102, 0)
	mc.setBlock(v + Vec3(9,-2,6),102, 0)
	mc.setBlock(v + Vec3(9,-2,7),155, 0)
	mc.setBlock(v + Vec3(9,-2,8),155, 0)
	mc.setBlock(v + Vec3(9,-2,9),17, 1)
	mc.setBlock(v + Vec3(10,-2,-3),85, 0)
	mc.setBlock(v + Vec3(11,-2,-3),85, 0)
	mc.setBlock(v + Vec3(12,-2,-3),85, 0)
	mc.setBlock(v + Vec3(13,-2,-3),85, 0)
	mc.setBlock(v + Vec3(14,-2,-3),85, 0)
	mc.setBlock(v + Vec3(-12,-1,-2),98, 0)
	mc.setBlock(v + Vec3(-12,-1,2),98, 0)
	mc.setBlock(v + Vec3(-11,-1,-8),17, 1)
	mc.setBlock(v + Vec3(-11,-1,-7),155, 0)
	mc.setBlock(v + Vec3(-11,-1,-6),17, 1)
	mc.setBlock(v + Vec3(-11,-1,-5),102, 0)
	mc.setBlock(v + Vec3(-11,-1,-4),102, 0)
	mc.setBlock(v + Vec3(-11,-1,-3),17, 1)
	mc.setBlock(v + Vec3(-11,-1,-2),156, 5)
	mc.setBlock(v + Vec3(-11,-1,-1),17, 1)
	mc.setBlock(v + Vec3(-11,-1,0),64, 8)
	mc.setBlock(v + Vec3(-11,-1,1),17, 1)
	mc.setBlock(v + Vec3(-11,-1,2),156, 5)
	mc.setBlock(v + Vec3(-11,-1,3),17, 1)
	mc.setBlock(v + Vec3(-11,-1,4),102, 0)
	mc.setBlock(v + Vec3(-11,-1,5),102, 0)
	mc.setBlock(v + Vec3(-11,-1,6),17, 1)
	mc.setBlock(v + Vec3(-11,-1,7),155, 0)
	mc.setBlock(v + Vec3(-11,-1,8),17, 1)
	mc.setBlock(v + Vec3(-11,-1,9),102, 0)
	mc.setBlock(v + Vec3(-11,-1,10),102, 0)
	mc.setBlock(v + Vec3(-11,-1,11),17, 1)
	mc.setBlock(v + Vec3(-11,-1,12),155, 0)
	mc.setBlock(v + Vec3(-11,-1,13),17, 1)
	mc.setBlock(v + Vec3(-10,-1,-8),155, 0)
	mc.setBlock(v + Vec3(-10,-1,-7),47, 0)
	mc.setBlock(v + Vec3(-10,-1,7),5, 0)
	mc.setBlock(v + Vec3(-10,-1,13),155, 0)
	mc.setBlock(v + Vec3(-9,-1,-8),155, 0)
	mc.setBlock(v + Vec3(-9,-1,-7),47, 0)
	mc.setBlock(v + Vec3(-9,-1,7),5, 0)
	mc.setBlock(v + Vec3(-9,-1,13),155, 0)
	mc.setBlock(v + Vec3(-8,-1,-9),4, 0)
	mc.setBlock(v + Vec3(-8,-1,-8),4, 0)
	mc.setBlock(v + Vec3(-8,-1,-7),4, 0)
	mc.setBlock(v + Vec3(-8,-1,7),5, 0)
	mc.setBlock(v + Vec3(-8,-1,13),17, 1)
	mc.setBlock(v + Vec3(-7,-1,-9),4, 0)
	mc.setBlock(v + Vec3(-7,-1,7),64, 9)
	mc.setBlock(v + Vec3(-7,-1,8),64, 9)
	mc.setBlock(v + Vec3(-7,-1,13),102, 0)
	mc.setBlock(v + Vec3(-6,-1,-9),4, 0)
	mc.setBlock(v + Vec3(-6,-1,7),64, 8)
	mc.setBlock(v + Vec3(-6,-1,8),64, 8)
	mc.setBlock(v + Vec3(-6,-1,13),102, 0)
	mc.setBlock(v + Vec3(-5,-1,-9),4, 0)
	mc.setBlock(v + Vec3(-5,-1,-8),4, 0)
	mc.setBlock(v + Vec3(-5,-1,-7),4, 0)
	mc.setBlock(v + Vec3(-5,-1,7),5, 0)
	mc.setBlock(v + Vec3(-5,-1,13),17, 1)
	mc.setBlock(v + Vec3(-4,-1,-8),155, 0)
	mc.setBlock(v + Vec3(-4,-1,7),5, 0)
	mc.setBlock(v + Vec3(-4,-1,13),155, 0)
	mc.setBlock(v + Vec3(-3,-1,-8),155, 0)
	mc.setBlock(v + Vec3(-3,-1,7),5, 0)
	mc.setBlock(v + Vec3(-3,-1,13),155, 0)
	mc.setBlock(v + Vec3(-2,-1,-8),17, 1)
	mc.setBlock(v + Vec3(-2,-1,-7),155, 0)
	mc.setBlock(v + Vec3(-2,-1,-6),17, 1)
	mc.setBlock(v + Vec3(-2,-1,-5),102, 0)
	mc.setBlock(v + Vec3(-2,-1,-4),102, 0)
	mc.setBlock(v + Vec3(-2,-1,-3),17, 1)
	mc.setBlock(v + Vec3(-2,-1,-2),155, 0)
	mc.setBlock(v + Vec3(-2,-1,-1),155, 0)
	mc.setBlock(v + Vec3(-2,-1,0),155, 0)
	mc.setBlock(v + Vec3(-2,-1,1),155, 0)
	mc.setBlock(v + Vec3(-2,-1,2),17, 1)
	mc.setBlock(v + Vec3(-2,-1,5),17, 1)
	mc.setBlock(v + Vec3(-2,-1,6),155, 0)
	mc.setBlock(v + Vec3(-2,-1,7),155, 0)
	mc.setBlock(v + Vec3(-2,-1,8),155, 0)
	mc.setBlock(v + Vec3(-2,-1,9),155, 0)
	mc.setBlock(v + Vec3(-2,-1,10),155, 0)
	mc.setBlock(v + Vec3(-2,-1,11),155, 0)
	mc.setBlock(v + Vec3(-2,-1,12),155, 0)
	mc.setBlock(v + Vec3(-2,-1,13),17, 1)
	mc.setBlock(v + Vec3(-1,-1,2),17, 0)
	mc.setBlock(v + Vec3(-1,-1,5),17, 0)
	mc.setBlock(v + Vec3(0,-1,2),17, 0)
	mc.setBlock(v + Vec3(0,-1,5),17, 0)
	mc.setBlock(v + Vec3(1,-1,0),17, 1)
	mc.setBlock(v + Vec3(1,-1,1),155, 0)
	mc.setBlock(v + Vec3(1,-1,2),17, 1)
	mc.setBlock(v + Vec3(1,-1,5),17, 1)
	mc.setBlock(v + Vec3(1,-1,6),155, 0)
	mc.setBlock(v + Vec3(1,-1,7),155, 0)
	mc.setBlock(v + Vec3(1,-1,8),155, 0)
	mc.setBlock(v + Vec3(1,-1,9),17, 1)
	mc.setBlock(v + Vec3(2,-1,0),155, 0)
	mc.setBlock(v + Vec3(2,-1,1),102, 0)
	mc.setBlock(v + Vec3(2,-1,2),102, 0)
	mc.setBlock(v + Vec3(2,-1,3),102, 0)
	mc.setBlock(v + Vec3(2,-1,4),102, 0)
	mc.setBlock(v + Vec3(2,-1,5),102, 0)
	mc.setBlock(v + Vec3(2,-1,6),102, 0)
	mc.setBlock(v + Vec3(2,-1,7),102, 0)
	mc.setBlock(v + Vec3(2,-1,8),102, 0)
	mc.setBlock(v + Vec3(2,-1,9),155, 0)
	mc.setBlock(v + Vec3(3,-1,0),155, 0)
	mc.setBlock(v + Vec3(3,-1,1),102, 0)
	mc.setBlock(v + Vec3(3,-1,8),102, 0)
	mc.setBlock(v + Vec3(3,-1,9),155, 0)
	mc.setBlock(v + Vec3(4,-1,0),155, 0)
	mc.setBlock(v + Vec3(4,-1,1),102, 0)
	mc.setBlock(v + Vec3(4,-1,8),102, 0)
	mc.setBlock(v + Vec3(4,-1,9),155, 0)
	mc.setBlock(v + Vec3(5,-1,0),155, 0)
	mc.setBlock(v + Vec3(5,-1,1),102, 0)
	mc.setBlock(v + Vec3(5,-1,8),102, 0)
	mc.setBlock(v + Vec3(5,-1,9),155, 0)
	mc.setBlock(v + Vec3(6,-1,0),155, 0)
	mc.setBlock(v + Vec3(6,-1,1),102, 0)
	mc.setBlock(v + Vec3(6,-1,8),102, 0)
	mc.setBlock(v + Vec3(6,-1,9),155, 0)
	mc.setBlock(v + Vec3(7,-1,0),155, 0)
	mc.setBlock(v + Vec3(7,-1,1),102, 0)
	mc.setBlock(v + Vec3(7,-1,8),102, 0)
	mc.setBlock(v + Vec3(7,-1,9),155, 0)
	mc.setBlock(v + Vec3(8,-1,0),155, 0)
	mc.setBlock(v + Vec3(8,-1,1),102, 0)
	mc.setBlock(v + Vec3(8,-1,2),102, 0)
	mc.setBlock(v + Vec3(8,-1,3),102, 0)
	mc.setBlock(v + Vec3(8,-1,4),102, 0)
	mc.setBlock(v + Vec3(8,-1,5),102, 0)
	mc.setBlock(v + Vec3(8,-1,6),102, 0)
	mc.setBlock(v + Vec3(8,-1,7),102, 0)
	mc.setBlock(v + Vec3(8,-1,8),102, 0)
	mc.setBlock(v + Vec3(8,-1,9),155, 0)
	mc.setBlock(v + Vec3(9,-1,-3),85, 0)
	mc.setBlock(v + Vec3(9,-1,-2),85, 0)
	mc.setBlock(v + Vec3(9,-1,0),17, 1)
	mc.setBlock(v + Vec3(9,-1,1),155, 0)
	mc.setBlock(v + Vec3(9,-1,2),155, 0)
	mc.setBlock(v + Vec3(9,-1,3),155, 0)
	mc.setBlock(v + Vec3(9,-1,4),155, 0)
	mc.setBlock(v + Vec3(9,-1,5),155, 0)
	mc.setBlock(v + Vec3(9,-1,6),155, 0)
	mc.setBlock(v + Vec3(9,-1,7),155, 0)
	mc.setBlock(v + Vec3(9,-1,8),155, 0)
	mc.setBlock(v + Vec3(9,-1,9),17, 1)
	mc.setBlock(v + Vec3(10,-1,-3),85, 0)
	mc.setBlock(v + Vec3(11,-1,-3),85, 0)
	mc.setBlock(v + Vec3(12,-1,-3),85, 0)
	mc.setBlock(v + Vec3(13,-1,-3),85, 0)
	mc.setBlock(v + Vec3(14,-1,-3),85, 0)
	mc.setBlock(v + Vec3(-12,0,-9),53, 6)
	mc.setBlock(v + Vec3(-12,0,-8),53, 4)
	mc.setBlock(v + Vec3(-12,0,-7),53, 4)
	mc.setBlock(v + Vec3(-12,0,-6),44, 10)
	mc.setBlock(v + Vec3(-12,0,-5),44, 10)
	mc.setBlock(v + Vec3(-12,0,-4),44, 10)
	mc.setBlock(v + Vec3(-12,0,-3),44, 10)
	mc.setBlock(v + Vec3(-12,0,-2),98, 0)
	mc.setBlock(v + Vec3(-12,0,2),98, 0)
	mc.setBlock(v + Vec3(-12,0,3),53, 4)
	mc.setBlock(v + Vec3(-12,0,4),53, 4)
	mc.setBlock(v + Vec3(-12,0,5),53, 4)
	mc.setBlock(v + Vec3(-12,0,6),53, 4)
	mc.setBlock(v + Vec3(-12,0,7),53, 4)
	mc.setBlock(v + Vec3(-12,0,8),53, 4)
	mc.setBlock(v + Vec3(-12,0,9),53, 4)
	mc.setBlock(v + Vec3(-12,0,10),53, 4)
	mc.setBlock(v + Vec3(-12,0,11),53, 4)
	mc.setBlock(v + Vec3(-12,0,12),53, 4)
	mc.setBlock(v + Vec3(-12,0,13),53, 4)
	mc.setBlock(v + Vec3(-12,0,14),53, 7)
	mc.setBlock(v + Vec3(-11,0,-9),53, 6)
	mc.setBlock(v + Vec3(-11,0,-8),17, 1)
	mc.setBlock(v + Vec3(-11,0,-7),155, 0)
	mc.setBlock(v + Vec3(-11,0,-6),17, 1)
	mc.setBlock(v + Vec3(-11,0,-5),53, 4)
	mc.setBlock(v + Vec3(-11,0,-4),53, 4)
	mc.setBlock(v + Vec3(-11,0,-3),17, 1)
	mc.setBlock(v + Vec3(-11,0,-2),156, 5)
	mc.setBlock(v + Vec3(-11,0,-1),17, 1)
	mc.setBlock(v + Vec3(-11,0,0),20, 0)
	mc.setBlock(v + Vec3(-11,0,1),17, 1)
	mc.setBlock(v + Vec3(-11,0,2),156, 5)
	mc.setBlock(v + Vec3(-11,0,3),17, 1)
	mc.setBlock(v + Vec3(-11,0,4),53, 5)
	mc.setBlock(v + Vec3(-11,0,5),53, 5)
	mc.setBlock(v + Vec3(-11,0,6),17, 1)
	mc.setBlock(v + Vec3(-11,0,7),155, 0)
	mc.setBlock(v + Vec3(-11,0,8),17, 1)
	mc.setBlock(v + Vec3(-11,0,9),5, 0)
	mc.setBlock(v + Vec3(-11,0,10),5, 0)
	mc.setBlock(v + Vec3(-11,0,11),17, 1)
	mc.setBlock(v + Vec3(-11,0,12),155, 0)
	mc.setBlock(v + Vec3(-11,0,13),17, 1)
	mc.setBlock(v + Vec3(-11,0,14),53, 7)
	mc.setBlock(v + Vec3(-10,0,-9),53, 6)
	mc.setBlock(v + Vec3(-10,0,-8),155, 0)
	mc.setBlock(v + Vec3(-10,0,-7),47, 0)
	mc.setBlock(v + Vec3(-10,0,7),5, 0)
	mc.setBlock(v + Vec3(-10,0,13),155, 0)
	mc.setBlock(v + Vec3(-10,0,14),53, 7)
	mc.setBlock(v + Vec3(-9,0,-9),53, 6)
	mc.setBlock(v + Vec3(-9,0,-8),155, 0)
	mc.setBlock(v + Vec3(-9,0,-7),47, 0)
	mc.setBlock(v + Vec3(-9,0,7),5, 0)
	mc.setBlock(v + Vec3(-9,0,13),155, 0)
	mc.setBlock(v + Vec3(-9,0,14),53, 7)
	mc.setBlock(v + Vec3(-8,0,-9),4, 0)
	mc.setBlock(v + Vec3(-8,0,-8),4, 0)
	mc.setBlock(v + Vec3(-8,0,-7),4, 0)
	mc.setBlock(v + Vec3(-8,0,7),5, 0)
	mc.setBlock(v + Vec3(-8,0,13),17, 1)
	mc.setBlock(v + Vec3(-8,0,14),53, 7)
	mc.setBlock(v + Vec3(-7,0,-9),4, 0)
	mc.setBlock(v + Vec3(-7,0,7),5, 0)
	mc.setBlock(v + Vec3(-7,0,13),5, 0)
	mc.setBlock(v + Vec3(-7,0,14),53, 7)
	mc.setBlock(v + Vec3(-6,0,-9),4, 0)
	mc.setBlock(v + Vec3(-6,0,7),5, 0)
	mc.setBlock(v + Vec3(-6,0,13),5, 0)
	mc.setBlock(v + Vec3(-6,0,14),53, 7)
	mc.setBlock(v + Vec3(-5,0,-9),4, 0)
	mc.setBlock(v + Vec3(-5,0,-8),4, 0)
	mc.setBlock(v + Vec3(-5,0,-7),4, 0)
	mc.setBlock(v + Vec3(-5,0,7),5, 0)
	mc.setBlock(v + Vec3(-5,0,13),17, 1)
	mc.setBlock(v + Vec3(-5,0,14),53, 7)
	mc.setBlock(v + Vec3(-4,0,-9),53, 6)
	mc.setBlock(v + Vec3(-4,0,-8),155, 0)
	mc.setBlock(v + Vec3(-4,0,7),5, 0)
	mc.setBlock(v + Vec3(-4,0,13),155, 0)
	mc.setBlock(v + Vec3(-4,0,14),53, 7)
	mc.setBlock(v + Vec3(-3,0,-9),53, 6)
	mc.setBlock(v + Vec3(-3,0,-8),155, 0)
	mc.setBlock(v + Vec3(-3,0,7),5, 0)
	mc.setBlock(v + Vec3(-3,0,13),155, 0)
	mc.setBlock(v + Vec3(-3,0,14),53, 7)
	mc.setBlock(v + Vec3(-2,0,-9),53, 6)
	mc.setBlock(v + Vec3(-2,0,-8),17, 1)
	mc.setBlock(v + Vec3(-2,0,-7),155, 0)
	mc.setBlock(v + Vec3(-2,0,-6),17, 1)
	mc.setBlock(v + Vec3(-2,0,-5),53, 4)
	mc.setBlock(v + Vec3(-2,0,-4),53, 4)
	mc.setBlock(v + Vec3(-2,0,-3),17, 1)
	mc.setBlock(v + Vec3(-2,0,-2),155, 0)
	mc.setBlock(v + Vec3(-2,0,-1),155, 0)
	mc.setBlock(v + Vec3(-2,0,0),155, 0)
	mc.setBlock(v + Vec3(-2,0,1),155, 0)
	mc.setBlock(v + Vec3(-2,0,2),17, 1)
	mc.setBlock(v + Vec3(-2,0,5),17, 1)
	mc.setBlock(v + Vec3(-2,0,6),155, 0)
	mc.setBlock(v + Vec3(-2,0,7),155, 0)
	mc.setBlock(v + Vec3(-2,0,8),155, 0)
	mc.setBlock(v + Vec3(-2,0,9),155, 0)
	mc.setBlock(v + Vec3(-2,0,10),155, 0)
	mc.setBlock(v + Vec3(-2,0,11),155, 0)
	mc.setBlock(v + Vec3(-2,0,12),155, 0)
	mc.setBlock(v + Vec3(-2,0,13),17, 1)
	mc.setBlock(v + Vec3(-2,0,14),53, 7)
	mc.setBlock(v + Vec3(-1,0,-9),53, 5)
	mc.setBlock(v + Vec3(-1,0,-8),53, 5)
	mc.setBlock(v + Vec3(-1,0,-7),53, 5)
	mc.setBlock(v + Vec3(-1,0,-6),53, 5)
	mc.setBlock(v + Vec3(-1,0,-5),53, 5)
	mc.setBlock(v + Vec3(-1,0,-4),53, 5)
	mc.setBlock(v + Vec3(-1,0,-3),53, 5)
	mc.setBlock(v + Vec3(-1,0,-2),53, 5)
	mc.setBlock(v + Vec3(-1,0,-1),53, 5)
	mc.setBlock(v + Vec3(-1,0,0),53, 5)
	mc.setBlock(v + Vec3(-1,0,1),53, 5)
	mc.setBlock(v + Vec3(-1,0,2),17, 0)
	mc.setBlock(v + Vec3(-1,0,3),53, 4)
	mc.setBlock(v + Vec3(-1,0,4),53, 4)
	mc.setBlock(v + Vec3(-1,0,5),17, 0)
	mc.setBlock(v + Vec3(-1,0,6),53, 5)
	mc.setBlock(v + Vec3(-1,0,7),53, 5)
	mc.setBlock(v + Vec3(-1,0,8),53, 5)
	mc.setBlock(v + Vec3(-1,0,9),53, 5)
	mc.setBlock(v + Vec3(-1,0,10),53, 5)
	mc.setBlock(v + Vec3(-1,0,11),53, 5)
	mc.setBlock(v + Vec3(-1,0,12),53, 5)
	mc.setBlock(v + Vec3(-1,0,13),53, 5)
	mc.setBlock(v + Vec3(-1,0,14),53, 7)
	mc.setBlock(v + Vec3(0,0,-1),53, 6)
	mc.setBlock(v + Vec3(0,0,0),53, 4)
	mc.setBlock(v + Vec3(0,0,1),53, 4)
	mc.setBlock(v + Vec3(0,0,2),17, 0)
	mc.setBlock(v + Vec3(0,0,5),17, 0)
	mc.setBlock(v + Vec3(0,0,6),53, 4)
	mc.setBlock(v + Vec3(0,0,7),53, 4)
	mc.setBlock(v + Vec3(0,0,8),53, 4)
	mc.setBlock(v + Vec3(0,0,9),53, 4)
	mc.setBlock(v + Vec3(0,0,10),53, 7)
	mc.setBlock(v + Vec3(1,0,-1),53, 6)
	mc.setBlock(v + Vec3(1,0,0),17, 1)
	mc.setBlock(v + Vec3(1,0,1),155, 0)
	mc.setBlock(v + Vec3(1,0,2),17, 1)
	mc.setBlock(v + Vec3(1,0,5),17, 1)
	mc.setBlock(v + Vec3(1,0,6),155, 0)
	mc.setBlock(v + Vec3(1,0,7),155, 0)
	mc.setBlock(v + Vec3(1,0,8),155, 0)
	mc.setBlock(v + Vec3(1,0,9),17, 1)
	mc.setBlock(v + Vec3(1,0,10),53, 7)
	mc.setBlock(v + Vec3(2,0,-1),53, 6)
	mc.setBlock(v + Vec3(2,0,0),155, 0)
	mc.setBlock(v + Vec3(2,0,9),155, 0)
	mc.setBlock(v + Vec3(2,0,10),53, 7)
	mc.setBlock(v + Vec3(3,0,-1),53, 6)
	mc.setBlock(v + Vec3(3,0,0),155, 0)
	mc.setBlock(v + Vec3(3,0,9),155, 0)
	mc.setBlock(v + Vec3(3,0,10),53, 7)
	mc.setBlock(v + Vec3(4,0,-1),53, 6)
	mc.setBlock(v + Vec3(4,0,0),155, 0)
	mc.setBlock(v + Vec3(4,0,9),155, 0)
	mc.setBlock(v + Vec3(4,0,10),53, 7)
	mc.setBlock(v + Vec3(5,0,-1),53, 6)
	mc.setBlock(v + Vec3(5,0,0),155, 0)
	mc.setBlock(v + Vec3(5,0,9),155, 0)
	mc.setBlock(v + Vec3(5,0,10),53, 7)
	mc.setBlock(v + Vec3(6,0,-1),53, 6)
	mc.setBlock(v + Vec3(6,0,0),155, 0)
	mc.setBlock(v + Vec3(6,0,9),155, 0)
	mc.setBlock(v + Vec3(6,0,10),53, 7)
	mc.setBlock(v + Vec3(7,0,-1),53, 6)
	mc.setBlock(v + Vec3(7,0,0),155, 0)
	mc.setBlock(v + Vec3(7,0,9),155, 0)
	mc.setBlock(v + Vec3(7,0,10),53, 7)
	mc.setBlock(v + Vec3(8,0,-1),53, 6)
	mc.setBlock(v + Vec3(8,0,0),155, 0)
	mc.setBlock(v + Vec3(8,0,9),155, 0)
	mc.setBlock(v + Vec3(8,0,10),53, 7)
	mc.setBlock(v + Vec3(9,0,-3),43, 2)
	mc.setBlock(v + Vec3(9,0,-2),44, 10)
	mc.setBlock(v + Vec3(9,0,-1),53, 6)
	mc.setBlock(v + Vec3(9,0,0),17, 1)
	mc.setBlock(v + Vec3(9,0,1),155, 0)
	mc.setBlock(v + Vec3(9,0,2),155, 0)
	mc.setBlock(v + Vec3(9,0,3),155, 0)
	mc.setBlock(v + Vec3(9,0,4),155, 0)
	mc.setBlock(v + Vec3(9,0,5),155, 0)
	mc.setBlock(v + Vec3(9,0,6),155, 0)
	mc.setBlock(v + Vec3(9,0,7),155, 0)
	mc.setBlock(v + Vec3(9,0,8),155, 0)
	mc.setBlock(v + Vec3(9,0,9),17, 1)
	mc.setBlock(v + Vec3(9,0,10),53, 7)
	mc.setBlock(v + Vec3(10,0,-3),44, 10)
	mc.setBlock(v + Vec3(10,0,-2),44, 10)
	mc.setBlock(v + Vec3(10,0,-1),53, 6)
	mc.setBlock(v + Vec3(10,0,0),53, 5)
	mc.setBlock(v + Vec3(10,0,1),53, 5)
	mc.setBlock(v + Vec3(10,0,2),53, 5)
	mc.setBlock(v + Vec3(10,0,3),53, 5)
	mc.setBlock(v + Vec3(10,0,4),53, 5)
	mc.setBlock(v + Vec3(10,0,5),53, 5)
	mc.setBlock(v + Vec3(10,0,6),53, 5)
	mc.setBlock(v + Vec3(10,0,7),53, 5)
	mc.setBlock(v + Vec3(10,0,8),53, 5)
	mc.setBlock(v + Vec3(10,0,9),53, 5)
	mc.setBlock(v + Vec3(10,0,10),53, 5)
	mc.setBlock(v + Vec3(11,0,-3),43, 2)
	mc.setBlock(v + Vec3(11,0,-2),44, 10)
	mc.setBlock(v + Vec3(11,0,0),44, 10)
	mc.setBlock(v + Vec3(11,0,2),44, 10)
	mc.setBlock(v + Vec3(11,0,4),44, 10)
	mc.setBlock(v + Vec3(11,0,6),44, 10)
	mc.setBlock(v + Vec3(11,0,8),44, 10)
	mc.setBlock(v + Vec3(11,0,10),44, 10)
	mc.setBlock(v + Vec3(12,0,-3),44, 10)
	mc.setBlock(v + Vec3(12,0,-2),44, 10)
	mc.setBlock(v + Vec3(12,0,0),44, 10)
	mc.setBlock(v + Vec3(12,0,2),44, 10)
	mc.setBlock(v + Vec3(12,0,4),44, 10)
	mc.setBlock(v + Vec3(12,0,6),44, 10)
	mc.setBlock(v + Vec3(12,0,8),44, 10)
	mc.setBlock(v + Vec3(12,0,10),44, 10)
	mc.setBlock(v + Vec3(13,0,-3),43, 2)
	mc.setBlock(v + Vec3(13,0,-2),44, 10)
	mc.setBlock(v + Vec3(13,0,-1),44, 10)
	mc.setBlock(v + Vec3(13,0,0),44, 10)
	mc.setBlock(v + Vec3(13,0,1),44, 10)
	mc.setBlock(v + Vec3(13,0,2),44, 10)
	mc.setBlock(v + Vec3(13,0,3),44, 10)
	mc.setBlock(v + Vec3(13,0,4),44, 10)
	mc.setBlock(v + Vec3(13,0,5),44, 10)
	mc.setBlock(v + Vec3(13,0,6),44, 10)
	mc.setBlock(v + Vec3(13,0,7),44, 10)
	mc.setBlock(v + Vec3(13,0,8),44, 10)
	mc.setBlock(v + Vec3(13,0,9),44, 10)
	mc.setBlock(v + Vec3(13,0,10),44, 10)
	mc.setBlock(v + Vec3(-12,1,-2),109, 2)
	mc.setBlock(v + Vec3(-12,1,-1),109, 7)
	mc.setBlock(v + Vec3(-12,1,1),109, 6)
	mc.setBlock(v + Vec3(-12,1,2),109, 3)
	mc.setBlock(v + Vec3(-11,1,-8),53, 2)
	mc.setBlock(v + Vec3(-11,1,-7),53, 0)
	mc.setBlock(v + Vec3(-11,1,-6),53, 0)
	mc.setBlock(v + Vec3(-11,1,-5),53, 0)
	mc.setBlock(v + Vec3(-11,1,-4),53, 0)
	mc.setBlock(v + Vec3(-11,1,-3),53, 0)
	mc.setBlock(v + Vec3(-11,1,-2),109, 2)
	mc.setBlock(v + Vec3(-11,1,-1),17, 1)
	mc.setBlock(v + Vec3(-11,1,0),17, 1)
	mc.setBlock(v + Vec3(-11,1,1),17, 1)
	mc.setBlock(v + Vec3(-11,1,2),109, 3)
	mc.setBlock(v + Vec3(-11,1,3),53, 0)
	mc.setBlock(v + Vec3(-11,1,4),53, 0)
	mc.setBlock(v + Vec3(-11,1,5),53, 0)
	mc.setBlock(v + Vec3(-11,1,6),53, 0)
	mc.setBlock(v + Vec3(-11,1,7),53, 0)
	mc.setBlock(v + Vec3(-11,1,8),53, 0)
	mc.setBlock(v + Vec3(-11,1,9),53, 0)
	mc.setBlock(v + Vec3(-11,1,10),53, 0)
	mc.setBlock(v + Vec3(-11,1,11),53, 0)
	mc.setBlock(v + Vec3(-11,1,12),53, 0)
	mc.setBlock(v + Vec3(-11,1,13),53, 0)
	mc.setBlock(v + Vec3(-10,1,-8),53, 2)
	mc.setBlock(v + Vec3(-10,1,-7),44, 8)
	mc.setBlock(v + Vec3(-10,1,-6),44, 8)
	mc.setBlock(v + Vec3(-10,1,-5),5, 0)
	mc.setBlock(v + Vec3(-10,1,-4),44, 8)
	mc.setBlock(v + Vec3(-10,1,-3),44, 8)
	mc.setBlock(v + Vec3(-10,1,-2),5, 0)
	mc.setBlock(v + Vec3(-10,1,-1),5, 0)
	mc.setBlock(v + Vec3(-10,1,0),44, 8)
	mc.setBlock(v + Vec3(-10,1,1),5, 0)
	mc.setBlock(v + Vec3(-10,1,2),44, 8)
	mc.setBlock(v + Vec3(-10,1,3),44, 8)
	mc.setBlock(v + Vec3(-10,1,4),5, 0)
	mc.setBlock(v + Vec3(-10,1,5),44, 8)
	mc.setBlock(v + Vec3(-10,1,6),44, 8)
	mc.setBlock(v + Vec3(-10,1,7),5, 0)
	mc.setBlock(v + Vec3(-10,1,8),44, 8)
	mc.setBlock(v + Vec3(-10,1,9),44, 8)
	mc.setBlock(v + Vec3(-10,1,10),5, 0)
	mc.setBlock(v + Vec3(-10,1,11),44, 8)
	mc.setBlock(v + Vec3(-10,1,12),44, 8)
	mc.setBlock(v + Vec3(-10,1,13),53, 3)
	mc.setBlock(v + Vec3(-9,1,-8),53, 2)
	mc.setBlock(v + Vec3(-9,1,-7),44, 8)
	mc.setBlock(v + Vec3(-9,1,-6),44, 8)
	mc.setBlock(v + Vec3(-9,1,-5),5, 0)
	mc.setBlock(v + Vec3(-9,1,-4),5, 0)
	mc.setBlock(v + Vec3(-9,1,-3),5, 0)
	mc.setBlock(v + Vec3(-9,1,-2),5, 0)
	mc.setBlock(v + Vec3(-9,1,-1),5, 0)
	mc.setBlock(v + Vec3(-9,1,0),44, 8)
	mc.setBlock(v + Vec3(-9,1,1),5, 0)
	mc.setBlock(v + Vec3(-9,1,2),5, 0)
	mc.setBlock(v + Vec3(-9,1,3),5, 0)
	mc.setBlock(v + Vec3(-9,1,4),5, 0)
	mc.setBlock(v + Vec3(-9,1,5),44, 8)
	mc.setBlock(v + Vec3(-9,1,6),44, 8)
	mc.setBlock(v + Vec3(-9,1,7),5, 0)
	mc.setBlock(v + Vec3(-9,1,8),44, 10)
	mc.setBlock(v + Vec3(-9,1,9),44, 10)
	mc.setBlock(v + Vec3(-9,1,10),5, 0)
	mc.setBlock(v + Vec3(-9,1,11),44, 8)
	mc.setBlock(v + Vec3(-9,1,12),44, 8)
	mc.setBlock(v + Vec3(-9,1,13),53, 3)
	mc.setBlock(v + Vec3(-8,1,-9),4, 0)
	mc.setBlock(v + Vec3(-8,1,-8),4, 0)
	mc.setBlock(v + Vec3(-8,1,-7),5, 0)
	mc.setBlock(v + Vec3(-8,1,-6),5, 0)
	mc.setBlock(v + Vec3(-8,1,-5),5, 0)
	mc.setBlock(v + Vec3(-8,1,-4),44, 8)
	mc.setBlock(v + Vec3(-8,1,-3),44, 8)
	mc.setBlock(v + Vec3(-8,1,-2),5, 0)
	mc.setBlock(v + Vec3(-8,1,-1),5, 0)
	mc.setBlock(v + Vec3(-8,1,0),5, 0)
	mc.setBlock(v + Vec3(-8,1,1),5, 0)
	mc.setBlock(v + Vec3(-8,1,2),44, 8)
	mc.setBlock(v + Vec3(-8,1,3),44, 8)
	mc.setBlock(v + Vec3(-8,1,4),5, 0)
	mc.setBlock(v + Vec3(-8,1,5),5, 0)
	mc.setBlock(v + Vec3(-8,1,6),5, 0)
	mc.setBlock(v + Vec3(-8,1,7),5, 0)
	mc.setBlock(v + Vec3(-8,1,8),44, 8)
	mc.setBlock(v + Vec3(-8,1,9),44, 8)
	mc.setBlock(v + Vec3(-8,1,10),5, 0)
	mc.setBlock(v + Vec3(-8,1,11),5, 0)
	mc.setBlock(v + Vec3(-8,1,12),5, 0)
	mc.setBlock(v + Vec3(-8,1,13),53, 3)
	mc.setBlock(v + Vec3(-7,1,-9),4, 0)
	mc.setBlock(v + Vec3(-7,1,-7),44, 8)
	mc.setBlock(v + Vec3(-7,1,-6),44, 8)
	mc.setBlock(v + Vec3(-7,1,-5),5, 0)
	mc.setBlock(v + Vec3(-7,1,-4),44, 8)
	mc.setBlock(v + Vec3(-7,1,-3),44, 8)
	mc.setBlock(v + Vec3(-7,1,-2),5, 0)
	mc.setBlock(v + Vec3(-7,1,-1),96, 1)
	mc.setBlock(v + Vec3(-7,1,0),96, 0)
	mc.setBlock(v + Vec3(-7,1,1),5, 0)
	mc.setBlock(v + Vec3(-7,1,2),44, 8)
	mc.setBlock(v + Vec3(-7,1,3),44, 8)
	mc.setBlock(v + Vec3(-7,1,4),5, 0)
	mc.setBlock(v + Vec3(-7,1,5),44, 8)
	mc.setBlock(v + Vec3(-7,1,6),44, 8)
	mc.setBlock(v + Vec3(-7,1,7),5, 0)
	mc.setBlock(v + Vec3(-7,1,8),44, 8)
	mc.setBlock(v + Vec3(-7,1,10),5, 0)
	mc.setBlock(v + Vec3(-7,1,11),44, 8)
	mc.setBlock(v + Vec3(-7,1,12),44, 8)
	mc.setBlock(v + Vec3(-7,1,13),53, 3)
	mc.setBlock(v + Vec3(-6,1,-9),4, 0)
	mc.setBlock(v + Vec3(-6,1,-7),44, 8)
	mc.setBlock(v + Vec3(-6,1,-6),44, 8)
	mc.setBlock(v + Vec3(-6,1,-5),5, 0)
	mc.setBlock(v + Vec3(-6,1,-4),44, 8)
	mc.setBlock(v + Vec3(-6,1,-3),44, 8)
	mc.setBlock(v + Vec3(-6,1,-2),5, 0)
	mc.setBlock(v + Vec3(-6,1,-1),96, 6)
	mc.setBlock(v + Vec3(-6,1,0),96, 0)
	mc.setBlock(v + Vec3(-6,1,1),5, 0)
	mc.setBlock(v + Vec3(-6,1,2),44, 8)
	mc.setBlock(v + Vec3(-6,1,3),44, 8)
	mc.setBlock(v + Vec3(-6,1,4),5, 0)
	mc.setBlock(v + Vec3(-6,1,5),44, 8)
	mc.setBlock(v + Vec3(-6,1,6),44, 8)
	mc.setBlock(v + Vec3(-6,1,7),5, 0)
	mc.setBlock(v + Vec3(-6,1,8),44, 8)
	mc.setBlock(v + Vec3(-6,1,10),5, 0)
	mc.setBlock(v + Vec3(-6,1,11),44, 8)
	mc.setBlock(v + Vec3(-6,1,12),44, 8)
	mc.setBlock(v + Vec3(-6,1,13),53, 3)
	mc.setBlock(v + Vec3(-5,1,-9),4, 0)
	mc.setBlock(v + Vec3(-5,1,-8),4, 0)
	mc.setBlock(v + Vec3(-5,1,-7),5, 0)
	mc.setBlock(v + Vec3(-5,1,-6),5, 0)
	mc.setBlock(v + Vec3(-5,1,-5),5, 0)
	mc.setBlock(v + Vec3(-5,1,-4),44, 8)
	mc.setBlock(v + Vec3(-5,1,-3),44, 8)
	mc.setBlock(v + Vec3(-5,1,-2),5, 0)
	mc.setBlock(v + Vec3(-5,1,-1),5, 0)
	mc.setBlock(v + Vec3(-5,1,0),5, 0)
	mc.setBlock(v + Vec3(-5,1,1),5, 0)
	mc.setBlock(v + Vec3(-5,1,2),44, 8)
	mc.setBlock(v + Vec3(-5,1,3),44, 8)
	mc.setBlock(v + Vec3(-5,1,4),5, 0)
	mc.setBlock(v + Vec3(-5,1,5),5, 0)
	mc.setBlock(v + Vec3(-5,1,6),5, 0)
	mc.setBlock(v + Vec3(-5,1,7),5, 0)
	mc.setBlock(v + Vec3(-5,1,8),44, 8)
	mc.setBlock(v + Vec3(-5,1,9),44, 8)
	mc.setBlock(v + Vec3(-5,1,10),5, 0)
	mc.setBlock(v + Vec3(-5,1,11),5, 0)
	mc.setBlock(v + Vec3(-5,1,12),5, 0)
	mc.setBlock(v + Vec3(-5,1,13),53, 3)
	mc.setBlock(v + Vec3(-4,1,-8),53, 2)
	mc.setBlock(v + Vec3(-4,1,-7),44, 8)
	mc.setBlock(v + Vec3(-4,1,-6),44, 8)
	mc.setBlock(v + Vec3(-4,1,-5),5, 0)
	mc.setBlock(v + Vec3(-4,1,-4),5, 0)
	mc.setBlock(v + Vec3(-4,1,-3),5, 0)
	mc.setBlock(v + Vec3(-4,1,-2),5, 0)
	mc.setBlock(v + Vec3(-4,1,-1),44, 8)
	mc.setBlock(v + Vec3(-4,1,0),44, 8)
	mc.setBlock(v + Vec3(-4,1,1),5, 0)
	mc.setBlock(v + Vec3(-4,1,2),5, 0)
	mc.setBlock(v + Vec3(-4,1,3),5, 0)
	mc.setBlock(v + Vec3(-4,1,4),5, 0)
	mc.setBlock(v + Vec3(-4,1,5),44, 8)
	mc.setBlock(v + Vec3(-4,1,6),44, 8)
	mc.setBlock(v + Vec3(-4,1,7),5, 0)
	mc.setBlock(v + Vec3(-4,1,8),5, 0)
	mc.setBlock(v + Vec3(-4,1,9),5, 0)
	mc.setBlock(v + Vec3(-4,1,10),5, 0)
	mc.setBlock(v + Vec3(-4,1,11),44, 8)
	mc.setBlock(v + Vec3(-4,1,12),44, 8)
	mc.setBlock(v + Vec3(-4,1,13),53, 3)
	mc.setBlock(v + Vec3(-3,1,-8),53, 2)
	mc.setBlock(v + Vec3(-3,1,-7),44, 8)
	mc.setBlock(v + Vec3(-3,1,-6),44, 8)
	mc.setBlock(v + Vec3(-3,1,-5),5, 0)
	mc.setBlock(v + Vec3(-3,1,-4),44, 8)
	mc.setBlock(v + Vec3(-3,1,-3),44, 8)
	mc.setBlock(v + Vec3(-3,1,-2),5, 0)
	mc.setBlock(v + Vec3(-3,1,-1),44, 8)
	mc.setBlock(v + Vec3(-3,1,0),44, 8)
	mc.setBlock(v + Vec3(-3,1,1),5, 0)
	mc.setBlock(v + Vec3(-3,1,2),44, 8)
	mc.setBlock(v + Vec3(-3,1,3),44, 8)
	mc.setBlock(v + Vec3(-3,1,4),5, 0)
	mc.setBlock(v + Vec3(-3,1,5),44, 8)
	mc.setBlock(v + Vec3(-3,1,6),44, 8)
	mc.setBlock(v + Vec3(-3,1,7),5, 0)
	mc.setBlock(v + Vec3(-3,1,8),44, 8)
	mc.setBlock(v + Vec3(-3,1,9),44, 8)
	mc.setBlock(v + Vec3(-3,1,10),5, 0)
	mc.setBlock(v + Vec3(-3,1,11),44, 8)
	mc.setBlock(v + Vec3(-3,1,12),44, 8)
	mc.setBlock(v + Vec3(-3,1,13),53, 3)
	mc.setBlock(v + Vec3(-2,1,-8),53, 1)
	mc.setBlock(v + Vec3(-2,1,-7),53, 1)
	mc.setBlock(v + Vec3(-2,1,-6),53, 1)
	mc.setBlock(v + Vec3(-2,1,-5),53, 1)
	mc.setBlock(v + Vec3(-2,1,-4),53, 1)
	mc.setBlock(v + Vec3(-2,1,-3),53, 1)
	mc.setBlock(v + Vec3(-2,1,-2),53, 1)
	mc.setBlock(v + Vec3(-2,1,-1),53, 1)
	mc.setBlock(v + Vec3(-2,1,0),53, 1)
	mc.setBlock(v + Vec3(-2,1,1),53, 1)
	mc.setBlock(v + Vec3(-2,1,2),53, 2)
	mc.setBlock(v + Vec3(-2,1,3),5, 0)
	mc.setBlock(v + Vec3(-2,1,4),5, 0)
	mc.setBlock(v + Vec3(-2,1,5),53, 3)
	mc.setBlock(v + Vec3(-2,1,6),53, 1)
	mc.setBlock(v + Vec3(-2,1,7),53, 1)
	mc.setBlock(v + Vec3(-2,1,8),53, 1)
	mc.setBlock(v + Vec3(-2,1,9),53, 1)
	mc.setBlock(v + Vec3(-2,1,10),53, 1)
	mc.setBlock(v + Vec3(-2,1,11),53, 1)
	mc.setBlock(v + Vec3(-2,1,12),53, 1)
	mc.setBlock(v + Vec3(-2,1,13),53, 3)
	mc.setBlock(v + Vec3(-1,1,2),53, 2)
	mc.setBlock(v + Vec3(-1,1,3),5, 0)
	mc.setBlock(v + Vec3(-1,1,4),5, 0)
	mc.setBlock(v + Vec3(-1,1,5),53, 3)
	mc.setBlock(v + Vec3(0,1,2),53, 2)
	mc.setBlock(v + Vec3(0,1,3),5, 0)
	mc.setBlock(v + Vec3(0,1,4),5, 0)
	mc.setBlock(v + Vec3(0,1,5),53, 3)
	mc.setBlock(v + Vec3(1,1,0),53, 0)
	mc.setBlock(v + Vec3(1,1,1),53, 0)
	mc.setBlock(v + Vec3(1,1,2),53, 2)
	mc.setBlock(v + Vec3(1,1,3),5, 0)
	mc.setBlock(v + Vec3(1,1,4),5, 0)
	mc.setBlock(v + Vec3(1,1,5),53, 3)
	mc.setBlock(v + Vec3(1,1,6),53, 0)
	mc.setBlock(v + Vec3(1,1,7),53, 0)
	mc.setBlock(v + Vec3(1,1,8),53, 0)
	mc.setBlock(v + Vec3(1,1,9),53, 0)
	mc.setBlock(v + Vec3(2,1,0),53, 2)
	mc.setBlock(v + Vec3(2,1,1),5, 0)
	mc.setBlock(v + Vec3(2,1,2),5, 0)
	mc.setBlock(v + Vec3(2,1,3),5, 0)
	mc.setBlock(v + Vec3(2,1,4),5, 0)
	mc.setBlock(v + Vec3(2,1,5),5, 0)
	mc.setBlock(v + Vec3(2,1,6),5, 0)
	mc.setBlock(v + Vec3(2,1,7),5, 0)
	mc.setBlock(v + Vec3(2,1,8),5, 0)
	mc.setBlock(v + Vec3(2,1,9),53, 3)
	mc.setBlock(v + Vec3(3,1,0),53, 2)
	mc.setBlock(v + Vec3(3,1,1),5, 0)
	mc.setBlock(v + Vec3(3,1,2),5, 0)
	mc.setBlock(v + Vec3(3,1,3),5, 0)
	mc.setBlock(v + Vec3(3,1,4),5, 0)
	mc.setBlock(v + Vec3(3,1,5),5, 0)
	mc.setBlock(v + Vec3(3,1,6),5, 0)
	mc.setBlock(v + Vec3(3,1,7),5, 0)
	mc.setBlock(v + Vec3(3,1,8),5, 0)
	mc.setBlock(v + Vec3(3,1,9),53, 3)
	mc.setBlock(v + Vec3(4,1,0),53, 2)
	mc.setBlock(v + Vec3(4,1,1),5, 0)
	mc.setBlock(v + Vec3(4,1,2),5, 0)
	mc.setBlock(v + Vec3(4,1,3),5, 0)
	mc.setBlock(v + Vec3(4,1,4),5, 0)
	mc.setBlock(v + Vec3(4,1,5),5, 0)
	mc.setBlock(v + Vec3(4,1,6),5, 0)
	mc.setBlock(v + Vec3(4,1,7),5, 0)
	mc.setBlock(v + Vec3(4,1,8),5, 0)
	mc.setBlock(v + Vec3(4,1,9),53, 3)
	mc.setBlock(v + Vec3(5,1,0),53, 2)
	mc.setBlock(v + Vec3(5,1,1),5, 0)
	mc.setBlock(v + Vec3(5,1,2),5, 0)
	mc.setBlock(v + Vec3(5,1,3),5, 0)
	mc.setBlock(v + Vec3(5,1,4),5, 0)
	mc.setBlock(v + Vec3(5,1,5),5, 0)
	mc.setBlock(v + Vec3(5,1,6),5, 0)
	mc.setBlock(v + Vec3(5,1,7),5, 0)
	mc.setBlock(v + Vec3(5,1,8),5, 0)
	mc.setBlock(v + Vec3(5,1,9),53, 3)
	mc.setBlock(v + Vec3(6,1,0),53, 2)
	mc.setBlock(v + Vec3(6,1,1),5, 0)
	mc.setBlock(v + Vec3(6,1,2),5, 0)
	mc.setBlock(v + Vec3(6,1,3),5, 0)
	mc.setBlock(v + Vec3(6,1,4),5, 0)
	mc.setBlock(v + Vec3(6,1,5),5, 0)
	mc.setBlock(v + Vec3(6,1,6),5, 0)
	mc.setBlock(v + Vec3(6,1,7),5, 0)
	mc.setBlock(v + Vec3(6,1,8),5, 0)
	mc.setBlock(v + Vec3(6,1,9),53, 3)
	mc.setBlock(v + Vec3(7,1,0),53, 2)
	mc.setBlock(v + Vec3(7,1,1),5, 0)
	mc.setBlock(v + Vec3(7,1,2),5, 0)
	mc.setBlock(v + Vec3(7,1,3),5, 0)
	mc.setBlock(v + Vec3(7,1,4),5, 0)
	mc.setBlock(v + Vec3(7,1,5),5, 0)
	mc.setBlock(v + Vec3(7,1,6),5, 0)
	mc.setBlock(v + Vec3(7,1,7),5, 0)
	mc.setBlock(v + Vec3(7,1,8),5, 0)
	mc.setBlock(v + Vec3(7,1,9),53, 3)
	mc.setBlock(v + Vec3(8,1,0),53, 2)
	mc.setBlock(v + Vec3(8,1,1),5, 0)
	mc.setBlock(v + Vec3(8,1,2),5, 0)
	mc.setBlock(v + Vec3(8,1,3),5, 0)
	mc.setBlock(v + Vec3(8,1,4),5, 0)
	mc.setBlock(v + Vec3(8,1,5),5, 0)
	mc.setBlock(v + Vec3(8,1,6),5, 0)
	mc.setBlock(v + Vec3(8,1,7),5, 0)
	mc.setBlock(v + Vec3(8,1,8),5, 0)
	mc.setBlock(v + Vec3(8,1,9),53, 3)
	mc.setBlock(v + Vec3(9,1,0),53, 2)
	mc.setBlock(v + Vec3(9,1,1),53, 1)
	mc.setBlock(v + Vec3(9,1,2),53, 1)
	mc.setBlock(v + Vec3(9,1,3),53, 1)
	mc.setBlock(v + Vec3(9,1,4),53, 1)
	mc.setBlock(v + Vec3(9,1,5),53, 1)
	mc.setBlock(v + Vec3(9,1,6),53, 1)
	mc.setBlock(v + Vec3(9,1,7),53, 1)
	mc.setBlock(v + Vec3(9,1,8),53, 1)
	mc.setBlock(v + Vec3(9,1,9),53, 3)
	mc.setBlock(v + Vec3(-12,2,-1),109, 2)
	mc.setBlock(v + Vec3(-12,2,0),98, 0)
	mc.setBlock(v + Vec3(-12,2,1),109, 3)
	mc.setBlock(v + Vec3(-11,2,-1),109, 2)
	mc.setBlock(v + Vec3(-11,2,0),109, 1)
	mc.setBlock(v + Vec3(-11,2,1),109, 3)
	mc.setBlock(v + Vec3(-8,2,-9),4, 0)
	mc.setBlock(v + Vec3(-8,2,-8),4, 0)
	mc.setBlock(v + Vec3(-8,2,-7),4, 0)
	mc.setBlock(v + Vec3(-7,2,-9),4, 0)
	mc.setBlock(v + Vec3(-7,2,-7),4, 0)
	mc.setBlock(v + Vec3(-6,2,-9),4, 0)
	mc.setBlock(v + Vec3(-6,2,-7),4, 0)
	mc.setBlock(v + Vec3(-5,2,-9),4, 0)
	mc.setBlock(v + Vec3(-5,2,-8),4, 0)
	mc.setBlock(v + Vec3(-5,2,-7),4, 0)
	mc.setBlock(v + Vec3(-8,3,-9),67, 0)
	mc.setBlock(v + Vec3(-8,3,-8),67, 0)
	mc.setBlock(v + Vec3(-8,3,-7),67, 0)
	mc.setBlock(v + Vec3(-7,3,-9),4, 0)
	mc.setBlock(v + Vec3(-7,3,-7),4, 0)
	mc.setBlock(v + Vec3(-6,3,-9),4, 0)
	mc.setBlock(v + Vec3(-6,3,-7),4, 0)
