mc.setBlock(loc + Vec3(-4,-4,-4),1, 0)
mc.setBlock(loc + Vec3(-4,-4,-3),1, 0)
mc.setBlock(loc + Vec3(-4,-4,-2),1, 0)
mc.setBlock(loc + Vec3(-4,-4,-1),1, 0)
mc.setBlock(loc + Vec3(-4,-4,0),1, 0)
mc.setBlock(loc + Vec3(-4,-4,1),1, 0)
mc.setBlock(loc + Vec3(-4,-4,2),1, 0)
mc.setBlock(loc + Vec3(-4,-4,3),1, 0)
mc.setBlock(loc + Vec3(-3,-4,-4),1, 0)
mc.setBlock(loc + Vec3(-3,-4,-3),1, 0)
mc.setBlock(loc + Vec3(-3,-4,-2),1, 0)
mc.setBlock(loc + Vec3(-3,-4,-1),1, 0)
mc.setBlock(loc + Vec3(-3,-4,0),1, 0)
mc.setBlock(loc + Vec3(-3,-4,1),1, 0)
mc.setBlock(loc + Vec3(-3,-4,2),1, 0)
mc.setBlock(loc + Vec3(-3,-4,3),1, 0)
mc.setBlock(loc + Vec3(-2,-4,-4),1, 0)
mc.setBlock(loc + Vec3(-2,-4,-3),1, 0)
mc.setBlock(loc + Vec3(-2,-4,-2),1, 0)
mc.setBlock(loc + Vec3(-2,-4,-1),1, 0)
mc.setBlock(loc + Vec3(-2,-4,0),1, 0)
mc.setBlock(loc + Vec3(-2,-4,1),1, 0)
mc.setBlock(loc + Vec3(-2,-4,2),1, 0)
mc.setBlock(loc + Vec3(-2,-4,3),1, 0)
mc.setBlock(loc + Vec3(-1,-4,-4),1, 0)
mc.setBlock(loc + Vec3(-1,-4,-3),1, 0)
mc.setBlock(loc + Vec3(-1,-4,-2),1, 0)
mc.setBlock(loc + Vec3(-1,-4,-1),1, 0)
mc.setBlock(loc + Vec3(-1,-4,0),1, 0)
mc.setBlock(loc + Vec3(-1,-4,1),1, 0)
mc.setBlock(loc + Vec3(-1,-4,2),1, 0)
mc.setBlock(loc + Vec3(-1,-4,3),1, 0)
mc.setBlock(loc + Vec3(0,-4,-4),1, 0)
mc.setBlock(loc + Vec3(0,-4,-3),1, 0)
mc.setBlock(loc + Vec3(0,-4,-2),1, 0)
mc.setBlock(loc + Vec3(0,-4,-1),1, 0)
mc.setBlock(loc + Vec3(0,-4,0),1, 0)
mc.setBlock(loc + Vec3(0,-4,1),1, 0)
mc.setBlock(loc + Vec3(0,-4,2),1, 0)
mc.setBlock(loc + Vec3(0,-4,3),1, 0)
mc.setBlock(loc + Vec3(1,-4,-4),1, 0)
mc.setBlock(loc + Vec3(1,-4,-3),1, 0)
mc.setBlock(loc + Vec3(1,-4,-2),1, 0)
mc.setBlock(loc + Vec3(1,-4,-1),1, 0)
mc.setBlock(loc + Vec3(1,-4,0),1, 0)
mc.setBlock(loc + Vec3(1,-4,1),1, 0)
mc.setBlock(loc + Vec3(1,-4,2),1, 0)
mc.setBlock(loc + Vec3(1,-4,3),1, 0)
mc.setBlock(loc + Vec3(2,-4,-4),1, 0)
mc.setBlock(loc + Vec3(2,-4,-3),1, 0)
mc.setBlock(loc + Vec3(2,-4,-2),1, 0)
mc.setBlock(loc + Vec3(2,-4,-1),1, 0)
mc.setBlock(loc + Vec3(2,-4,0),1, 0)
mc.setBlock(loc + Vec3(2,-4,1),1, 0)
mc.setBlock(loc + Vec3(2,-4,2),1, 0)
mc.setBlock(loc + Vec3(2,-4,3),1, 0)
mc.setBlock(loc + Vec3(3,-4,-4),1, 0)
mc.setBlock(loc + Vec3(3,-4,-3),1, 0)
mc.setBlock(loc + Vec3(3,-4,-2),1, 0)
mc.setBlock(loc + Vec3(3,-4,-1),1, 0)
mc.setBlock(loc + Vec3(3,-4,0),1, 0)
mc.setBlock(loc + Vec3(3,-4,1),1, 0)
mc.setBlock(loc + Vec3(3,-4,2),1, 0)
mc.setBlock(loc + Vec3(3,-4,3),1, 0)
mc.setBlock(loc + Vec3(-4,-3,-4),1, 0)
mc.setBlock(loc + Vec3(-4,-3,-2),1, 0)
mc.setBlock(loc + Vec3(-4,-3,-1),1, 0)
mc.setBlock(loc + Vec3(-4,-3,0),1, 0)
mc.setBlock(loc + Vec3(-4,-3,1),1, 0)
mc.setBlock(loc + Vec3(-4,-3,2),1, 0)
mc.setBlock(loc + Vec3(-4,-3,3),1, 0)
mc.setBlock(loc + Vec3(-3,-3,-4),1, 0)
mc.setBlock(loc + Vec3(-3,-3,-3),1, 0)
mc.setBlock(loc + Vec3(-3,-3,-2),1, 0)
mc.setBlock(loc + Vec3(-3,-3,-1),1, 0)
mc.setBlock(loc + Vec3(-3,-3,0),1, 0)
mc.setBlock(loc + Vec3(-3,-3,1),1, 0)
mc.setBlock(loc + Vec3(-3,-3,2),1, 0)
mc.setBlock(loc + Vec3(-3,-3,3),1, 0)
mc.setBlock(loc + Vec3(-2,-3,-4),1, 0)
mc.setBlock(loc + Vec3(-2,-3,-3),1, 0)
mc.setBlock(loc + Vec3(-2,-3,-2),1, 0)
mc.setBlock(loc + Vec3(-2,-3,-1),1, 0)
mc.setBlock(loc + Vec3(-2,-3,0),1, 0)
mc.setBlock(loc + Vec3(-2,-3,1),1, 0)
mc.setBlock(loc + Vec3(-2,-3,2),1, 0)
mc.setBlock(loc + Vec3(-2,-3,3),1, 0)
mc.setBlock(loc + Vec3(-1,-3,-4),1, 0)
mc.setBlock(loc + Vec3(-1,-3,-3),1, 0)
mc.setBlock(loc + Vec3(-1,-3,-2),1, 0)
mc.setBlock(loc + Vec3(-1,-3,-1),1, 0)
mc.setBlock(loc + Vec3(-1,-3,0),1, 0)
mc.setBlock(loc + Vec3(-1,-3,1),1, 0)
mc.setBlock(loc + Vec3(-1,-3,2),1, 0)
mc.setBlock(loc + Vec3(-1,-3,3),1, 0)
mc.setBlock(loc + Vec3(0,-3,-4),1, 0)
mc.setBlock(loc + Vec3(0,-3,-3),1, 0)
mc.setBlock(loc + Vec3(0,-3,-2),1, 0)
mc.setBlock(loc + Vec3(0,-3,-1),1, 0)
mc.setBlock(loc + Vec3(0,-3,0),1, 0)
mc.setBlock(loc + Vec3(0,-3,1),1, 0)
mc.setBlock(loc + Vec3(0,-3,2),1, 0)
mc.setBlock(loc + Vec3(0,-3,3),1, 0)
mc.setBlock(loc + Vec3(1,-3,-4),1, 0)
mc.setBlock(loc + Vec3(1,-3,-3),1, 0)
mc.setBlock(loc + Vec3(1,-3,-2),1, 0)
mc.setBlock(loc + Vec3(1,-3,-1),1, 0)
mc.setBlock(loc + Vec3(1,-3,0),1, 0)
mc.setBlock(loc + Vec3(1,-3,1),1, 0)
mc.setBlock(loc + Vec3(1,-3,2),1, 0)
mc.setBlock(loc + Vec3(1,-3,3),1, 0)
mc.setBlock(loc + Vec3(2,-3,-4),1, 0)
mc.setBlock(loc + Vec3(2,-3,-3),1, 0)
mc.setBlock(loc + Vec3(2,-3,-2),1, 0)
mc.setBlock(loc + Vec3(2,-3,-1),1, 0)
mc.setBlock(loc + Vec3(2,-3,0),1, 0)
mc.setBlock(loc + Vec3(2,-3,1),1, 0)
mc.setBlock(loc + Vec3(2,-3,2),1, 0)
mc.setBlock(loc + Vec3(2,-3,3),1, 0)
mc.setBlock(loc + Vec3(3,-3,-4),1, 0)
mc.setBlock(loc + Vec3(3,-3,-3),1, 0)
mc.setBlock(loc + Vec3(3,-3,-2),1, 0)
mc.setBlock(loc + Vec3(3,-3,-1),1, 0)
mc.setBlock(loc + Vec3(3,-3,0),1, 0)
mc.setBlock(loc + Vec3(3,-3,1),1, 0)
mc.setBlock(loc + Vec3(3,-3,2),1, 0)
mc.setBlock(loc + Vec3(3,-3,3),1, 0)
mc.setBlock(loc + Vec3(-4,-2,-4),3, 0)
mc.setBlock(loc + Vec3(-4,-2,-3),3, 0)
mc.setBlock(loc + Vec3(-4,-2,-2),3, 0)
mc.setBlock(loc + Vec3(-4,-2,-1),3, 0)
mc.setBlock(loc + Vec3(-4,-2,0),3, 0)
mc.setBlock(loc + Vec3(-4,-2,1),3, 0)
mc.setBlock(loc + Vec3(-4,-2,2),3, 0)
mc.setBlock(loc + Vec3(-4,-2,3),3, 0)
mc.setBlock(loc + Vec3(-3,-2,-4),98, 0)
mc.setBlock(loc + Vec3(-3,-2,-3),98, 0)
mc.setBlock(loc + Vec3(-3,-2,-2),98, 0)
mc.setBlock(loc + Vec3(-3,-2,-1),98, 0)
mc.setBlock(loc + Vec3(-3,-2,0),98, 0)
mc.setBlock(loc + Vec3(-3,-2,1),98, 0)
mc.setBlock(loc + Vec3(-3,-2,2),98, 0)
mc.setBlock(loc + Vec3(-3,-2,3),3, 0)
mc.setBlock(loc + Vec3(-2,-2,-4),98, 0)
mc.setBlock(loc + Vec3(-2,-2,-3),98, 2)
mc.setBlock(loc + Vec3(-2,-2,-2),98, 0)
mc.setBlock(loc + Vec3(-2,-2,-1),98, 0)
mc.setBlock(loc + Vec3(-2,-2,0),98, 0)
mc.setBlock(loc + Vec3(-2,-2,1),98, 1)
mc.setBlock(loc + Vec3(-2,-2,2),98, 0)
mc.setBlock(loc + Vec3(-2,-2,3),3, 0)
mc.setBlock(loc + Vec3(-1,-2,-4),98, 0)
mc.setBlock(loc + Vec3(-1,-2,-3),98, 2)
mc.setBlock(loc + Vec3(-1,-2,-2),98, 0)
mc.setBlock(loc + Vec3(-1,-2,-1),98, 0)
mc.setBlock(loc + Vec3(-1,-2,0),98, 0)
mc.setBlock(loc + Vec3(-1,-2,1),98, 0)
mc.setBlock(loc + Vec3(-1,-2,2),98, 0)
mc.setBlock(loc + Vec3(-1,-2,3),3, 0)
mc.setBlock(loc + Vec3(0,-2,-4),98, 0)
mc.setBlock(loc + Vec3(0,-2,-3),98, 2)
mc.setBlock(loc + Vec3(0,-2,-2),98, 0)
mc.setBlock(loc + Vec3(0,-2,-1),98, 0)
mc.setBlock(loc + Vec3(0,-2,0),98, 0)
mc.setBlock(loc + Vec3(0,-2,1),98, 0)
mc.setBlock(loc + Vec3(0,-2,2),98, 0)
mc.setBlock(loc + Vec3(0,-2,3),3, 0)
mc.setBlock(loc + Vec3(1,-2,-4),98, 0)
mc.setBlock(loc + Vec3(1,-2,-3),98, 0)
mc.setBlock(loc + Vec3(1,-2,-2),98, 0)
mc.setBlock(loc + Vec3(1,-2,-1),98, 0)
mc.setBlock(loc + Vec3(1,-2,0),98, 0)
mc.setBlock(loc + Vec3(1,-2,1),98, 0)
mc.setBlock(loc + Vec3(1,-2,2),98, 0)
mc.setBlock(loc + Vec3(1,-2,3),3, 0)
mc.setBlock(loc + Vec3(2,-2,-4),98, 0)
mc.setBlock(loc + Vec3(2,-2,-3),98, 0)
mc.setBlock(loc + Vec3(2,-2,-2),98, 0)
mc.setBlock(loc + Vec3(2,-2,-1),98, 0)
mc.setBlock(loc + Vec3(2,-2,0),98, 0)
mc.setBlock(loc + Vec3(2,-2,1),98, 2)
mc.setBlock(loc + Vec3(2,-2,2),98, 0)
mc.setBlock(loc + Vec3(2,-2,3),3, 0)
mc.setBlock(loc + Vec3(3,-2,-4),98, 0)
mc.setBlock(loc + Vec3(3,-2,-3),98, 0)
mc.setBlock(loc + Vec3(3,-2,-2),98, 0)
mc.setBlock(loc + Vec3(3,-2,-1),98, 0)
mc.setBlock(loc + Vec3(3,-2,0),98, 0)
mc.setBlock(loc + Vec3(3,-2,1),98, 0)
mc.setBlock(loc + Vec3(3,-2,2),98, 0)
mc.setBlock(loc + Vec3(3,-2,3),3, 0)
mc.setBlock(loc + Vec3(-4,-1,-4),2, 0)
mc.setBlock(loc + Vec3(-4,-1,-3),2, 0)
mc.setBlock(loc + Vec3(-4,-1,-2),2, 0)
mc.setBlock(loc + Vec3(-4,-1,-1),2, 0)
mc.setBlock(loc + Vec3(-4,-1,0),2, 0)
mc.setBlock(loc + Vec3(-4,-1,1),2, 0)
mc.setBlock(loc + Vec3(-4,-1,2),2, 0)
mc.setBlock(loc + Vec3(-4,-1,3),2, 0)
mc.setBlock(loc + Vec3(-3,-1,-4),98, 0)
mc.setBlock(loc + Vec3(-3,-1,-3),98, 2)
mc.setBlock(loc + Vec3(-3,-1,-2),98, 0)
mc.setBlock(loc + Vec3(-3,-1,-1),98, 0)
mc.setBlock(loc + Vec3(-3,-1,0),98, 0)
mc.setBlock(loc + Vec3(-3,-1,1),98, 1)
mc.setBlock(loc + Vec3(-3,-1,2),98, 0)
mc.setBlock(loc + Vec3(-3,-1,3),98, 0)
mc.setBlock(loc + Vec3(-2,-1,-4),98, 2)
mc.setBlock(loc + Vec3(-2,-1,2),98, 1)
mc.setBlock(loc + Vec3(-2,-1,3),98, 0)
mc.setBlock(loc + Vec3(-1,-1,-4),98, 0)
mc.setBlock(loc + Vec3(-1,-1,2),109, 1)
mc.setBlock(loc + Vec3(-1,-1,3),109, 2)
mc.setBlock(loc + Vec3(0,-1,-4),98, 0)
mc.setBlock(loc + Vec3(0,-1,3),109, 2)
mc.setBlock(loc + Vec3(1,-1,-4),98, 0)
mc.setBlock(loc + Vec3(1,-1,2),109, 0)
mc.setBlock(loc + Vec3(1,-1,3),109, 0)
mc.setBlock(loc + Vec3(2,-1,-4),98, 0)
mc.setBlock(loc + Vec3(2,-1,2),98, 0)
mc.setBlock(loc + Vec3(2,-1,3),98, 0)
mc.setBlock(loc + Vec3(3,-1,-4),98, 1)
mc.setBlock(loc + Vec3(3,-1,-3),98, 0)
mc.setBlock(loc + Vec3(3,-1,-2),98, 0)
mc.setBlock(loc + Vec3(3,-1,-1),98, 0)
mc.setBlock(loc + Vec3(3,-1,0),98, 0)
mc.setBlock(loc + Vec3(3,-1,1),98, 0)
mc.setBlock(loc + Vec3(3,-1,2),98, 0)
mc.setBlock(loc + Vec3(3,-1,3),98, 0)
mc.setBlock(loc + Vec3(-3,0,-4),98, 0)
mc.setBlock(loc + Vec3(-3,0,-3),109, 3)
mc.setBlock(loc + Vec3(-3,0,-2),109, 3)
mc.setBlock(loc + Vec3(-3,0,-1),109, 3)
mc.setBlock(loc + Vec3(-3,0,0),109, 3)
mc.setBlock(loc + Vec3(-3,0,1),109, 3)
mc.setBlock(loc + Vec3(-3,0,2),109, 3)
mc.setBlock(loc + Vec3(-3,0,3),98, 1)
mc.setBlock(loc + Vec3(-2,0,-4),109, 0)
mc.setBlock(loc + Vec3(-2,0,3),109, 0)
mc.setBlock(loc + Vec3(-1,0,-4),109, 0)
mc.setBlock(loc + Vec3(0,0,-4),43, 5)
mc.setBlock(loc + Vec3(1,0,-4),109, 1)
mc.setBlock(loc + Vec3(2,0,-4),109, 1)
mc.setBlock(loc + Vec3(2,0,3),109, 1)
mc.setBlock(loc + Vec3(3,0,-4),98, 1)
mc.setBlock(loc + Vec3(3,0,-3),109, 3)
mc.setBlock(loc + Vec3(3,0,-2),109, 3)
mc.setBlock(loc + Vec3(3,0,-1),109, 3)
mc.setBlock(loc + Vec3(3,0,0),109, 3)
mc.setBlock(loc + Vec3(3,0,1),109, 3)
mc.setBlock(loc + Vec3(3,0,2),98, 0)
mc.setBlock(loc + Vec3(3,0,3),98, 2)
mc.setBlock(loc + Vec3(-3,1,-4),98, 2)
mc.setBlock(loc + Vec3(-3,1,-3),109, 7)
mc.setBlock(loc + Vec3(-3,1,-2),109, 7)
mc.setBlock(loc + Vec3(-3,1,-1),109, 7)
mc.setBlock(loc + Vec3(-3,1,0),109, 7)
mc.setBlock(loc + Vec3(-3,1,1),109, 7)
mc.setBlock(loc + Vec3(-3,1,2),109, 7)
mc.setBlock(loc + Vec3(-3,1,3),98, 2)
mc.setBlock(loc + Vec3(-2,1,-4),109, 4)
mc.setBlock(loc + Vec3(-2,1,3),109, 4)
mc.setBlock(loc + Vec3(-1,1,-4),109, 4)
mc.setBlock(loc + Vec3(0,1,-4),44, 13)
mc.setBlock(loc + Vec3(1,1,-4),109, 5)
mc.setBlock(loc + Vec3(2,1,-4),109, 5)
mc.setBlock(loc + Vec3(2,1,3),109, 5)
mc.setBlock(loc + Vec3(3,1,-4),98, 0)
mc.setBlock(loc + Vec3(3,1,-3),109, 7)
mc.setBlock(loc + Vec3(3,1,-2),109, 7)
mc.setBlock(loc + Vec3(3,1,-1),109, 7)
mc.setBlock(loc + Vec3(3,1,0),109, 7)
mc.setBlock(loc + Vec3(3,1,1),109, 7)
mc.setBlock(loc + Vec3(3,1,2),98, 0)
mc.setBlock(loc + Vec3(3,1,3),98, 0)
mc.setBlock(loc + Vec3(-3,2,-4),109, 2)
mc.setBlock(loc + Vec3(-3,2,-3),109, 0)
mc.setBlock(loc + Vec3(-3,2,-2),109, 0)
mc.setBlock(loc + Vec3(-3,2,-1),109, 0)
mc.setBlock(loc + Vec3(-3,2,0),109, 0)
mc.setBlock(loc + Vec3(-3,2,1),109, 0)
mc.setBlock(loc + Vec3(-3,2,2),109, 0)
mc.setBlock(loc + Vec3(-3,2,3),109, 0)
mc.setBlock(loc + Vec3(-2,2,-4),109, 2)
mc.setBlock(loc + Vec3(-2,2,-3),44, 13)
mc.setBlock(loc + Vec3(-2,2,-2),44, 13)
mc.setBlock(loc + Vec3(-2,2,-1),44, 13)
mc.setBlock(loc + Vec3(-2,2,0),44, 13)
mc.setBlock(loc + Vec3(-2,2,1),44, 13)
mc.setBlock(loc + Vec3(-2,2,2),44, 13)
mc.setBlock(loc + Vec3(-2,2,3),98, 2)
mc.setBlock(loc + Vec3(-1,2,-4),109, 2)
mc.setBlock(loc + Vec3(-1,2,-3),44, 13)
mc.setBlock(loc + Vec3(-1,2,2),44, 13)
mc.setBlock(loc + Vec3(-1,2,3),109, 5)
mc.setBlock(loc + Vec3(0,2,-4),109, 2)
mc.setBlock(loc + Vec3(0,2,-3),44, 13)
mc.setBlock(loc + Vec3(0,2,2),44, 13)
mc.setBlock(loc + Vec3(0,2,3),44, 13)
mc.setBlock(loc + Vec3(1,2,-4),109, 2)
mc.setBlock(loc + Vec3(1,2,-3),44, 13)
mc.setBlock(loc + Vec3(1,2,2),44, 13)
mc.setBlock(loc + Vec3(1,2,3),109, 4)
mc.setBlock(loc + Vec3(2,2,-4),109, 2)
mc.setBlock(loc + Vec3(2,2,-3),44, 13)
mc.setBlock(loc + Vec3(2,2,-2),44, 13)
mc.setBlock(loc + Vec3(2,2,-1),44, 13)
mc.setBlock(loc + Vec3(2,2,0),44, 13)
mc.setBlock(loc + Vec3(2,2,1),44, 13)
mc.setBlock(loc + Vec3(2,2,2),44, 13)
mc.setBlock(loc + Vec3(2,2,3),98, 0)
mc.setBlock(loc + Vec3(3,2,-4),109, 1)
mc.setBlock(loc + Vec3(3,2,-3),109, 1)
mc.setBlock(loc + Vec3(3,2,-2),109, 1)
mc.setBlock(loc + Vec3(3,2,-1),109, 1)
mc.setBlock(loc + Vec3(3,2,0),109, 1)
mc.setBlock(loc + Vec3(3,2,1),109, 1)
mc.setBlock(loc + Vec3(3,2,2),109, 1)
mc.setBlock(loc + Vec3(3,2,3),109, 1)
mc.setBlock(loc + Vec3(-2,3,-3),109, 0)
mc.setBlock(loc + Vec3(-2,3,-2),109, 0)
mc.setBlock(loc + Vec3(-2,3,-1),109, 0)
mc.setBlock(loc + Vec3(-2,3,0),109, 0)
mc.setBlock(loc + Vec3(-2,3,1),109, 0)
mc.setBlock(loc + Vec3(-2,3,2),109, 3)
mc.setBlock(loc + Vec3(-1,3,-3),109, 2)
mc.setBlock(loc + Vec3(-1,3,-2),44, 5)
mc.setBlock(loc + Vec3(-1,3,-1),44, 5)
mc.setBlock(loc + Vec3(-1,3,0),44, 5)
mc.setBlock(loc + Vec3(-1,3,1),44, 5)
mc.setBlock(loc + Vec3(-1,3,2),109, 3)
mc.setBlock(loc + Vec3(0,3,-3),109, 2)
mc.setBlock(loc + Vec3(0,3,-2),44, 5)
mc.setBlock(loc + Vec3(0,3,-1),44, 5)
mc.setBlock(loc + Vec3(0,3,0),44, 5)
mc.setBlock(loc + Vec3(0,3,1),44, 5)
mc.setBlock(loc + Vec3(0,3,2),109, 3)
mc.setBlock(loc + Vec3(1,3,-3),109, 2)
mc.setBlock(loc + Vec3(1,3,-2),44, 5)
mc.setBlock(loc + Vec3(1,3,-1),44, 5)
mc.setBlock(loc + Vec3(1,3,0),44, 5)
mc.setBlock(loc + Vec3(1,3,1),44, 5)
mc.setBlock(loc + Vec3(1,3,2),109, 3)
mc.setBlock(loc + Vec3(2,3,-2),109, 1)
mc.setBlock(loc + Vec3(2,3,-1),109, 1)
mc.setBlock(loc + Vec3(2,3,0),109, 1)
mc.setBlock(loc + Vec3(2,3,1),109, 1)
mc.setBlock(loc + Vec3(2,3,2),109, 1)