from first import *

def TieFighter(v):
	mc.setBlock(v + Vec3(-3,-6,-5),155, 0)
	mc.setBlock(v + Vec3(-3,-6,5),155, 0)
	mc.setBlock(v + Vec3(-2,-6,-5),155, 0)
	mc.setBlock(v + Vec3(-2,-6,5),155, 0)
	mc.setBlock(v + Vec3(-1,-6,-5),155, 0)
	mc.setBlock(v + Vec3(-1,-6,5),155, 0)
	mc.setBlock(v + Vec3(0,-6,-5),155, 0)
	mc.setBlock(v + Vec3(0,-6,5),155, 0)
	mc.setBlock(v + Vec3(1,-6,-5),155, 0)
	mc.setBlock(v + Vec3(1,-6,5),155, 0)
	mc.setBlock(v + Vec3(2,-6,-5),155, 0)
	mc.setBlock(v + Vec3(2,-6,5),155, 0)
	mc.setBlock(v + Vec3(3,-6,-5),155, 0)
	mc.setBlock(v + Vec3(3,-6,5),155, 0)
	mc.setBlock(v + Vec3(4,-6,-5),155, 0)
	mc.setBlock(v + Vec3(4,-6,5),155, 0)
	mc.setBlock(v + Vec3(5,-6,-5),155, 0)
	mc.setBlock(v + Vec3(5,-6,5),155, 0)
	mc.setBlock(v + Vec3(-3,-5,-5),155, 0)
	mc.setBlock(v + Vec3(-3,-5,5),155, 0)
	mc.setBlock(v + Vec3(-2,-5,-5),155, 0)
	mc.setBlock(v + Vec3(-2,-5,5),155, 0)
	mc.setBlock(v + Vec3(-1,-5,-5),35,15)
	mc.setBlock(v + Vec3(-1,-5,5),35,15)
	mc.setBlock(v + Vec3(0,-5,-5),35,15)
	mc.setBlock(v + Vec3(0,-5,5),35,15)
	mc.setBlock(v + Vec3(1,-5,-5),35,15)
	mc.setBlock(v + Vec3(1,-5,5),35,15)
	mc.setBlock(v + Vec3(2,-5,-5),35,15)
	mc.setBlock(v + Vec3(2,-5,5),35,15)
	mc.setBlock(v + Vec3(3,-5,-5),35,15)
	mc.setBlock(v + Vec3(3,-5,5),35,15)
	mc.setBlock(v + Vec3(4,-5,-5),155, 0)
	mc.setBlock(v + Vec3(4,-5,5),155, 0)
	mc.setBlock(v + Vec3(5,-5,-5),155, 0)
	mc.setBlock(v + Vec3(5,-5,5),155, 0)
	mc.setBlock(v + Vec3(-4,-4,-5),155, 0)
	mc.setBlock(v + Vec3(-4,-4,5),155, 0)
	mc.setBlock(v + Vec3(-3,-4,-5),35,15)
	mc.setBlock(v + Vec3(-3,-4,5),35,15)
	mc.setBlock(v + Vec3(-2,-4,-5),155, 0)
	mc.setBlock(v + Vec3(-2,-4,5),155, 0)
	mc.setBlock(v + Vec3(-1,-4,-5),35,15)
	mc.setBlock(v + Vec3(-1,-4,5),35,15)
	mc.setBlock(v + Vec3(0,-4,-5),35,15)
	mc.setBlock(v + Vec3(0,-4,5),35,15)
	mc.setBlock(v + Vec3(1,-4,-5),35,15)
	mc.setBlock(v + Vec3(1,-4,5),35,15)
	mc.setBlock(v + Vec3(2,-4,-5),35,15)
	mc.setBlock(v + Vec3(2,-4,5),35,15)
	mc.setBlock(v + Vec3(3,-4,-5),35,15)
	mc.setBlock(v + Vec3(3,-4,5),35,15)
	mc.setBlock(v + Vec3(4,-4,-5),155, 0)
	mc.setBlock(v + Vec3(4,-4,5),155, 0)
	mc.setBlock(v + Vec3(5,-4,-5),35,15)
	mc.setBlock(v + Vec3(5,-4,5),35,15)
	mc.setBlock(v + Vec3(6,-4,-5),155, 0)
	mc.setBlock(v + Vec3(6,-4,5),155, 0)
	mc.setBlock(v + Vec3(-4,-3,-5),155, 0)
	mc.setBlock(v + Vec3(-4,-3,5),155, 0)
	mc.setBlock(v + Vec3(-3,-3,-5),35,15)
	mc.setBlock(v + Vec3(-3,-3,5),35,15)
	mc.setBlock(v + Vec3(-2,-3,-5),35,15)
	mc.setBlock(v + Vec3(-2,-3,5),35,15)
	mc.setBlock(v + Vec3(-1,-3,-5),155, 0)
	mc.setBlock(v + Vec3(-1,-3,5),155, 0)
	mc.setBlock(v + Vec3(0,-3,-5),35,15)
	mc.setBlock(v + Vec3(0,-3,5),35,15)
	mc.setBlock(v + Vec3(1,-3,-5),35,15)
	mc.setBlock(v + Vec3(1,-3,5),35,15)
	mc.setBlock(v + Vec3(2,-3,-5),35,15)
	mc.setBlock(v + Vec3(2,-3,5),35,15)
	mc.setBlock(v + Vec3(3,-3,-5),155, 0)
	mc.setBlock(v + Vec3(3,-3,5),155, 0)
	mc.setBlock(v + Vec3(4,-3,-5),35,15)
	mc.setBlock(v + Vec3(4,-3,5),35,15)
	mc.setBlock(v + Vec3(5,-3,-5),35,15)
	mc.setBlock(v + Vec3(5,-3,5),35,15)
	mc.setBlock(v + Vec3(6,-3,-5),155, 0)
	mc.setBlock(v + Vec3(6,-3,5),155, 0)
	mc.setBlock(v + Vec3(-5,-2,-5),155, 0)
	mc.setBlock(v + Vec3(-5,-2,5),155, 0)
	mc.setBlock(v + Vec3(-4,-2,-5),35,15)
	mc.setBlock(v + Vec3(-4,-2,5),35,15)
	mc.setBlock(v + Vec3(-3,-2,-5),35,15)
	mc.setBlock(v + Vec3(-3,-2,5),35,15)
	mc.setBlock(v + Vec3(-2,-2,-5),35,15)
	mc.setBlock(v + Vec3(-2,-2,5),35,15)
	mc.setBlock(v + Vec3(-1,-2,-5),155, 0)
	mc.setBlock(v + Vec3(-1,-2,5),155, 0)
	mc.setBlock(v + Vec3(0,-2,-5),35,15)
	mc.setBlock(v + Vec3(0,-2,5),35,15)
	mc.setBlock(v + Vec3(1,-2,-5),35,15)
	mc.setBlock(v + Vec3(1,-2,5),35,15)
	mc.setBlock(v + Vec3(2,-2,-5),35,15)
	mc.setBlock(v + Vec3(2,-2,5),35,15)
	mc.setBlock(v + Vec3(3,-2,-5),155, 0)
	mc.setBlock(v + Vec3(3,-2,5),155, 0)
	mc.setBlock(v + Vec3(4,-2,-5),35,15)
	mc.setBlock(v + Vec3(4,-2,5),35,15)
	mc.setBlock(v + Vec3(5,-2,-5),35,15)
	mc.setBlock(v + Vec3(5,-2,5),35,15)
	mc.setBlock(v + Vec3(6,-2,-5),35,15)
	mc.setBlock(v + Vec3(6,-2,5),35,15)
	mc.setBlock(v + Vec3(7,-2,-5),155, 0)
	mc.setBlock(v + Vec3(7,-2,5),155, 0)
	mc.setBlock(v + Vec3(-5,-1,-5),155, 0)
	mc.setBlock(v + Vec3(-5,-1,5),155, 0)
	mc.setBlock(v + Vec3(-4,-1,-5),35,15)
	mc.setBlock(v + Vec3(-4,-1,5),35,15)
	mc.setBlock(v + Vec3(-3,-1,-5),35,15)
	mc.setBlock(v + Vec3(-3,-1,5),35,15)
	mc.setBlock(v + Vec3(-2,-1,-5),35,15)
	mc.setBlock(v + Vec3(-2,-1,5),35,15)
	mc.setBlock(v + Vec3(-1,-1,-5),35,15)
	mc.setBlock(v + Vec3(-1,-1,5),35,15)
	mc.setBlock(v + Vec3(0,-1,-5),155, 0)
	mc.setBlock(v + Vec3(0,-1,-1),156, 6)
	mc.setBlock(v + Vec3(0,-1,0),156, 4)
	mc.setBlock(v + Vec3(0,-1,1),156, 7)
	mc.setBlock(v + Vec3(0,-1,5),155, 0)
	mc.setBlock(v + Vec3(1,-1,-5),35,15)
	mc.setBlock(v + Vec3(1,-1,-1),156, 6)
	mc.setBlock(v + Vec3(1,-1,0),155, 0)
	mc.setBlock(v + Vec3(1,-1,1),156, 7)
	mc.setBlock(v + Vec3(1,-1,5),35,15)
	mc.setBlock(v + Vec3(2,-1,-5),155, 0)
	mc.setBlock(v + Vec3(2,-1,-1),156, 5)
	mc.setBlock(v + Vec3(2,-1,0),156, 5)
	mc.setBlock(v + Vec3(2,-1,1),156, 7)
	mc.setBlock(v + Vec3(2,-1,5),155, 0)
	mc.setBlock(v + Vec3(3,-1,-5),35,15)
	mc.setBlock(v + Vec3(3,-1,5),35,15)
	mc.setBlock(v + Vec3(4,-1,-5),35,15)
	mc.setBlock(v + Vec3(4,-1,5),35,15)
	mc.setBlock(v + Vec3(5,-1,-5),35,15)
	mc.setBlock(v + Vec3(5,-1,5),35,15)
	mc.setBlock(v + Vec3(6,-1,-5),35,15)
	mc.setBlock(v + Vec3(6,-1,5),35,15)
	mc.setBlock(v + Vec3(7,-1,-5),155, 0)
	mc.setBlock(v + Vec3(7,-1,5),155, 0)
	mc.setBlock(v + Vec3(-6,0,-5),155, 0)
	mc.setBlock(v + Vec3(-6,0,5),155, 0)
	mc.setBlock(v + Vec3(-5,0,-5),35,15)
	mc.setBlock(v + Vec3(-5,0,5),35,15)
	mc.setBlock(v + Vec3(-4,0,-5),35,15)
	mc.setBlock(v + Vec3(-4,0,5),35,15)
	mc.setBlock(v + Vec3(-3,0,-5),35,15)
	mc.setBlock(v + Vec3(-3,0,5),35,15)
	mc.setBlock(v + Vec3(-2,0,-5),35,15)
	mc.setBlock(v + Vec3(-2,0,5),35,15)
	mc.setBlock(v + Vec3(-1,0,-5),35,15)
	mc.setBlock(v + Vec3(-1,0,-1),156, 4)
	mc.setBlock(v + Vec3(-1,0,0),20, 0)
	mc.setBlock(v + Vec3(-1,0,1),156, 4)
	mc.setBlock(v + Vec3(-1,0,5),35,15)
	mc.setBlock(v + Vec3(0,0,-6),156, 4)
	mc.setBlock(v + Vec3(0,0,-5),155, 0)
	mc.setBlock(v + Vec3(0,0,-4),156, 4)
	mc.setBlock(v + Vec3(0,0,-2),156, 6)
	mc.setBlock(v + Vec3(0,0,-1),35,15)
	mc.setBlock(v + Vec3(0,0,0),35,15)
	mc.setBlock(v + Vec3(0,0,1),35,15)
	mc.setBlock(v + Vec3(0,0,2),156, 7)
	mc.setBlock(v + Vec3(0,0,4),156, 4)
	mc.setBlock(v + Vec3(0,0,5),155, 0)
	mc.setBlock(v + Vec3(0,0,6),156, 4)
	mc.setBlock(v + Vec3(1,0,-6),156, 6)
	mc.setBlock(v + Vec3(1,0,-5),155, 0)
	mc.setBlock(v + Vec3(1,0,-4),156, 7)
	mc.setBlock(v + Vec3(1,0,-2),156, 6)
	mc.setBlock(v + Vec3(1,0,-1),35,15)
	mc.setBlock(v + Vec3(1,0,1),35,15)
	mc.setBlock(v + Vec3(1,0,2),156, 7)
	mc.setBlock(v + Vec3(1,0,4),156, 6)
	mc.setBlock(v + Vec3(1,0,5),155, 0)
	mc.setBlock(v + Vec3(1,0,6),156, 7)
	mc.setBlock(v + Vec3(2,0,-6),156, 5)
	mc.setBlock(v + Vec3(2,0,-5),155, 0)
	mc.setBlock(v + Vec3(2,0,-4),156, 5)
	mc.setBlock(v + Vec3(2,0,-2),156, 6)
	mc.setBlock(v + Vec3(2,0,-1),155, 0)
	mc.setBlock(v + Vec3(2,0,0),35,15)
	mc.setBlock(v + Vec3(2,0,1),155, 0)
	mc.setBlock(v + Vec3(2,0,2),156, 7)
	mc.setBlock(v + Vec3(2,0,4),156, 5)
	mc.setBlock(v + Vec3(2,0,5),155, 0)
	mc.setBlock(v + Vec3(2,0,6),156, 5)
	mc.setBlock(v + Vec3(3,0,-5),35,15)
	mc.setBlock(v + Vec3(3,0,-2),156, 6)
	mc.setBlock(v + Vec3(3,0,-1),156, 5)
	mc.setBlock(v + Vec3(3,0,0),156, 5)
	mc.setBlock(v + Vec3(3,0,1),156, 5)
	mc.setBlock(v + Vec3(3,0,2),156, 7)
	mc.setBlock(v + Vec3(3,0,5),35,15)
	mc.setBlock(v + Vec3(4,0,-5),35,15)
	mc.setBlock(v + Vec3(4,0,5),35,15)
	mc.setBlock(v + Vec3(5,0,-5),35,15)
	mc.setBlock(v + Vec3(5,0,5),35,15)
	mc.setBlock(v + Vec3(6,0,-5),35,15)
	mc.setBlock(v + Vec3(6,0,5),35,15)
	mc.setBlock(v + Vec3(7,0,-5),35,15)
	mc.setBlock(v + Vec3(7,0,5),35,15)
	mc.setBlock(v + Vec3(8,0,-5),155, 0)
	mc.setBlock(v + Vec3(8,0,5),155, 0)
	mc.setBlock(v + Vec3(-6,1,-5),155, 0)
	mc.setBlock(v + Vec3(-6,1,5),155, 0)
	mc.setBlock(v + Vec3(-5,1,-5),155, 0)
	mc.setBlock(v + Vec3(-5,1,5),155, 0)
	mc.setBlock(v + Vec3(-4,1,-5),155, 0)
	mc.setBlock(v + Vec3(-4,1,5),155, 0)
	mc.setBlock(v + Vec3(-3,1,-5),155, 0)
	mc.setBlock(v + Vec3(-3,1,5),155, 0)
	mc.setBlock(v + Vec3(-2,1,-5),155, 0)
	mc.setBlock(v + Vec3(-2,1,5),155, 0)
	mc.setBlock(v + Vec3(-1,1,-5),155, 0)
	mc.setBlock(v + Vec3(-1,1,-1),20, 0)
	mc.setBlock(v + Vec3(-1,1,0),20, 0)
	mc.setBlock(v + Vec3(-1,1,1),20, 0)
	mc.setBlock(v + Vec3(-1,1,5),155, 0)
	mc.setBlock(v + Vec3(0,1,-6),155, 0)
	mc.setBlock(v + Vec3(0,1,-5),155, 0)
	mc.setBlock(v + Vec3(0,1,-4),155, 0)
	mc.setBlock(v + Vec3(0,1,-2),155, 0)
	mc.setBlock(v + Vec3(0,1,2),155, 0)
	mc.setBlock(v + Vec3(0,1,4),155, 0)
	mc.setBlock(v + Vec3(0,1,5),155, 0)
	mc.setBlock(v + Vec3(0,1,6),155, 0)
	mc.setBlock(v + Vec3(1,1,-6),155, 0)
	mc.setBlock(v + Vec3(1,1,-5),155, 0)
	mc.setBlock(v + Vec3(1,1,-4),155, 0)
	mc.setBlock(v + Vec3(1,1,-3),155, 0)
	mc.setBlock(v + Vec3(1,1,-2),35,15)
	mc.setBlock(v + Vec3(1,1,2),35,15)
	mc.setBlock(v + Vec3(1,1,3),155, 0)
	mc.setBlock(v + Vec3(1,1,4),155, 0)
	mc.setBlock(v + Vec3(1,1,5),155, 0)
	mc.setBlock(v + Vec3(1,1,6),155, 0)
	mc.setBlock(v + Vec3(2,1,-6),155, 0)
	mc.setBlock(v + Vec3(2,1,-5),155, 0)
	mc.setBlock(v + Vec3(2,1,-4),155, 0)
	mc.setBlock(v + Vec3(2,1,-2),155, 0)
	mc.setBlock(v + Vec3(2,1,-1),35,15)
	mc.setBlock(v + Vec3(2,1,0),35,15)
	mc.setBlock(v + Vec3(2,1,1),35,15)
	mc.setBlock(v + Vec3(2,1,2),155, 0)
	mc.setBlock(v + Vec3(2,1,4),155, 0)
	mc.setBlock(v + Vec3(2,1,5),155, 0)
	mc.setBlock(v + Vec3(2,1,6),155, 0)
	mc.setBlock(v + Vec3(3,1,-5),155, 0)
	mc.setBlock(v + Vec3(3,1,-2),155, 0)
	mc.setBlock(v + Vec3(3,1,-1),35, 15)
	mc.setBlock(v + Vec3(3,1,0),35, 15)
	mc.setBlock(v + Vec3(3,1,1),35, 15)
	mc.setBlock(v + Vec3(3,1,2),155, 0)
	mc.setBlock(v + Vec3(3,1,5),155, 0)
	mc.setBlock(v + Vec3(4,1,-5),155, 0)
	mc.setBlock(v + Vec3(4,1,5),155, 0)
	mc.setBlock(v + Vec3(5,1,-5),155, 0)
	mc.setBlock(v + Vec3(5,1,5),155, 0)
	mc.setBlock(v + Vec3(6,1,-5),155, 0)
	mc.setBlock(v + Vec3(6,1,5),155, 0)
	mc.setBlock(v + Vec3(7,1,-5),155, 0)
	mc.setBlock(v + Vec3(7,1,5),155, 0)
	mc.setBlock(v + Vec3(8,1,-5),155, 0)
	mc.setBlock(v + Vec3(8,1,5),155, 0)
	mc.setBlock(v + Vec3(-6,2,-5),155, 0)
	mc.setBlock(v + Vec3(-6,2,5),155, 0)
	mc.setBlock(v + Vec3(-5,2,-5),35,15)
	mc.setBlock(v + Vec3(-5,2,5),35,15)
	mc.setBlock(v + Vec3(-4,2,-5),35,15)
	mc.setBlock(v + Vec3(-4,2,5),35,15)
	mc.setBlock(v + Vec3(-3,2,-5),35,15)
	mc.setBlock(v + Vec3(-3,2,5),35,15)
	mc.setBlock(v + Vec3(-2,2,-5),35,15)
	mc.setBlock(v + Vec3(-2,2,5),35,15)
	mc.setBlock(v + Vec3(-1,2,-5),35,15)
	mc.setBlock(v + Vec3(-1,2,-1),156, 0)
	mc.setBlock(v + Vec3(-1,2,0),20, 0)
	mc.setBlock(v + Vec3(-1,2,1),156, 0)
	mc.setBlock(v + Vec3(-1,2,5),35,15)
	mc.setBlock(v + Vec3(0,2,-6),156, 0)
	mc.setBlock(v + Vec3(0,2,-5),155, 0)
	mc.setBlock(v + Vec3(0,2,-4),156, 0)
	mc.setBlock(v + Vec3(0,2,-2),156, 2)
	mc.setBlock(v + Vec3(0,2,2),156, 3)
	mc.setBlock(v + Vec3(0,2,4),156, 0)
	mc.setBlock(v + Vec3(0,2,5),155, 0)
	mc.setBlock(v + Vec3(0,2,6),156, 0)
	mc.setBlock(v + Vec3(1,2,-6),156, 2)
	mc.setBlock(v + Vec3(1,2,-5),155, 0)
	mc.setBlock(v + Vec3(1,2,-4),156, 3)
	mc.setBlock(v + Vec3(1,2,-2),156, 2)
	mc.setBlock(v + Vec3(1,2,2),156, 3)
	mc.setBlock(v + Vec3(1,2,4),156, 2)
	mc.setBlock(v + Vec3(1,2,5),155, 0)
	mc.setBlock(v + Vec3(1,2,6),156, 3)
	mc.setBlock(v + Vec3(2,2,-6),156, 1)
	mc.setBlock(v + Vec3(2,2,-5),155, 0)
	mc.setBlock(v + Vec3(2,2,-4),156, 1)
	mc.setBlock(v + Vec3(2,2,-2),156, 2)
	mc.setBlock(v + Vec3(2,2,-1),155, 0)
	mc.setBlock(v + Vec3(2,2,0),35,15)
	mc.setBlock(v + Vec3(2,2,1),155, 0)
	mc.setBlock(v + Vec3(2,2,2),156, 3)
	mc.setBlock(v + Vec3(2,2,4),156, 1)
	mc.setBlock(v + Vec3(2,2,5),155, 0)
	mc.setBlock(v + Vec3(2,2,6),156, 1)
	mc.setBlock(v + Vec3(3,2,-5),35,15)
	mc.setBlock(v + Vec3(3,2,-2),156, 1)
	mc.setBlock(v + Vec3(3,2,-1),156, 1)
	mc.setBlock(v + Vec3(3,2,0),156, 1)
	mc.setBlock(v + Vec3(3,2,1),156, 1)
	mc.setBlock(v + Vec3(3,2,2),156, 3)
	mc.setBlock(v + Vec3(3,2,5),35,15)
	mc.setBlock(v + Vec3(4,2,-5),35,15)
	mc.setBlock(v + Vec3(4,2,5),35,15)
	mc.setBlock(v + Vec3(5,2,-5),35,15)
	mc.setBlock(v + Vec3(5,2,5),35,15)
	mc.setBlock(v + Vec3(6,2,-5),35,15)
	mc.setBlock(v + Vec3(6,2,5),35,15)
	mc.setBlock(v + Vec3(7,2,-5),35,15)
	mc.setBlock(v + Vec3(7,2,5),35,15)
	mc.setBlock(v + Vec3(8,2,-5),155, 0)
	mc.setBlock(v + Vec3(8,2,5),155, 0)
	mc.setBlock(v + Vec3(-5,3,-5),155, 0)
	mc.setBlock(v + Vec3(-5,3,5),155, 0)
	mc.setBlock(v + Vec3(-4,3,-5),35,15)
	mc.setBlock(v + Vec3(-4,3,5),35,15)
	mc.setBlock(v + Vec3(-3,3,-5),35,15)
	mc.setBlock(v + Vec3(-3,3,5),35,15)
	mc.setBlock(v + Vec3(-2,3,-5),35,15)
	mc.setBlock(v + Vec3(-2,3,5),35,15)
	mc.setBlock(v + Vec3(-1,3,-5),35,15)
	mc.setBlock(v + Vec3(-1,3,5),35,15)
	mc.setBlock(v + Vec3(0,3,-5),155, 0)
	mc.setBlock(v + Vec3(0,3,-1),156, 0)
	mc.setBlock(v + Vec3(0,3,0),156, 0)
	mc.setBlock(v + Vec3(0,3,1),156, 3)
	mc.setBlock(v + Vec3(0,3,5),155, 0)
	mc.setBlock(v + Vec3(1,3,-5),35,15)
	mc.setBlock(v + Vec3(1,3,-1),156, 2)
	mc.setBlock(v + Vec3(1,3,1),156, 3)
	mc.setBlock(v + Vec3(1,3,5),35,15)
	mc.setBlock(v + Vec3(2,3,-5),155, 0)
	mc.setBlock(v + Vec3(2,3,-1),156, 2)
	mc.setBlock(v + Vec3(2,3,0),156, 1)
	mc.setBlock(v + Vec3(2,3,1),156, 1)
	mc.setBlock(v + Vec3(2,3,5),155, 0)
	mc.setBlock(v + Vec3(3,3,-5),35,15)
	mc.setBlock(v + Vec3(3,3,5),35,15)
	mc.setBlock(v + Vec3(4,3,-5),35,15)
	mc.setBlock(v + Vec3(4,3,5),35,15)
	mc.setBlock(v + Vec3(5,3,-5),35,15)
	mc.setBlock(v + Vec3(5,3,5),35,15)
	mc.setBlock(v + Vec3(6,3,-5),35,15)
	mc.setBlock(v + Vec3(6,3,5),35,15)
	mc.setBlock(v + Vec3(7,3,-5),155, 0)
	mc.setBlock(v + Vec3(7,3,5),155, 0)
	mc.setBlock(v + Vec3(-5,4,-5),155, 0)
	mc.setBlock(v + Vec3(-5,4,5),155, 0)
	mc.setBlock(v + Vec3(-4,4,-5),35,15)
	mc.setBlock(v + Vec3(-4,4,5),35,15)
	mc.setBlock(v + Vec3(-3,4,-5),35,15)
	mc.setBlock(v + Vec3(-3,4,5),35,15)
	mc.setBlock(v + Vec3(-2,4,-5),35,15)
	mc.setBlock(v + Vec3(-2,4,5),35,15)
	mc.setBlock(v + Vec3(-1,4,-5),155, 0)
	mc.setBlock(v + Vec3(-1,4,5),155, 0)
	mc.setBlock(v + Vec3(0,4,-5),35,15)
	mc.setBlock(v + Vec3(0,4,5),35,15)
	mc.setBlock(v + Vec3(1,4,-5),35,15)
	mc.setBlock(v + Vec3(1,4,0),96, 6)
	mc.setBlock(v + Vec3(1,4,5),35,15)
	mc.setBlock(v + Vec3(2,4,-5),35,15)
	mc.setBlock(v + Vec3(2,4,5),35,15)
	mc.setBlock(v + Vec3(3,4,-5),155, 0)
	mc.setBlock(v + Vec3(3,4,5),155, 0)
	mc.setBlock(v + Vec3(4,4,-5),35,15)
	mc.setBlock(v + Vec3(4,4,5),35,15)
	mc.setBlock(v + Vec3(5,4,-5),35,15)
	mc.setBlock(v + Vec3(5,4,5),35,15)
	mc.setBlock(v + Vec3(6,4,-5),35,15)
	mc.setBlock(v + Vec3(6,4,5),35,15)
	mc.setBlock(v + Vec3(7,4,-5),155, 0)
	mc.setBlock(v + Vec3(7,4,5),155, 0)
	mc.setBlock(v + Vec3(-4,5,-5),155, 0)
	mc.setBlock(v + Vec3(-4,5,5),155, 0)
	mc.setBlock(v + Vec3(-3,5,-5),35,15)
	mc.setBlock(v + Vec3(-3,5,5),35,15)
	mc.setBlock(v + Vec3(-2,5,-5),35,15)
	mc.setBlock(v + Vec3(-2,5,5),35,15)
	mc.setBlock(v + Vec3(-1,5,-5),155, 0)
	mc.setBlock(v + Vec3(-1,5,5),155, 0)
	mc.setBlock(v + Vec3(0,5,-5),35,15)
	mc.setBlock(v + Vec3(0,5,5),35,15)
	mc.setBlock(v + Vec3(1,5,-5),35,15)
	mc.setBlock(v + Vec3(1,5,5),35,15)
	mc.setBlock(v + Vec3(2,5,-5),35,15)
	mc.setBlock(v + Vec3(2,5,5),35,15)
	mc.setBlock(v + Vec3(3,5,-5),155, 0)
	mc.setBlock(v + Vec3(3,5,5),155, 0)
	mc.setBlock(v + Vec3(4,5,-5),35,15)
	mc.setBlock(v + Vec3(4,5,5),35,15)
	mc.setBlock(v + Vec3(5,5,-5),35,15)
	mc.setBlock(v + Vec3(5,5,5),35,15)
	mc.setBlock(v + Vec3(6,5,-5),155, 0)
	mc.setBlock(v + Vec3(6,5,5),155, 0)
	mc.setBlock(v + Vec3(-4,6,-5),155, 0)
	mc.setBlock(v + Vec3(-4,6,5),155, 0)
	mc.setBlock(v + Vec3(-3,6,-5),35,15)
	mc.setBlock(v + Vec3(-3,6,5),35,15)
	mc.setBlock(v + Vec3(-2,6,-5),155, 0)
	mc.setBlock(v + Vec3(-2,6,5),155, 0)
	mc.setBlock(v + Vec3(-1,6,-5),35,15)
	mc.setBlock(v + Vec3(-1,6,5),35,15)
	mc.setBlock(v + Vec3(0,6,-5),35,15)
	mc.setBlock(v + Vec3(0,6,5),35,15)
	mc.setBlock(v + Vec3(1,6,-5),35,15)
	mc.setBlock(v + Vec3(1,6,5),35,15)
	mc.setBlock(v + Vec3(2,6,-5),35,15)
	mc.setBlock(v + Vec3(2,6,5),35,15)
	mc.setBlock(v + Vec3(3,6,-5),35,15)
	mc.setBlock(v + Vec3(3,6,5),35,15)
	mc.setBlock(v + Vec3(4,6,-5),155, 0)
	mc.setBlock(v + Vec3(4,6,5),155, 0)
	mc.setBlock(v + Vec3(5,6,-5),35,15)
	mc.setBlock(v + Vec3(5,6,5),35,15)
	mc.setBlock(v + Vec3(6,6,-5),155, 0)
	mc.setBlock(v + Vec3(6,6,5),155, 0)
	mc.setBlock(v + Vec3(-3,7,-5),155, 0)
	mc.setBlock(v + Vec3(-3,7,5),155, 0)
	mc.setBlock(v + Vec3(-2,7,-5),155, 0)
	mc.setBlock(v + Vec3(-2,7,5),155, 0)
	mc.setBlock(v + Vec3(-1,7,-5),35,15)
	mc.setBlock(v + Vec3(-1,7,5),35,15)
	mc.setBlock(v + Vec3(0,7,-5),35,15)
	mc.setBlock(v + Vec3(0,7,5),35,15)
	mc.setBlock(v + Vec3(1,7,-5),35,15)
	mc.setBlock(v + Vec3(1,7,5),35,15)
	mc.setBlock(v + Vec3(2,7,-5),35,15)
	mc.setBlock(v + Vec3(2,7,5),35,15)
	mc.setBlock(v + Vec3(3,7,-5),35,15)
	mc.setBlock(v + Vec3(3,7,5),35,15)
	mc.setBlock(v + Vec3(4,7,-5),155, 0)
	mc.setBlock(v + Vec3(4,7,5),155, 0)
	mc.setBlock(v + Vec3(5,7,-5),155, 0)
	mc.setBlock(v + Vec3(5,7,5),155, 0)
	mc.setBlock(v + Vec3(-3,8,-5),155, 0)
	mc.setBlock(v + Vec3(-3,8,5),155, 0)
	mc.setBlock(v + Vec3(-2,8,-5),155, 0)
	mc.setBlock(v + Vec3(-2,8,5),155, 0)
	mc.setBlock(v + Vec3(-1,8,-5),155, 0)
	mc.setBlock(v + Vec3(-1,8,5),155, 0)
	mc.setBlock(v + Vec3(0,8,-5),155, 0)
	mc.setBlock(v + Vec3(0,8,5),155, 0)
	mc.setBlock(v + Vec3(1,8,-5),155, 0)
	mc.setBlock(v + Vec3(1,8,5),155, 0)
	mc.setBlock(v + Vec3(2,8,-5),155, 0)
	mc.setBlock(v + Vec3(2,8,5),155, 0)
	mc.setBlock(v + Vec3(3,8,-5),155, 0)
	mc.setBlock(v + Vec3(3,8,5),155, 0)
	mc.setBlock(v + Vec3(4,8,-5),155, 0)
	mc.setBlock(v + Vec3(4,8,5),155, 0)
	mc.setBlock(v + Vec3(5,8,-5),155, 0)
	mc.setBlock(v + Vec3(5,8,5),155, 0)
